Workbook

Sheet 🚀 Dashboard Investidor
A2: AUTONOMA | C2: DASHBOARD DO INVESTIDOR · PLANO 24 MESES
A3: Business Plan completo: 📋 Sumário · 🌎 Mercado & GTM · 📈 DRE · 💰 Caixa & Runway · ⚠️ Riscos & Roadmap · 💎 Resumo Anjo
A5: CENÁRIO ATIVO | B5: ='🔧 Cenário Ativo'!B2 -> Conservador | C5: ← altere em 🔧 Cenário Ativo!B2 (Conservador / Base / Otimista) — todo o BP recalcula
A8: VALUATION · M24 | C8: RETORNO DO ANJO · M24 | E8: RECEITA ACUM. · 24M | G8: BREAKEVEN DE CAIXA | I8: CAIXA FINAL · M24
A9: =IF('🔧 Cenário Ativo'!B2="Conservador",'📊 Resumo Cenários'!B21,IF('🔧 Cenário Ativo'!B2="Base",'📊 Resumo Cenários'!C21,'📊 Resumo Cenários'!D21)) -> 19914787 | C9: =A9*'🎛️ Premissas'!B59 -> 2987218 | E9: =IF('🔧 Cenário Ativo'!B2="Conservador",'📊 Resumo Cenários'!B19,IF('🔧 Cenário Ativo'!B2="Base",'📊 Resumo Cenários'!C19,'📊 Resumo Cenários'!D19)) -> 6638262.2 | G9: {=IFERROR("M"&MATCH(TRUE,INDEX('📊 Base Mensal'!C25:Z25>0,0),0),">24m")} -> M5 | I9: ='💰 Caixa & Runway'!Z10 -> 4275921.5
A10: ="receita acum. × "&TEXT('🔧 Cenário Ativo'!B50,"0,0")&"× (múltiplo do cenário)" -> receita acum. × 3,0× (múltiplo do cenário) | C10: =TEXT(C9/'🎛️ Premissas'!B58,"0,0")&"× o aporte de R$ "&TEXT('🎛️ Premissas'!B58/1000,"#.##0")&" mil · fatia de "&TEXT('🎛️ Premissas'!B59,"0%") -> 3,0× o aporte de R$ 1.000 mil · fatia de 15% | E10: base oficial do valuation (📊 Resumo Cenários) | G10: resultado acumulado fica positivo | I10: ="caixa nunca abaixo de R$ "&TEXT(MIN('💰 Caixa & Runway'!C10:Z10)/1000,"#.##0")&" mil" -> caixa nunca abaixo de R$ 942 mil
A13: MRR · M24 | C13: ASSINANTES PAGANTES · M24 | E13: LTV / CAC | G13: PAYBACK DO CAC | I13: MARGEM BRUTA · M24
A14: ='📊 Base Mensal'!Z11*12 -> 5606367.6 | C14: ='📊 Base Mensal'!Z9 -> 8027 | E14: ='🔧 Cenário Ativo'!B56 -> 6.8861031 | G14: ='🔧 Cenário Ativo'!B57 -> 1.8152502 | I14: ='📊 Base Mensal'!Z26 -> 0.84939387
A15: ="ARR de R$ "&TEXT('📊 Base Mensal'!Z11*12/1000000,"0,0")&" M no fim do Ano 2" -> ARR de R$ 5,6 M no fim do Ano 2 | C15: ="de "&TEXT(('🔧 Cenário Ativo'!B30+'🔧 Cenário Ativo'!B31)*12,"#.##0")&" cadastros acumulados · trial 30d" -> de 78.000 cadastros acumulados · trial 30d | E15: ="CAC R$ "&TEXT('🔧 Cenário Ativo'!B47,"0")&" · LTV R$ "&TEXT('🔧 Cenário Ativo'!B55,"0")&" (Essencial)" -> CAC R$ 80 · LTV R$ 551 (Essencial) | G15: ="≈ "&TEXT('🔧 Cenário Ativo'!B57*30,"0")&" dias para recuperar o CAC" -> ≈ 54 dias para recuperar o CAC | I15: após custo de API (Free Haiku · pago Sonnet)
A16: PROJEÇÕES · 24 MESES | F16: ="Cenário ativo: "&'🔧 Cenário Ativo'!B2 -> Cenário ativo: Conservador
A35: RECEITA & COMPARATIVO DE CENÁRIOS
A53: Modelo 100% dinâmico · motor de cálculo em 📊 Base Mensal · premissas em 🎛️ Premissas e 🔧 Cenário Ativo · comparação em 📊 Resumo Cenários
A54: Este material é um estudo de projeção e não configura oferta de investimento. AutoNoma © 2025
L76: Mês | M76: MRR | N76: Pagantes | O76: Free | P76: Resultado | Q76: Acumulado | R76: Essencial | S76: Autônoma | T76: Livre | U76: API Total | V76: Custo Fixo | W76: Margem%
L77: M01 | M77: ='📊 Base Mensal'!C11 -> 21562 | N77: ='📊 Base Mensal'!C9 -> 380 | O77: ='📊 Base Mensal'!C5 -> 2000 | P77: ='📊 Base Mensal'!C24 -> -39903.991 | Q77: ='📊 Base Mensal'!C25 -> -39903.991 | R77: ='📊 Base Mensal'!C6 -> 200 | S77: ='📊 Base Mensal'!C7 -> 140 | T77: ='📊 Base Mensal'!C8 -> 40 | U77: ='📊 Base Mensal'!C18 -> 3662.9307 | V77: ='📊 Base Mensal'!C20 -> 55000 | W77: ='📊 Base Mensal'!C26 -> 0.83012101
L78: M02 | M78: ='📊 Base Mensal'!D11 -> 52607.4 | N78: ='📊 Base Mensal'!D9 -> 926 | O78: ='📊 Base Mensal'!D5 -> 3000 | P78: ='📊 Base Mensal'!D24 -> -17668.581 | Q78: ='📊 Base Mensal'!D25 -> -57572.571 | R78: ='📊 Base Mensal'!D6 -> 484 | S78: ='📊 Base Mensal'!D7 -> 343 | T78: ='📊 Base Mensal'!D8 -> 99 | U78: ='📊 Base Mensal'!D18 -> 8437.0186 | V78: ='📊 Base Mensal'!D20 -> 55000 | W78: ='📊 Base Mensal'!D26 -> 0.83962297
L79: M03 | M79: ='📊 Base Mensal'!E11 -> 81746.3 | N79: ='📊 Base Mensal'!E9 -> 1437 | O79: ='📊 Base Mensal'!E5 -> 3000 | P79: ='📊 Base Mensal'!E24 -> 3441.7706 | Q79: ='📊 Base Mensal'!E25 -> -54130.801 | R79: ='📊 Base Mensal'!E6 -> 745 | S79: ='📊 Base Mensal'!E7 -> 536 | T79: ='📊 Base Mensal'!E8 -> 156 | U79: ='📊 Base Mensal'!E18 -> 12677.51 | V79: ='📊 Base Mensal'!E20 -> 55000 | W79: ='📊 Base Mensal'!E26 -> 0.8449164
L80: M04 | M80: ='📊 Base Mensal'!F11 -> 109078.5 | N80: ='📊 Base Mensal'!F9 -> 1915 | O80: ='📊 Base Mensal'!F5 -> 3000 | P80: ='📊 Base Mensal'!F24 -> 23230.937 | Q80: ='📊 Base Mensal'!F25 -> -30899.864 | R80: ='📊 Base Mensal'!F6 -> 985 | S80: ='📊 Base Mensal'!F7 -> 719 | T80: ='📊 Base Mensal'!F8 -> 211 | U80: ='📊 Base Mensal'!F18 -> 16667.358 | V80: ='📊 Base Mensal'!F20 -> 55000 | W80: ='📊 Base Mensal'!F26 -> 0.84719851
L81: M05 | M81: ='📊 Base Mensal'!G11 -> 134843.6 | N81: ='📊 Base Mensal'!G9 -> 2364 | O81: ='📊 Base Mensal'!G5 -> 3000 | P81: ='📊 Base Mensal'!G24 -> 41872.273 | Q81: ='📊 Base Mensal'!G25 -> 10972.41 | R81: ='📊 Base Mensal'!G6 -> 1206 | S81: ='📊 Base Mensal'!G7 -> 893 | T81: ='📊 Base Mensal'!G8 -> 265 | U81: ='📊 Base Mensal'!G18 -> 20441.659 | V81: ='📊 Base Mensal'!G20 -> 55000 | W81: ='📊 Base Mensal'!G26 -> 0.84840468
L82: M06 | M82: ='📊 Base Mensal'!H11 -> 159061.5 | N82: ='📊 Base Mensal'!H9 -> 2785 | O82: ='📊 Base Mensal'!H5 -> 3000 | P82: ='📊 Base Mensal'!H24 -> 59384.705 | Q82: ='📊 Base Mensal'!H25 -> 70357.115 | R82: ='📊 Base Mensal'!H6 -> 1410 | S82: ='📊 Base Mensal'!H7 -> 1058 | T82: ='📊 Base Mensal'!H8 -> 317 | U82: ='📊 Base Mensal'!H18 -> 23998.8 | V82: ='📊 Base Mensal'!H20 -> 55000 | W82: ='📊 Base Mensal'!H26 -> 0.84912251
L83: M07 | M83: ='📊 Base Mensal'!I11 -> 181792.1 | N83: ='📊 Base Mensal'!I9 -> 3179 | O83: ='📊 Base Mensal'!I5 -> 3000 | P83: ='📊 Base Mensal'!I24 -> 75810.175 | Q83: ='📊 Base Mensal'!I25 -> 146167.29 | R83: ='📊 Base Mensal'!I6 -> 1597 | S83: ='📊 Base Mensal'!I7 -> 1215 | T83: ='📊 Base Mensal'!I8 -> 367 | U83: ='📊 Base Mensal'!I18 -> 27348.952 | V83: ='📊 Base Mensal'!I20 -> 55000 | W83: ='📊 Base Mensal'!I26 -> 0.84955918
L84: M08 | M84: ='📊 Base Mensal'!J11 -> 203215.1 | N84: ='📊 Base Mensal'!J9 -> 3549 | O84: ='📊 Base Mensal'!J5 -> 3000 | P84: ='📊 Base Mensal'!J24 -> 91280.094 | Q84: ='📊 Base Mensal'!J25 -> 237447.38 | R84: ='📊 Base Mensal'!J6 -> 1769 | S84: ='📊 Base Mensal'!J7 -> 1364 | T84: ='📊 Base Mensal'!J8 -> 416 | U84: ='📊 Base Mensal'!J18 -> 30517.043 | V84: ='📊 Base Mensal'!J20 -> 55000 | W84: ='📊 Base Mensal'!J26 -> 0.84982886
L85: M09 | M85: ='📊 Base Mensal'!K11 -> 223440.3 | N85: ='📊 Base Mensal'!K9 -> 3897 | O85: ='📊 Base Mensal'!K5 -> 3000 | P85: ='📊 Base Mensal'!K24 -> 105873.99 | Q85: ='📊 Base Mensal'!K25 -> 343321.37 | R85: ='📊 Base Mensal'!K6 -> 1927 | S85: ='📊 Base Mensal'!K7 -> 1506 | T85: ='📊 Base Mensal'!K8 -> 464 | U85: ='📊 Base Mensal'!K18 -> 33519.071 | V85: ='📊 Base Mensal'!K20 -> 55000 | W85: ='📊 Base Mensal'!K26 -> 0.84998646
L86: M10 | M86: ='📊 Base Mensal'!L11 -> 242487.6 | N86: ='📊 Base Mensal'!L9 -> 4224 | O86: ='📊 Base Mensal'!L5 -> 3000 | P86: ='📊 Base Mensal'!L24 -> 119610.79 | Q86: ='📊 Base Mensal'!L25 -> 462932.16 | R86: ='📊 Base Mensal'!L6 -> 2073 | S86: ='📊 Base Mensal'!L7 -> 1641 | T86: ='📊 Base Mensal'!L8 -> 510 | U86: ='📊 Base Mensal'!L18 -> 36353.425 | V86: ='📊 Base Mensal'!L20 -> 55000 | W86: ='📊 Base Mensal'!L26 -> 0.85008131
L87: M11 | M87: ='📊 Base Mensal'!M11 -> 260436.9 | N87: ='📊 Base Mensal'!M9 -> 4531 | O87: ='📊 Base Mensal'!M5 -> 3000 | P87: ='📊 Base Mensal'!M24 -> 132546.73 | Q87: ='📊 Base Mensal'!M25 -> 595478.89 | R87: ='📊 Base Mensal'!M6 -> 2207 | S87: ='📊 Base Mensal'!M7 -> 1769 | T87: ='📊 Base Mensal'!M8 -> 555 | U87: ='📊 Base Mensal'!M18 -> 39033.373 | V87: ='📊 Base Mensal'!M20 -> 55000 | W87: ='📊 Base Mensal'!M26 -> 0.85012349
L88: M12 | M88: ='📊 Base Mensal'!N11 -> 277318.1 | N88: ='📊 Base Mensal'!N9 -> 4819 | O88: ='📊 Base Mensal'!N5 -> 3000 | P88: ='📊 Base Mensal'!N24 -> 144705.1 | Q88: ='📊 Base Mensal'!N25 -> 740183.99 | R88: ='📊 Base Mensal'!N6 -> 2330 | S88: ='📊 Base Mensal'!N7 -> 1891 | T88: ='📊 Base Mensal'!N8 -> 598 | U88: ='📊 Base Mensal'!N18 -> 41561.644 | V88: ='📊 Base Mensal'!N20 -> 55000 | W88: ='📊 Base Mensal'!N26 -> 0.85013007
L89: M13 | M89: ='📊 Base Mensal'!O11 -> 298641.5 | N89: ='📊 Base Mensal'!O9 -> 5185 | O89: ='📊 Base Mensal'!O5 -> 3500 | P89: ='📊 Base Mensal'!O24 -> 144949.37 | Q89: ='📊 Base Mensal'!O25 -> 885133.37 | R89: ='📊 Base Mensal'!O6 -> 2494 | S89: ='📊 Base Mensal'!O7 -> 2041 | T89: ='📊 Base Mensal'!O8 -> 650 | U89: ='📊 Base Mensal'!O18 -> 44868.731 | V89: ='📊 Base Mensal'!O20 -> 70000 | W89: ='📊 Base Mensal'!O26 -> 0.84975721
L90: M14 | M90: ='📊 Base Mensal'!P11 -> 318767.1 | N90: ='📊 Base Mensal'!P9 -> 5529 | O90: ='📊 Base Mensal'!P5 -> 3500 | P90: ='📊 Base Mensal'!P24 -> 159453.27 | Q90: ='📊 Base Mensal'!P25 -> 1044586.6 | R90: ='📊 Base Mensal'!P6 -> 2644 | S90: ='📊 Base Mensal'!P7 -> 2184 | T90: ='📊 Base Mensal'!P8 -> 701 | U90: ='📊 Base Mensal'!P18 -> 47874.107 | V90: ='📊 Base Mensal'!P20 -> 70000 | W90: ='📊 Base Mensal'!P26 -> 0.84981478
L91: M15 | M91: ='📊 Base Mensal'!Q11 -> 337714.8 | N91: ='📊 Base Mensal'!Q9 -> 5852 | O91: ='📊 Base Mensal'!Q5 -> 3500 | P91: ='📊 Base Mensal'!Q24 -> 173100.07 | Q91: ='📊 Base Mensal'!Q25 -> 1217686.7 | R91: ='📊 Base Mensal'!Q6 -> 2782 | S91: ='📊 Base Mensal'!Q7 -> 2320 | T91: ='📊 Base Mensal'!Q8 -> 750 | U91: ='📊 Base Mensal'!Q18 -> 50711.809 | V91: ='📊 Base Mensal'!Q20 -> 70000 | W91: ='📊 Base Mensal'!Q26 -> 0.84983836
L92: M16 | M92: ='📊 Base Mensal'!R11 -> 355614.4 | N92: ='📊 Base Mensal'!R9 -> 6156 | O92: ='📊 Base Mensal'!R5 -> 3500 | P92: ='📊 Base Mensal'!R24 -> 185983.59 | Q92: ='📊 Base Mensal'!R25 -> 1403670.3 | R92: ='📊 Base Mensal'!R6 -> 2909 | S92: ='📊 Base Mensal'!R7 -> 2449 | T92: ='📊 Base Mensal'!R8 -> 798 | U92: ='📊 Base Mensal'!R18 -> 53400.935 | V92: ='📊 Base Mensal'!R20 -> 70000 | W92: ='📊 Base Mensal'!R26 -> 0.84983472
L93: M17 | M93: ='📊 Base Mensal'!S11 -> 372495.8 | N93: ='📊 Base Mensal'!S9 -> 6442 | O93: ='📊 Base Mensal'!S5 -> 3500 | P93: ='📊 Base Mensal'!S24 -> 198127.13 | Q93: ='📊 Base Mensal'!S25 -> 1601797.4 | R93: ='📊 Base Mensal'!S6 -> 3026 | S93: ='📊 Base Mensal'!S7 -> 2572 | T93: ='📊 Base Mensal'!S8 -> 844 | U93: ='📊 Base Mensal'!S18 -> 55944.213 | V93: ='📊 Base Mensal'!S20 -> 70000 | W93: ='📊 Base Mensal'!S26 -> 0.8498125
L94: M18 | M94: ='📊 Base Mensal'!T11 -> 388428.9 | N94: ='📊 Base Mensal'!T9 -> 6711 | O94: ='📊 Base Mensal'!T5 -> 3500 | P94: ='📊 Base Mensal'!T24 -> 209582.57 | Q94: ='📊 Base Mensal'!T25 -> 1811380 | R94: ='📊 Base Mensal'!T6 -> 3134 | S94: ='📊 Base Mensal'!T7 -> 2688 | T94: ='📊 Base Mensal'!T8 -> 889 | U94: ='📊 Base Mensal'!T18 -> 58350.573 | V94: ='📊 Base Mensal'!T20 -> 70000 | W94: ='📊 Base Mensal'!T26 -> 0.84977798
L95: M19 | M95: ='📊 Base Mensal'!U11 -> 403453.6 | N95: ='📊 Base Mensal'!U9 -> 6964 | O95: ='📊 Base Mensal'!U5 -> 3500 | P95: ='📊 Base Mensal'!U24 -> 220377.55 | Q95: ='📊 Base Mensal'!U25 -> 2031757.5 | R95: ='📊 Base Mensal'!U6 -> 3233 | S95: ='📊 Base Mensal'!U7 -> 2799 | T95: ='📊 Base Mensal'!U8 -> 932 | U95: ='📊 Base Mensal'!U18 -> 60627.084 | V95: ='📊 Base Mensal'!U20 -> 70000 | W95: ='📊 Base Mensal'!U26 -> 0.84972972
L96: M20 | M96: ='📊 Base Mensal'!V11 -> 417639.8 | N96: ='📊 Base Mensal'!V9 -> 7202 | O96: ='📊 Base Mensal'!V5 -> 3500 | P96: ='📊 Base Mensal'!V24 -> 230563.95 | Q96: ='📊 Base Mensal'!V25 -> 2262321.5 | R96: ='📊 Base Mensal'!V6 -> 3324 | S96: ='📊 Base Mensal'!V7 -> 2904 | T96: ='📊 Base Mensal'!V8 -> 974 | U96: ='📊 Base Mensal'!V18 -> 62782.676 | V96: ='📊 Base Mensal'!V20 -> 70000 | W96: ='📊 Base Mensal'!V26 -> 0.84967267
L97: M21 | M97: ='📊 Base Mensal'!W11 -> 431097.3 | N97: ='📊 Base Mensal'!W9 -> 7427 | O97: ='📊 Base Mensal'!W5 -> 3500 | P97: ='📊 Base Mensal'!W24 -> 240221.3 | Q97: ='📊 Base Mensal'!W25 -> 2502542.8 | R97: ='📊 Base Mensal'!W6 -> 3408 | S97: ='📊 Base Mensal'!W7 -> 3004 | T97: ='📊 Base Mensal'!W8 -> 1015 | U97: ='📊 Base Mensal'!W18 -> 64833.346 | V97: ='📊 Base Mensal'!W20 -> 70000 | W97: ='📊 Base Mensal'!W26 -> 0.84960855
L98: M22 | M98: ='📊 Base Mensal'!X11 -> 443826.1 | N98: ='📊 Base Mensal'!X9 -> 7639 | O98: ='📊 Base Mensal'!X5 -> 3500 | P98: ='📊 Base Mensal'!X24 -> 249349.61 | Q98: ='📊 Base Mensal'!X25 -> 2751892.4 | R98: ='📊 Base Mensal'!X6 -> 3485 | S98: ='📊 Base Mensal'!X7 -> 3099 | T98: ='📊 Base Mensal'!X8 -> 1055 | U98: ='📊 Base Mensal'!X18 -> 66779.096 | V98: ='📊 Base Mensal'!X20 -> 70000 | W98: ='📊 Base Mensal'!X26 -> 0.8495377
L99: M23 | M99: ='📊 Base Mensal'!Y11 -> 455796.2 | N99: ='📊 Base Mensal'!Y9 -> 7838 | O99: ='📊 Base Mensal'!Y5 -> 3500 | P99: ='📊 Base Mensal'!Y24 -> 257930.21 | Q99: ='📊 Base Mensal'!Y25 -> 3009822.6 | R99: ='📊 Base Mensal'!Y6 -> 3556 | S99: ='📊 Base Mensal'!Y7 -> 3189 | T99: ='📊 Base Mensal'!Y8 -> 1093 | U99: ='📊 Base Mensal'!Y18 -> 68612.484 | V99: ='📊 Base Mensal'!Y20 -> 70000 | W99: ='📊 Base Mensal'!Y26 -> 0.84946675
L100: M24 | M100: ='📊 Base Mensal'!Z11 -> 467197.3 | N100: ='📊 Base Mensal'!Z9 -> 8027 | O100: ='📊 Base Mensal'!Z5 -> 3500 | P100: ='📊 Base Mensal'!Z24 -> 266098.87 | Q100: ='📊 Base Mensal'!Z25 -> 3275921.5 | R100: ='📊 Base Mensal'!Z6 -> 3622 | S100: ='📊 Base Mensal'!Z7 -> 3275 | T100: ='📊 Base Mensal'!Z8 -> 1130 | U100: ='📊 Base Mensal'!Z18 -> 70362.778 | V100: ='📊 Base Mensal'!Z20 -> 70000 | W100: ='📊 Base Mensal'!Z26 -> 0.84939387
L102: Cenário | M102: Aporte R$1M | N102: Valuation 100% M24 | O102: ="Retorno Anjo ("&TEXT('🎛️ Premissas'!$B$59,"0%")&")" -> Retorno Anjo (15%)
L103: Conservador | M103: ='🎛️ Premissas'!$B$58/1000000 -> 1 | N103: ='📊 Resumo Cenários'!B21/1000000 -> 19.914787 | O103: ='📊 Resumo Cenários'!B22/1000000 -> 2.987218
...

Sheet 📋 Sumário Executivo
B2: AUTONOMA · SUMÁRIO EXECUTIVO
B3: Asset-Light SaaS · IA pessoal para a mulher brasileira · Brasil → LATAM · Horizonte 24 meses
B6: 1 · A EMPRESA
B7: Visão | C7: Ser a assistente de IA de referência para autonomia pessoal e financeira na América Latina, começando pelo Brasil.
B8: Problema | C8: Assistentes genéricos não executam tarefas de ponta a ponta: a usuária ainda carrega a carga mental de planejar, lembrar e resolver.
B9: Solução | C9: Noma: assistente com memória + agentes autônomos que resolvem tarefas completas (Sonnet 4.6 nos planos pagos; Haiku 4.5 no Free como custo de aquisição).
B10: Por que agora | C10: Custo por token em queda (caching -35% a -45%), agentes maduros para produção e mercado brasileiro sem player focado nesse público.
B12: 2 · MODELO DE NEGÓCIO · PLANOS
B13: Plano | C13: Preço (R$/mês) | D13: Modelo IA | E13: Inclui | F13: Papel no funil
B14: Free | C14: 0 | D14: Haiku 4.5 | E14: 50 interações/mês | F14: Aquisição (custo de mkt)
B15: Essencial | C15: ='🔧 Cenário Ativo'!B6 -> 39.9 | D15: Sonnet 4.6 | E15: Chat ilimitado + memória · agentes especializados avulsos (média R$ 10/mês) | F15: Volume · base da receita
B16: Autônoma | C16: ='🔧 Cenário Ativo'!B7 -> 59.9 | D16: Sonnet 4.6 | E16: Chat + 1 agente autônomo | F16: Upsell · lock-in
B17: Livre | C17: ='🔧 Cenário Ativo'!B8 -> 79.9 | D17: Sonnet 4.6 | E17: Chat + 2 agentes | F17: Premium · máximo lock-in
B18: Preços dinâmicos conforme o cenário selecionado em 🔧 Cenário Ativo!B2. Margem bruta >80% sustentada por caching e Free em Haiku.
B20: 3 · A OFERTA AO INVESTIDOR ANJO
B21: Aporte | C21: ='🎛️ Premissas'!B58 -> 1000000 | D21: ← entrada única, runway ~18 meses
B22: Equity oferecido | C22: ='🎛️ Premissas'!B59 -> 0.15 | D22: ← fatia adquirida no aporte
B23: Valuation pre-money | C23: ='🎛️ Premissas'!B60 -> 5666666.7 | D23: = aporte ÷ equity − aporte
B24: Valuation post-money | C24: ='🎛️ Premissas'!B61 -> 6666666.7 | D24: = aporte ÷ equity
B25: Uso do capital | C25: 40% Produto · 30% Aquisição · 20% Equipe · 10% Reserva (detalhe em 💎 Resumo Anjo)
B27: 4 · HIGHLIGHTS FINANCEIROS · CENÁRIO ATIVO: | C27: ='🔧 Cenário Ativo'!B2 -> Conservador
B28: Indicador | C28: M12 | D28: M24 | E28: Nota
B29: Assinantes pagantes | C29: ='📊 Base Mensal'!N9 -> 4819 | D29: ='📊 Base Mensal'!Z9 -> 8027 | E29: crescimento composto da base Free
B30: MRR (R$/mês) | C30: ='📊 Base Mensal'!N11 -> 277318.1 | D30: ='📊 Base Mensal'!Z11 -> 467197.3 | E30: receita recorrente mensal
B31: Receita acumulada | C31: ='📊 Base Mensal'!N12 -> 1947589.4 | D31: ='📊 Base Mensal'!Z12 -> 6638262.2 | E31: soma de 24 meses de MRR do cenário ativo (📊 Base Mensal)
B32: Resultado mensal | C32: ='📊 Base Mensal'!N24 -> 144705.1 | D32: ='📊 Base Mensal'!Z24 -> 266098.87 | E32: após API + fixo + impostos
B33: Margem bruta (% MRR) | C33: ='📊 Base Mensal'!N26 -> 0.85013007 | D33: ='📊 Base Mensal'!Z26 -> 0.84939387 | E33: após custo de API
B34: Breakeven de caixa | C34: {=IFERROR("M"&MATCH(TRUE,INDEX('📊 Base Mensal'!C25:Z25>0,0),0),">24m")} -> M5 | E34: resultado acumulado > 0
B35: LTV / CAC (Essencial) | C35: ='🔧 Cenário Ativo'!B56 -> 6.8861031 | E35: =IF(C35>=8,"✅ top quartile",IF(C35>=3,"✅ saudável","⚠️ rever CAC")) -> ✅ saudável
B36: Valuation M24 (cenário ativo) | C36: =IF('🔧 Cenário Ativo'!B2="Conservador",'📊 Resumo Cenários'!B21,IF('🔧 Cenário Ativo'!B2="Base",'📊 Resumo Cenários'!C21,'📊 Resumo Cenários'!D21)) -> 19914787 | E36: receita acum. 24m × múltiplo do cenário
B37: Retorno do anjo (fatia 15%) | C37: =C36*'🎛️ Premissas'!B59 -> 2987218 | D37: =C37/'🎛️ Premissas'!B58 -> 2.987218 | E37: valor da fatia ÷ aporte
B39: 5 · TESE DE INVESTIMENTO
B40: ① Unit economics provados desde o M1: LTV/CAC ≥5× mesmo no cenário Conservador; payback de CAC < 3 meses.
B41: ② Margem de software (>80%) com custo variável controlado: Free roda em Haiku 4.5; pagos em Sonnet 4.6 com caching.
B42: ③ Breakeven rápido (M7 no Conservador) — o aporte financia crescimento, não prejuízo operacional.
B43: ④ Churn decresce com adoção de agentes (8% → 3%): quanto mais a Noma executa, maior o lock-in.
B44: ⑤ Saída viável em 24m: receita acumulada sustenta Série A a 3–7× — retorno de 4–22× sobre o aporte conforme cenário.
B46: Obs.: Este estudo não configura convite ou promessa de investimento. Valores 100% dinâmicos — recalculam ao alterar 🔧 Cenário Ativo!B2 e 🎛️ Premissas. AutoNoma © 2025.

Sheet 🌎 Mercado & GTM
B2: AUTONOMA · MERCADO & GO-TO-MARKET
B3: Dimensionamento TAM/SAM/SOM · funil de aquisição · canais · posicionamento competitivo
B6: 1 · TAMANHO DE MERCADO · BRASIL (inputs editáveis em azul)
B7: Camada | C7: Usuárias | D7: Potencial anual (R$) | E7: % capturado | F7: Definição
B8: TAM · mercado total | C8: 54000000 | D8: =C8*'🔧 Cenário Ativo'!B6*12 -> 25855200000 | F8: Mulheres adultas conectadas no Brasil (estimativa editável)
B9: SAM · mercado endereçável | C9: 12000000 | D9: =C9*'🔧 Cenário Ativo'!B6*12 -> 5745600000 | E9: =C9/C8 -> 0.22222222 | F9: Já pagam assinaturas digitais e usam IA/apps de produtividade
B10: SOM · capturado até M24 (cadastros) | C10: =('🔧 Cenário Ativo'!B30+'🔧 Cenário Ativo'!B31)*12 -> 78000 | D10: ='📊 Base Mensal'!Z11*12 -> 5606367.6 | E10: =C10/C9 -> 0.0065 | F10: Cadastros acumulados em 24m (trial 30 dias) · potencial = ARR no M24
B11: └ dos quais pagantes no M24 | C11: ='📊 Base Mensal'!Z9 -> 8027 | D11: ='📊 Base Mensal'!Z11 -> 467197.3 | E11: =C11/C10 -> 0.10291026 | F11: Taxa de conversão acumulada Free → pago
B12: Penetração exigida do SAM em 24m é inferior a 1% — o plano não depende de dominar o mercado para entregar o retorno projetado.
B14: 2 · FUNIL DE AQUISIÇÃO · CENÁRIO ATIVO (valores dinâmicos)
B15: Etapa do funil | C15: Valor | D15: Unidade | F15: Leitura
B16: Novos cadastros Free · M1–M12 | C16: ='🔧 Cenário Ativo'!B30 -> 3000 | D16: leads/mês | F16: orgânico + viral + paid
B17: Novos cadastros Free · M13–M24 | C17: ='🔧 Cenário Ativo'!B31 -> 3500 | D17: leads/mês | F17: escala nacional
B18: Conversão Free → Essencial | C18: ='🔧 Cenário Ativo'!B32 -> 0.1 | D18: da base elegível/mês | F18: porta de entrada paga
B19: Upgrade Essencial → Autônoma | C19: ='🔧 Cenário Ativo'!B33 -> 0.07 | D19: da base elegível/mês | F19: 1º agente autônomo
B20: Upgrade Autônoma → Livre | C20: ='🔧 Cenário Ativo'!B34 -> 0.02 | D20: da base elegível/mês | F20: tier premium
B21: Churn mensal (Essencial / Autônoma / Livre) | C21: =TEXT('🔧 Cenário Ativo'!B35,"0%")&" / "&TEXT('🔧 Cenário Ativo'!B36,"0%")&" / "&TEXT('🔧 Cenário Ativo'!B37,"0%") -> 8% / 5% / 3% | D21: %/mês | F21: lock-in cresce com agentes
B22: CAC full-loaded | C22: ='🔧 Cenário Ativo'!B47 -> 80 | D22: por assinante | F22: ="payback em "&TEXT('🔧 Cenário Ativo'!B57,"0,0")&" meses" -> payback em 1,8 meses
B23: % aquisição via paid (vs. orgânico) | C23: ='🔧 Cenário Ativo'!B48 -> 0.5 | D23: dos novos pagantes | F23: restante: orgânico, viral, parcerias
B25: 3 · CANAIS & ESTRATÉGIA DE ENTRADA
B26: Orgânico & viral | C26: Conteúdo curto (TikTok/Reels/Shorts) mostrando a Noma executando tarefas reais · programa de indicação dentro do app
B27: Paid social | C27: Meta + TikTok Ads com criativos de caso de uso · ~50% dos novos pagantes · teto de CAC governado pelas premissas
B28: Parcerias & influenciadoras | C28: Criadoras de finanças pessoais, carreira e maternidade · cupons rastreáveis por canal
B29: Free como motor | C29: Plano Free (Haiku 4.5, 50 interações/mês) é o custo de aquisição: a usuária experimenta valor antes de pagar
B31: 4 · POSICIONAMENTO COMPETITIVO
B32: Player | C32: Preço (R$/mês) | D32: Foco | F32: Por que a AutoNoma ganha
B33: ChatGPT / Gemini (genéricos) | C33: ~R$ 100+ | D33: chat generalista | F33: Agentes que executam ponta a ponta + memória de contexto pessoal + preço em reais acessível
B34: Apps de produtividade/organização | C34: R$ 20–50 | D34: listas e lembretes | F34: A Noma não lembra a tarefa — ela faz a tarefa
B35: Assistentes embarcados (bancos, e-commerce) | C35: grátis | D35: vertical único | F35: Visão transversal da vida da usuária, não de um único produto
B36: AutoNoma | C36: ="R$ "&TEXT('🔧 Cenário Ativo'!B6,"0,00")&"–"&TEXT('🔧 Cenário Ativo'!B8,"0,00") -> R$ 39,90–79,90 | D36: agentes pessoais | F36: Foco no público, agentes autônomos, custo variável otimizado (Haiku Free / Sonnet pago)
B38: Obs.: valores de mercado são estimativas editáveis para dimensionamento — não substituem pesquisa formal. AutoNoma © 2025.

Sheet 💎 Resumo Anjo
B2: AUTONOMA · RESUMO PARA INVESTIDOR ANJO
B3: Asset-Light SaaS · Brasil → LATAM · Sonnet 4.6 (planos pagos) + Haiku 4.5 (Free) · Horizonte 24 meses
B5: 1 · A OFERTA
B6: Aporte | C6: ='🎛️ Premissas'!B58 -> 1000000 | D6: ← entrada do anjo
B7: Equity oferecido | C7: ='🎛️ Premissas'!B59 -> 0.15 | D7: ← fatia adquirida
B8: Valuation post-money | C8: ='🎛️ Premissas'!B61 -> 6666666.7 | D8: = aporte ÷ equity
B9: Valuation pre-money | C9: ='🎛️ Premissas'!B60 -> 5666666.7
B11: 2 · MARCOS ATÉ A SÉRIE A (cenário Base)
B12: Indicador | C12: M12 | D12: M24
B13: Assinantes pagantes | C13: ='📊 Base Mensal'!N9 -> 4819 | D13: ='📊 Base Mensal'!Z9 -> 8027
B14: MRR (R$/mês) | C14: ='📊 Base Mensal'!N11 -> 277318.1 | D14: ='📊 Base Mensal'!Z11 -> 467197.3
B15: Receita acumulada | C15: ='📊 Base Mensal'!N12 -> 1947589.4 | D15: ='📊 Base Mensal'!Z12 -> 6638262.2
B16: Margem bruta | C16: ='📊 Base Mensal'!N26 -> 0.85013007 | D16: ='📊 Base Mensal'!Z26 -> 0.84939387
B17: Resultado mensal | C17: ='📊 Base Mensal'!N24 -> 144705.1 | D17: ='📊 Base Mensal'!Z24 -> 266098.87
B19: 3 · RETORNO DO ANJO (fatia de 15%)
B20: Cenário | C20: Valuation M24 | D20: Valor da fatia 15% | E20: Múltiplo s/ aporte
B21: Conservador | C21: ='📊 Resumo Cenários'!B21 -> 19914787 | D21: =C21*'🎛️ Premissas'!$B$59 -> 2987218 | E21: =D21/'🎛️ Premissas'!$B$58 -> 2.987218
B22: Base | C22: ='📊 Resumo Cenários'!C21 -> 50824494 | D22: =C22*'🎛️ Premissas'!$B$59 -> 7623674 | E22: =D22/'🎛️ Premissas'!$B$58 -> 7.623674
B23: Otimista | C23: ='📊 Resumo Cenários'!D21 -> 1.0118223e+08 | D23: =C23*'🎛️ Premissas'!$B$59 -> 15177334 | E23: =D23/'🎛️ Premissas'!$B$58 -> 15.177334
B25: 4 · USO DO CAPITAL (R$1M · ~runway 18 meses)
B26: Produto & Engenharia (Sonnet/Haiku, dev) | C26: 0.4 | D26: =C26*'🎛️ Premissas'!$B$58 -> 400000
B27: Aquisição & Marketing (CAC, growth) | C27: 0.3 | D27: =C27*'🎛️ Premissas'!$B$58 -> 300000
B28: Equipe & Operação (CS, pró-labore) | C28: 0.2 | D28: =C28*'🎛️ Premissas'!$B$58 -> 200000
B29: Reserva & Jurídico/Contab. | C29: 0.1 | D29: =C29*'🎛️ Premissas'!$B$58 -> 100000
B30: Total | C30: =SUM(C26:C29) -> 1 | D30: =SUM(D26:D29) -> 1000000
B32: 5 · TESTE DE STRESS / DOWNSIDE (honestidade ao anjo)
B33: ="• Mesmo no cenário Conservador, o aporte retorna ~"&TEXT('📊 Resumo Cenários'!B23,"0,0")&"× em 24 meses (fatia "&TEXT('🎛️ Premissas'!B59,"0%")&" = R$ "&TEXT('📊 Resumo Cenários'!B22/1000000,"0,0")&" M)." -> • Mesmo no cenário Conservador, o aporte retorna ~3,0× em 24 meses (fatia 15% = R$ 3,0 M).
B34: • Churn diferenciado por plano: Essencial 8%, Autônoma 5%, Livre 3% — lock-in cresce com o agente.
B35: • Break-even de caixa no M6; margem bruta >80% sustentada por rodar o Free em Haiku (só custo).
B36: • Sensível a: CAC real (hoje R$60 full-loaded) e conversão Free→pago. Ambos controláveis em 🎛️ Premissas.
B37: • Próximo marco: Receita acum. R$15M no M24 sustenta conversão Série A a 5× receita (≈R$75M).
B39: Obs.: Este resumo não configura convite ou promessa de investimento. Todos os valores recalculam ao alterar o cenário em 🔧 Cenário Ativo e as premissas em 🎛️ Premissas. AutoNoma © 2025.
B42: 6 · SENSIBILIDADE: CHURN × LTV/CAC (plano Essencial, cenário Base)
B43: Churn/mês | C43: Vida média (m) | D43: LTV (R$) | E43: LTV / CAC | F43: Leitura
B44: 0.05 | C44: =1/B44 -> 20 | D44: ='📊 Resumo Cenários'!$C$13*C44 -> 867.1112 | E44: =D44/'🎛️ Premissas'!$C$48 -> 14.451853 | F44: =IF(E44>=8,"✅ top quartile",IF(E44>=3,"✅ saudável","⚠️ rever CAC")) -> ✅ top quartile
B45: 0.06 | C45: =1/B45 -> 16.666667 | D45: ='📊 Resumo Cenários'!$C$13*C45 -> 722.59267 | E45: =D45/'🎛️ Premissas'!$C$48 -> 12.043211 | F45: =IF(E45>=8,"✅ top quartile",IF(E45>=3,"✅ saudável","⚠️ rever CAC")) -> ✅ top quartile
B46: 0.07 | C46: =1/B46 -> 14.285714 | D46: ='📊 Resumo Cenários'!$C$13*C46 -> 619.36514 | E46: =D46/'🎛️ Premissas'!$C$48 -> 10.322752 | F46: =IF(E46>=8,"✅ top quartile",IF(E46>=3,"✅ saudável","⚠️ rever CAC")) -> ✅ top quartile
B47: 0.08 | C47: =1/B47 -> 12.5 | D47: ='📊 Resumo Cenários'!$C$13*C47 -> 541.9445 | E47: =D47/'🎛️ Premissas'!$C$48 -> 9.0324083 | F47: =IF(E47>=8,"✅ top quartile",IF(E47>=3,"✅ saudável","⚠️ rever CAC")) -> ✅ top quartile
B48: 0.1 | C48: =1/B48 -> 10 | D48: ='📊 Resumo Cenários'!$C$13*C48 -> 433.5556 | E48: =D48/'🎛️ Premissas'!$C$48 -> 7.2259267 | F48: =IF(E48>=8,"✅ top quartile",IF(E48>=3,"✅ saudável","⚠️ rever CAC")) -> ✅ saudável
B49: 0.12 | C49: =1/B49 -> 8.3333333 | D49: ='📊 Resumo Cenários'!$C$13*C49 -> 361.29633 | E49: =D49/'🎛️ Premissas'!$C$48 -> 6.0216056 | F49: =IF(E49>=8,"✅ top quartile",IF(E49>=3,"✅ saudável","⚠️ rever CAC")) -> ✅ saudável
...

Sheet 📈 DRE Anual
B2: AUTONOMA · DRE PROJETADO · ANO 1 & ANO 2
B3: ="Consolidado da 📊 Base Mensal · cenário ativo: "&'🔧 Cenário Ativo'!B2&" · valores recalculam ao trocar o cenário" -> Consolidado da 📊 Base Mensal · cenário ativo: Conservador · valores recalculam ao trocar o cenário
B6: Linha (R$) | C6: Ano 1 (M1–M12) | D6: Ano 2 (M13–M24) | E6: Total 24m | F6: Nota
B7: Receita bruta (assinaturas) | C7: =SUM('📊 Base Mensal'!C11:N11) -> 1947589.4 | D7: =SUM('📊 Base Mensal'!O11:Z11) -> 4690672.8 | E7: =C7+D7 -> 6638262.2 | F7: soma do MRR mensal
B8: (−) Impostos sobre receita | C8: =-SUM('📊 Base Mensal'!C21:N21) -> -253186.62 | D8: =-SUM('📊 Base Mensal'!O21:Z21) -> -609787.46 | E8: =C8+D8 -> -862974.09 | F8: ="Simples Nacional "&TEXT('🔧 Cenário Ativo'!B59,"0,0%")&" sobre o MRR" -> Simples Nacional 13,0% sobre o MRR
B9: (=) Receita líquida | C9: =C7+C8 -> 1694402.8 | D9: =D7+D8 -> 4080885.3 | E9: =C9+D9 -> 5775288.1
B10: (−) Custo variável · API Anthropic | C10: =-SUM('📊 Base Mensal'!C18:N18) -> -294218.78 | D10: =-SUM('📊 Base Mensal'!O18:Z18) -> -705147.83 | E10: =C10+D10 -> -999366.62 | F10: tokens Free (Haiku) + pagos (Sonnet, c/ caching)
B11: (=) Lucro bruto | C11: =C9+C10 -> 1400184 | D11: =D9+D10 -> 3375737.5 | E11: =C11+D11 -> 4775921.5
B12: Margem bruta (% receita bruta) | C12: =IF(C7=0,0,C11/C7) -> 0.71893182 | D12: =IF(D7=0,0,D11/D7) -> 0.71967022 | E12: =IF(E7=0,0,E11/E7) -> 0.71945358
B13: (−) Custos fixos operacionais | C13: =-SUM('📊 Base Mensal'!C20:N20) -> -660000 | D13: =-SUM('📊 Base Mensal'!O20:Z20) -> -840000 | E13: =C13+D13 -> -1500000 | F13: abertura abaixo
B14: ├ Equipe | C14: =-'🔧 Cenário Ativo'!B39*12 -> -480000 | D14: =-'🔧 Cenário Ativo'!B40*12 -> -600000 | E14: =C14+D14 -> -1080000
B15: ├ Infraestrutura & ferramentas | C15: =-'🔧 Cenário Ativo'!B41*12 -> -60000 | D15: =-'🔧 Cenário Ativo'!B42*12 -> -84000 | E15: =C15+D15 -> -144000
B16: ├ Marketing & aquisição | C16: =-'🔧 Cenário Ativo'!B43*12 -> -60000 | D16: =-'🔧 Cenário Ativo'!B44*12 -> -96000 | E16: =C16+D16 -> -156000
B17: └ Outros (contábil, jurídico, admin) | C17: =-'🔧 Cenário Ativo'!B45*12 -> -60000 | D17: =-'🔧 Cenário Ativo'!B45*12 -> -60000 | E17: =C17+D17 -> -120000
B18: (=) EBITDA ≈ resultado operacional | C18: =C11+C13 -> 740183.99 | D18: =D11+D13 -> 2535737.5 | E18: =C18+D18 -> 3275921.5 | F18: asset-light: sem capex relevante, sem dívida
B19: Margem EBITDA (% receita bruta) | C19: =IF(C7=0,0,C18/C7) -> 0.38005136 | D19: =IF(D7=0,0,D18/D7) -> 0.54059143 | E19: =IF(E7=0,0,E18/E7) -> 0.49349083
B21: Resultado acumulado ao fim do período | C21: ='📊 Base Mensal'!N25 -> 740183.99 | D21: ='📊 Base Mensal'!Z25 -> 3275921.5 | F21: conferência com a linha 25 da 📊 Base Mensal
B22: Checagem · EBITDA 24m = resultado acumulado M24 | C22: =IF(ROUND(E18-D21,0)=0,"✅ confere","⚠️ diverge em R$ "&TEXT(E18-D21,"#.##0")) -> ✅ confere
B24: Obs.: DRE regime de competência simplificado (sem D&A, resultado financeiro ou IR adicional — Simples Nacional sobre receita). CAC pago está contido em Marketing & aquisição.

Sheet 💰 Caixa & Runway
B2: AUTONOMA · CAIXA & RUNWAY · 24 MESES
B3: ="Aporte de R$ "&TEXT('🎛️ Premissas'!B58,"#.##0")&" no M1 + resultado operacional mensal · cenário: "&'🔧 Cenário Ativo'!B2 -> Aporte de R$ 1.000.000 no M1 + resultado operacional mensal · cenário: Conservador
B6: FLUXO DE CAIXA MENSAL (R$)
B7: Mês | C7: ='📊 Base Mensal'!C3 -> M01 | D7: ='📊 Base Mensal'!D3 -> M02 | E7: ='📊 Base Mensal'!E3 -> M03 | F7: ='📊 Base Mensal'!F3 -> M04 | G7: ='📊 Base Mensal'!G3 -> M05 | H7: ='📊 Base Mensal'!H3 -> M06 | I7: ='📊 Base Mensal'!I3 -> M07 | J7: ='📊 Base Mensal'!J3 -> M08 | ... Z7: ='📊 Base Mensal'!Z3 -> M24 ★
B8: Entrada de capital (aporte anjo) | C8: =IF(C7="M01",'🎛️ Premissas'!$B$58,0) -> 1000000 | D8: =IF(D7="M01",'🎛️ Premissas'!$B$58,0) -> 0 | E8: =IF(E7="M01",'🎛️ Premissas'!$B$58,0) -> 0 | F8: =IF(F7="M01",'🎛️ Premissas'!$B$58,0) -> 0 | G8: =IF(G7="M01",'🎛️ Premissas'!$B$58,0) -> 0 | H8: =IF(H7="M01",'🎛️ Premissas'!$B$58,0) -> 0 | I8: =IF(I7="M01",'🎛️ Premissas'!$B$58,0) -> 0 | J8: =IF(J7="M01",'🎛️ Premissas'!$B$58,0) -> 0 | ... Z8: =IF(Z7="M01",'🎛️ Premissas'!$B$58,0) -> 0
B9: Resultado operacional do mês | C9: ='📊 Base Mensal'!C24 -> -39903.991 | D9: ='📊 Base Mensal'!D24 -> -17668.581 | E9: ='📊 Base Mensal'!E24 -> 3441.7706 | F9: ='📊 Base Mensal'!F24 -> 23230.937 | G9: ='📊 Base Mensal'!G24 -> 41872.273 | H9: ='📊 Base Mensal'!H24 -> 59384.705 | I9: ='📊 Base Mensal'!I24 -> 75810.175 | J9: ='📊 Base Mensal'!J24 -> 91280.094 | ... Z9: ='📊 Base Mensal'!Z24 -> 266098.87
B10: Saldo de caixa (fim do mês) | C10: =C8+C9 -> 960096.01 | D10: =C10+D8+D9 -> 942427.43 | E10: =D10+E8+E9 -> 945869.2 | F10: =E10+F8+F9 -> 969100.14 | G10: =F10+G8+G9 -> 1010972.4 | H10: =G10+H8+H9 -> 1070357.1 | I10: =H10+I8+I9 -> 1146167.3 | J10: =I10+J8+J9 -> 1237447.4 | K10: =J10+K8+K9 -> 1343321.4 | ... Z10: =Y10+Z8+Z9 -> 4275921.5
B12: INDICADORES DE RUNWAY & SOLVÊNCIA
B13: Caixa mínimo no período | C13: =MIN(C10:Z10) -> 942427.43 | G13: ="ocorre em "&INDEX(C7:Z7,MATCH(MIN(C10:Z10),C10:Z10,0))&" — "&IF(MIN(C10:Z10)>0,"o aporte cobre toda a curva: caixa nunca fica negativo ✅","⚠️ caixa fica negativo: rever premissas ou aporte") -> ocorre em M02 — o aporte cobre toda a curva: caixa nunca fica negativo ✅
B14: Caixa final · M24 | C14: =Z10 -> 4275921.5 | G14: aporte + resultado acumulado de 24 meses
B15: Burn médio pré-breakeven | C15: =IFERROR(AVERAGEIF(C9:Z9,"<0"),0) -> -28786.286 | G15: média dos meses com resultado negativo
B16: Runway teórico sem receita | C16: ='🎛️ Premissas'!B58/AVERAGE('📊 Base Mensal'!C20:N20) -> 18.181818 | G16: aporte ÷ custo fixo médio do Ano 1 (stress extremo: receita zero)
B17: Breakeven de caixa (resultado acum. > 0) | C17: {=IFERROR("M"&MATCH(TRUE,INDEX('📊 Base Mensal'!C25:Z25>0,0),0),">24m")} -> M5 | G17: a partir daí a operação se autofinancia
B19: Obs.: fluxo de caixa simplificado = aporte + resultado operacional (sem capex, sem dívida, sem dividendos). Cenários alternativos em 📊 Resumo Cenários.

Sheet ⚠️ Riscos & Roadmap
B2: AUTONOMA · RISCOS, MITIGAÇÕES & ROADMAP
B3: Matriz de riscos com gatilhos de monitoramento · roadmap de execução 24 meses · guard-rails de gestão
B6: 1 · MATRIZ DE RISCOS & MITIGAÇÕES
B7: Risco | C7: Probabilidade | D7: Impacto | E7: Mitigação | F7: Gatilho de alerta
B8: CAC acima do previsto (paid saturado) | C8: Média | D8: Alto | E8: Disciplina de LTV/CAC ≥ 3× por canal; realocar verba para orgânico/parcerias; criativos testados semanalmente | F8: CAC blended > R$ 120
B9: Churn acima do plano | C9: Média | D9: Alto | E9: Onboarding guiado; ativação do 1º agente nos primeiros 7 dias (churn cai de 8% para 5–3% com agentes ativos) | F9: Churn Essencial > 10%/mês
B10: Reajuste de preço da API / fim do caching | C10: Baixa | D10: Alto | E10: Arquitetura multi-modelo (camada de abstração); limites de uso por plano; repasse parcial de preço se necessário | F10: Margem bruta < 70%
B11: Câmbio USD/BRL (custo de API dolarizado) | C11: Média | D11: Médio | E11: Margem >80% absorve variações; premissa de câmbio editável em 🎛️ Premissas; reajuste anual de preços | F11: USD > R$ 6,50
B12: Big techs lançam concorrente direto | C12: Alta | D12: Médio | E12: Foco em nicho + marca + memória pessoal acumulada (custo de troca); velocidade de execução local | F12: Queda de conversão nas coortes novas
B13: Dependência de fornecedor único (Anthropic) | C13: Baixa | D13: Alto | E13: Camada de abstração LLM-agnóstica; testes periódicos com modelos alternativos; contrato com SLA | F13: Latência/SLA fora do padrão
B14: LGPD · privacidade de dados sensíveis | C14: Média | D14: Alto | E14: Privacy by design; criptografia em repouso e trânsito; consentimento granular; DPO desde o M1 | F14: Qualquer incidente de dados
B15: Execução com equipe enxuta | C15: Média | D15: Médio | E15: 20% do aporte em equipe; advisors de produto/growth; roadmap com marcos verificáveis por trimestre | F15: Atraso > 1 trimestre nos marcos
B17: 2 · ROADMAP DE EXECUÇÃO · 24 MESES (metas dinâmicas do cenário ativo)
B18: Fase | C18: Período | E18: Entregas-chave | F18: Meta verificável
B19: Lançamento | C19: M1–M3 | E19: App + Noma core (chat com memória) · onboarding · cobrança recorrente · beta com lista de espera | F19: =TEXT('📊 Base Mensal'!E9,"#.##0")&" pagantes no M3" -> 1.437 pagantes no M3
B20: Tração | C20: M4–M6 | E20: 1º agente autônomo (plano Autônoma) · programa de indicação · início de paid em escala | F20: {="Breakeven de caixa em "&IFERROR("M"&MATCH(TRUE,INDEX('📊 Base Mensal'!C25:Z25>0,0),0),">24m")} -> Breakeven de caixa em M5
B21: Escala · Ano 1 | C21: M7–M12 | E21: Plano Livre (2 agentes) · parcerias com influenciadoras · expansão de canais pagos | F21: =TEXT('📊 Base Mensal'!N9,"#.##0")&" pagantes · MRR R$ "&TEXT('📊 Base Mensal'!N11,"#.##0")&" no M12" -> 4.819 pagantes · MRR R$ 277.318 no M12
B22: Expansão | C22: M13–M18 | E22: Novos agentes verticais (finanças, carreira, família) · melhoria de retenção · preparação de dados para due diligence | F22: ="MRR R$ "&TEXT('📊 Base Mensal'!T11,"#.##0")&" no M18" -> MRR R$ 388.429 no M18
B23: Série A ready | C23: M19–M24 | E23: Eficiência de margem · estudo LATAM (espanhol) · captação Série A com métricas auditadas | F23: =TEXT('📊 Base Mensal'!Z9,"#.##0")&" pagantes · valuation R$ "&TEXT(IF('🔧 Cenário Ativo'!B2="Conservador",'📊 Resumo Cenários'!B21,IF('🔧 Cenário Ativo'!B2="Base",'📊 Resumo Cenários'!C21,'📊 Resumo Cenários'!D21))/1000000,"#.##0,0")&" M" -> 8.027 pagantes · valuation R$ 19,9 M
B25: 3 · GUARD-RAILS DE GESTÃO (status automático · cenário ativo)
B26: Indicador | C26: Atual | D26: Limite | E26: Status
B27: LTV / CAC (Essencial) | C27: ='🔧 Cenário Ativo'!B56 -> 6.8861031 | D27: ≥ 3,0× | E27: =IF(C27>=3,"✅ dentro do guard-rail","⚠️ abaixo do mínimo — frear paid e revisar funil") -> ✅ dentro do guard-rail
B28: Payback do CAC | C28: ='🔧 Cenário Ativo'!B57 -> 1.8152502 | D28: ≤ 6 meses | E28: =IF(C28<=6,"✅ dentro do guard-rail","⚠️ payback longo — revisar CAC ou preços") -> ✅ dentro do guard-rail
B29: Margem bruta M24 | C29: ='📊 Base Mensal'!Z26 -> 0.84939387 | D29: ≥ 70% | E29: =IF(C29>=0.7,"✅ dentro do guard-rail","⚠️ margem comprimida — renegociar API/repassar preço") -> ✅ dentro do guard-rail
B30: Caixa mínimo na curva | C30: =MIN('💰 Caixa & Runway'!C10:Z10) -> 942427.43 | D30: > R$ 0 | E30: =IF(C30>0,"✅ aporte cobre toda a curva de caixa","⚠️ caixa negativo — aumentar aporte ou cortar custo") -> ✅ aporte cobre toda a curva de caixa
B32: Obs.: gatilhos e limites são política de gestão sugerida — editáveis conforme governança acordada com o investidor. AutoNoma © 2025.

Sheet 🔧 Cenário Ativo
A1: AutoNoma · Seletor de Cenário · Controler
A2: ▶ CENÁRIO ATIVO ◀ (altere aqui o modelo) | B2: Conservador | C2: ← Selecione: Conservador / Base / Otimista
A3: Coluna das premissas (uso interno — não edite) | B3: =MATCH(B2,{"Conservador","Base","Otimista"},0)+1 -> 2
A4: Premissas resolvidas para o cenário selecionado
A5: ── PREÇOS ──
A6: Preço Essencial | B6: =INDEX('🎛️ Premissas'!B5:D5,1,MATCH($B$2,{"Conservador","Base","Otimista"},0)) -> 39.9 | C6: ← Premissas!Preço Essencial (linha 5)
A7: Preço Autônoma | B7: =INDEX('🎛️ Premissas'!B6:D6,1,MATCH($B$2,{"Conservador","Base","Otimista"},0)) -> 59.9 | C7: ← Premissas!Preço Autônoma (linha 6)
A8: Preço Livre | B8: =INDEX('🎛️ Premissas'!B7:D7,1,MATCH($B$2,{"Conservador","Base","Otimista"},0)) -> 79.9 | C8: ← Premissas!Preço Livre (linha 7)
A9: Receita agentes avulsos / assinante Essencial | B9: =INDEX('🎛️ Premissas'!B8:D8,1,MATCH($B$2,{"Conservador","Base","Otimista"},0)) -> 10 | C9: ← Premissas!Agentes avulsos (linha 8)
A10: ── API ──
A11: Câmbio USD/BRL | B11: =INDEX('🎛️ Premissas'!B10:D10,1,MATCH($B$2,{"Conservador","Base","Otimista"},0)) -> 5.3 | C11: ← Premissas!Câmbio USD/BRL (linha 10)
A12: Sonnet Input $/MTok | B12: =INDEX('🎛️ Premissas'!B13:D13,1,MATCH($B$2,{"Conservador","Base","Otimista"},0)) -> 3 | C12: ← Premissas!Sonnet 4.6 Input ($/MTok) (linha 13)
A13: Sonnet Output $/MTok | B13: =INDEX('🎛️ Premissas'!B14:D14,1,MATCH($B$2,{"Conservador","Base","Otimista"},0)) -> 15 | C13: ← Premissas!Sonnet 4.6 Output ($/MTok) (linha 14)
A14: Haiku Input $/MTok | B14: =INDEX('🎛️ Premissas'!B11:D11,1,MATCH($B$2,{"Conservador","Base","Otimista"},0)) -> 1 | C14: ← Premissas!Haiku 4.5 Input ($/MTok) (linha 11)
A15: Haiku Output $/MTok | B15: =INDEX('🎛️ Premissas'!B12:D12,1,MATCH($B$2,{"Conservador","Base","Otimista"},0)) -> 5 | C15: ← Premissas!Haiku 4.5 Output ($/MTok) (linha 12)
A16: Desconto Caching | B16: =INDEX('🎛️ Premissas'!B15:D15,1,MATCH($B$2,{"Conservador","Base","Otimista"},0)) -> 0.35 | C16: ← Premissas!Desconto Prompt Caching (%) (linha 15)
A17: ── USO ──
A18: Free: interações/mês | B18: =INDEX('🎛️ Premissas'!B17:D17,1,MATCH($B$2,{"Conservador","Base","Otimista"},0)) -> 50 | C18: ← Premissas!Free: interações/mês (LIMITE) (linha 14)
A19: Free: tokens input | B19: =INDEX('🎛️ Premissas'!B18:D18,1,MATCH($B$2,{"Conservador","Base","Otimista"},0)) -> 900 | C19: ← Premissas!Free: tokens input/interação (linha 15)
A20: Free: tokens output | B20: =INDEX('🎛️ Premissas'!B19:D19,1,MATCH($B$2,{"Conservador","Base","Otimista"},0)) -> 450 | C20: ← Premissas!Free: tokens output/interação (linha 16)
A21: Free: % ativas/mês | B21: =INDEX('🎛️ Premissas'!B20:D20,1,MATCH($B$2,{"Conservador","Base","Otimista"},0)) -> 0.5 | C21: ← Premissas!Free: % usuárias ativas/mês (linha 17)
A22: Essencial: interações/mês | B22: =INDEX('🎛️ Premissas'!B21:D21,1,MATCH($B$2,{"Conservador","Base","Otimista"},0)) -> 120 | C22: ← Premissas!Essencial: interações chat/mês (linha 18)
A23: Essencial: tokens input | B23: =INDEX('🎛️ Premissas'!B22:D22,1,MATCH($B$2,{"Conservador","Base","Otimista"},0)) -> 1200 | C23: ← Premissas!Essencial: tokens input/interação (linha 19)
A24: Essencial: tokens output | B24: =INDEX('🎛️ Premissas'!B23:D23,1,MATCH($B$2,{"Conservador","Base","Otimista"},0)) -> 700 | C24: ← Premissas!Essencial: tokens output/interação (linha 20)
A25: Autônoma: sessões agente/mês | B25: =INDEX('🎛️ Premissas'!B25:D25,1,MATCH($B$2,{"Conservador","Base","Otimista"},0)) -> 35 | C25: ← Premissas!Autônoma: sessões agente/mês (linha 22)
A26: Autônoma: tokens input/sessão | B26: =INDEX('🎛️ Premissas'!B26:D26,1,MATCH($B$2,{"Conservador","Base","Otimista"},0)) -> 3000 | C26: ← Premissas!Autônoma: tokens input/sessão agente (linha 23)
A27: Autônoma: tokens output/sessão | B27: =INDEX('🎛️ Premissas'!B27:D27,1,MATCH($B$2,{"Conservador","Base","Otimista"},0)) -> 1800 | C27: ← Premissas!Autônoma: tokens output/sessão agente (linha 24)
A28: Livre: sessões totais/mês | B28: =INDEX('🎛️ Premissas'!B29:D29,1,MATCH($B$2,{"Conservador","Base","Otimista"},0)) -> 60 | C28: ← Premissas!Livre: sessões totais agentes/mês (linha 26)
A29: ── CRESCIMENTO ──
A30: Free leads M1–12 | B30: =INDEX('🎛️ Premissas'!B31:D31,1,MATCH($B$2,{"Conservador","Base","Otimista"},0)) -> 3000 | C30: ← Premissas!Crescimento Free M1–12 (leads/mês) (linha 28)
A31: Free leads M13–24 | B31: =INDEX('🎛️ Premissas'!B32:D32,1,MATCH($B$2,{"Conservador","Base","Otimista"},0)) -> 3500 | C31: ← Premissas!Crescimento Free M13–24 (leads/mês) (linha 29)
A32: Conv. Free→Essencial | B32: =INDEX('🎛️ Premissas'!B33:D33,1,MATCH($B$2,{"Conservador","Base","Otimista"},0)) -> 0.1 | C32: ← Premissas!Conversão Free → Essencial (%) (linha 31)
A33: Conv. Free→Autônoma | B33: =INDEX('🎛️ Premissas'!B34:D34,1,MATCH($B$2,{"Conservador","Base","Otimista"},0)) -> 0.07 | C33: ← Premissas!Conversão Free → Autônoma (%) (linha 32)
A34: Conv. Free→Livre | B34: =INDEX('🎛️ Premissas'!B35:D35,1,MATCH($B$2,{"Conservador","Base","Otimista"},0)) -> 0.02 | C34: ← Premissas!Conversão Free → Livre (%) (linha 33)
A35: Churn Essencial/mês | B35: =INDEX('🎛️ Premissas'!B36:D36,1,MATCH($B$2,{"Conservador","Base","Otimista"},0)) -> 0.08 | C35: ← Premissas!Churn mensal Essencial (linha 34)
A36: Churn Autônoma/mês | B36: =INDEX('🎛️ Premissas'!B37:D37,1,MATCH($B$2,{"Conservador","Base","Otimista"},0)) -> 0.05 | C36: ← Premissas!Churn mensal Autônoma (linha 35)
A37: Churn Livre/mês | B37: =INDEX('🎛️ Premissas'!B38:D38,1,MATCH($B$2,{"Conservador","Base","Otimista"},0)) -> 0.03 | C37: ← Premissas!Churn mensal Livre (linha 36)
A38: ── CUSTO FIXO ──
A39: Equipe Ano 1 | B39: =INDEX('🎛️ Premissas'!B40:D40,1,MATCH($B$2,{"Conservador","Base","Otimista"},0)) -> 40000 | C39: ← Premissas!Equipe Ano 1 (média/mês) (linha 38)
A40: Equipe Ano 2 | B40: =INDEX('🎛️ Premissas'!B41:D41,1,MATCH($B$2,{"Conservador","Base","Otimista"},0)) -> 50000 | C40: ← Premissas!Equipe Ano 2 (média/mês) (linha 39)
...

Sheet 🎛️ Premissas
A1: AutoNoma · Premissas · Fonte Única de Verdade ·Haiku Freemium / 100% Sonnet 4.6 Planos e Agentes
A2: Azul = Input editável | B2: Preto = Fórmula | C2: Malva = Link cross-sheet
A3: PARAMETRO | B3: Conservador | C3: Base (padrão) | D3: Otimista | E3: UNIDADE/NOTA
A4: 1 · PREÇOS DOS PLANOS (R$/mês)
A5: Preço Essencial | B5: 39.9 | C5: 39.9 | D5: 39.9 | E5: R$/mês · + uso esporadico agente
A6: Preço Autônoma | B6: 59.9 | C6: 59.9 | D6: 62.9 | E6: R$/mês · chat + 1 agente
A7: Preço Livre | B7: 79.9 | C7: 79.9 | D7: 79.9 | E7: R$/mês · chat + 2 agentes
A8: Receita agentes avulsos por assinante Essencial (R$/mês) | B8: 10 | C8: 10 | D8: 10
A9: 2 · CUSTO API ANTHROPIC (1 semestre 2026)
A10: Câmbio USD/BRL | B10: 5.3 | C10: 5.3 | D10: 5.3 | E10: R$ por USD
A11: Haiku 4.5 Input ($/MTok) | B11: 1 | C11: 1 | D11: 1 | E11: USD — oficial Anthropic (plano Free)
A12: Haiku 4.5 Output ($/MTok) | B12: 5 | C12: 5 | D12: 5 | E12: USD — oficial Anthropic (plano Free)
A13: Sonnet 4.6 Input ($/MTok) | B13: 3 | C13: 3 | D13: 3 | E13: USD — oficial Anthropic
A14: Sonnet 4.6 Output ($/MTok) | B14: 15 | C14: 15 | D14: 15 | E14: USD — oficial Anthropic
A15: Desconto Prompt Caching (%) | B15: 0.35 | C15: 0.4 | D15: 0.45 | E15: % redução no bloco fixo
A16: 3 · USO POR PLANO — 100% SONNET 4.6
A17: Free: interações/mês (LIMITE) | B17: 50 | C17: 50 | D17: 50 | E17: Sonnet · teto produto
A18: Free: tokens input/interação | B18: 900 | C18: 900 | D18: 900 | E18: inclui system prompt cacheado
A19: Free: tokens output/interação | B19: 450 | C19: 450 | D19: 450 | E19: resposta orientada
A20: Free: % usuárias ativas/mês | B20: 0.5 | C20: 0.5 | D20: 0.5 | E20: % do cadastro que usa no mês
A21: Essencial: interações chat/mês | B21: 120 | C21: 140 | D21: 180 | E21: ilimitado prático · 20 dias × uso
A22: Essencial: tokens input/interação | B22: 1200 | C22: 1400 | D22: 1800 | E22: contexto Noma + memória
A23: Essencial: tokens output/interação | B23: 700 | C23: 700 | D23: 700 | E23: resposta + ação autônoma
A24: Autônoma: chat (= Essencial) | B24: 140 | C24: 140 | D24: 140 | E24: chat ilimitado Sonnet
A25: Autônoma: sessões agente/mês | B25: 35 | C25: 45 | D25: 60 | E25: sessões profundas com 1 agente
A26: Autônoma: tokens input/sessão agente | B26: 3000 | C26: 3000 | D26: 3000 | E26: contexto resolução + memória
A27: Autônoma: tokens output/sessão agente | B27: 1800 | C27: 1800 | D27: 1800 | E27: resolução completa + confirmação
A28: Livre: chat (= Essencial) | B28: 140 | C28: 140 | D28: 140 | E28: chat ilimitado Sonnet
A29: Livre: sessões totais agentes/mês | B29: 60 | C29: 80 | D29: 100 | E29: 2 agentes · mais que Autônoma
A30: 4 · CRESCIMENTO DA BASE
A31: Crescimento Free M1–12 (leads/mês) | B31: 3000 | C31: 3500 | D31: 4000 | E31: cadastros orgânicos+viral+paid
A32: Crescimento Free M13–24 (leads/mês) | B32: 3500 | C32: 4000 | D32: 4500 | E32: escala Brasil
A33: Conversão Free → Essencial (%) | B33: 0.1 | C33: 0.15 | D33: 0.2 | E33: % base Free que vira assinante
A34: Conversão Free → Autônoma (%) | B34: 0.07 | C34: 0.07 | D34: 0.07 | E34: % Essenciais que sobem
A35: Conversão Free → Livre (%) | B35: 0.02 | C35: 0.03 | D35: 0.03 | E35: % Autônomas que sobem
A36: Churn mensal Essencial | B36: 0.08 | C36: 0.07 | D36: 0.05 | E36: % cancela por mês
A37: Churn mensal Autônoma | B37: 0.05 | C37: 0.05 | D37: 0.06 | E37: % cancela por mês · agente = lock-in
A38: Churn mensal Livre | B38: 0.03 | C38: 0.03 | D38: 0.02 | E38: % cancela · 2 agentes = máximo lock-in
A39: 5 · CUSTO FIXO MENSAL (R$)
A40: Equipe Ano 1 (média/mês) | B40: 40000 | C40: 45000 | D40: 50000 | E40: devs+CS+pró-labore fundadores
...

Sheet 📊 Base Mensal
A1: AutoNoma · Base Mensal · 24 Meses · Fórmulas Dinâmicas · Cenário Controlado por 🔧 Cenário Ativo
A2: Cenário ativo: | C2: ='🔧 Cenário Ativo'!B2 -> Conservador
A3: Indicador | B3: Unid. | C3: M01 | D3: M02 | E3: M03 | F3: M04 | G3: M05 | H3: M06 | I3: M07 | J3: M08 | K3: M09 | L3: M10 | M3: M11 | N3: M12 ★ | O3: M13 | P3: M14 | Q3: M15 | R3: M16 | S3: M17 | T3: M18 | U3: M19 | V3: M20 | W3: M21 | X3: M22 | Y3: M23 | Z3: M24 ★
A4: USUÁRIOS
A5: Free · Trial 30 dias (ativas no mês) | B5: usr | C5: ='🎛️ Premissas'!B64 -> 2000 | D5: ='🔧 Cenário Ativo'!$B$30 -> 3000 | E5: ='🔧 Cenário Ativo'!$B$30 -> 3000 | F5: ='🔧 Cenário Ativo'!$B$30 -> 3000 | G5: ='🔧 Cenário Ativo'!$B$30 -> 3000 | H5: ='🔧 Cenário Ativo'!$B$30 -> 3000 | I5: ='🔧 Cenário Ativo'!$B$30 -> 3000 | J5: ='🔧 Cenário Ativo'!$B$30 -> 3000 | K5: ='🔧 Cenário Ativo'!$B$30 -> 3000 | ... N5: ='🔧 Cenário Ativo'!$B$30 -> 3000 | O5: ='🔧 Cenário Ativo'!$B$31 -> 3500 | P5: ='🔧 Cenário Ativo'!$B$31 -> 3500 | Q5: ='🔧 Cenário Ativo'!$B$31 -> 3500 | R5: ='🔧 Cenário Ativo'!$B$31 -> 3500 | S5: ='🔧 Cenário Ativo'!$B$31 -> 3500 | T5: ='🔧 Cenário Ativo'!$B$31 -> 3500 | U5: ='🔧 Cenário Ativo'!$B$31 -> 3500 | V5: ='🔧 Cenário Ativo'!$B$31 -> 3500 | ... Z5: ='🔧 Cenário Ativo'!$B$31 -> 3500
A6: Essencial · Assinantes | B6: ass. | C6: =ROUND(C5*'🔧 Cenário Ativo'!$B$32,0) -> 200 | D6: =ROUND(C6*(1-'🔧 Cenário Ativo'!$B$35)+D5*'🔧 Cenário Ativo'!$B$32,0) -> 484 | E6: =ROUND(D6*(1-'🔧 Cenário Ativo'!$B$35)+E5*'🔧 Cenário Ativo'!$B$32,0) -> 745 | F6: =ROUND(E6*(1-'🔧 Cenário Ativo'!$B$35)+F5*'🔧 Cenário Ativo'!$B$32,0) -> 985 | G6: =ROUND(F6*(1-'🔧 Cenário Ativo'!$B$35)+G5*'🔧 Cenário Ativo'!$B$32,0) -> 1206 | H6: =ROUND(G6*(1-'🔧 Cenário Ativo'!$B$35)+H5*'🔧 Cenário Ativo'!$B$32,0) -> 1410 | I6: =ROUND(H6*(1-'🔧 Cenário Ativo'!$B$35)+I5*'🔧 Cenário Ativo'!$B$32,0) -> 1597 | J6: =ROUND(I6*(1-'🔧 Cenário Ativo'!$B$35)+J5*'🔧 Cenário Ativo'!$B$32,0) -> 1769 | K6: =ROUND(J6*(1-'🔧 Cenário Ativo'!$B$35)+K5*'🔧 Cenário Ativo'!$B$32,0) -> 1927 | ... Z6: =ROUND(Y6*(1-'🔧 Cenário Ativo'!$B$35)+Z5*'🔧 Cenário Ativo'!$B$32,0) -> 3622
A7: Autônoma · Assinantes | B7: ass. | C7: =ROUND(C5*'🔧 Cenário Ativo'!$B$33,0) -> 140 | D7: =ROUND(C7*(1-'🔧 Cenário Ativo'!$B$36)+D5*'🔧 Cenário Ativo'!$B$33,0) -> 343 | E7: =ROUND(D7*(1-'🔧 Cenário Ativo'!$B$36)+E5*'🔧 Cenário Ativo'!$B$33,0) -> 536 | F7: =ROUND(E7*(1-'🔧 Cenário Ativo'!$B$36)+F5*'🔧 Cenário Ativo'!$B$33,0) -> 719 | G7: =ROUND(F7*(1-'🔧 Cenário Ativo'!$B$36)+G5*'🔧 Cenário Ativo'!$B$33,0) -> 893 | H7: =ROUND(G7*(1-'🔧 Cenário Ativo'!$B$36)+H5*'🔧 Cenário Ativo'!$B$33,0) -> 1058 | I7: =ROUND(H7*(1-'🔧 Cenário Ativo'!$B$36)+I5*'🔧 Cenário Ativo'!$B$33,0) -> 1215 | J7: =ROUND(I7*(1-'🔧 Cenário Ativo'!$B$36)+J5*'🔧 Cenário Ativo'!$B$33,0) -> 1364 | K7: =ROUND(J7*(1-'🔧 Cenário Ativo'!$B$36)+K5*'🔧 Cenário Ativo'!$B$33,0) -> 1506 | ... Z7: =ROUND(Y7*(1-'🔧 Cenário Ativo'!$B$36)+Z5*'🔧 Cenário Ativo'!$B$33,0) -> 3275
A8: Livre · Assinantes | B8: ass. | C8: =ROUND(C5*'🔧 Cenário Ativo'!$B$34,0) -> 40 | D8: =ROUND(C8*(1-'🔧 Cenário Ativo'!$B$37)+D5*'🔧 Cenário Ativo'!$B$34,0) -> 99 | E8: =ROUND(D8*(1-'🔧 Cenário Ativo'!$B$37)+E5*'🔧 Cenário Ativo'!$B$34,0) -> 156 | F8: =ROUND(E8*(1-'🔧 Cenário Ativo'!$B$37)+F5*'🔧 Cenário Ativo'!$B$34,0) -> 211 | G8: =ROUND(F8*(1-'🔧 Cenário Ativo'!$B$37)+G5*'🔧 Cenário Ativo'!$B$34,0) -> 265 | H8: =ROUND(G8*(1-'🔧 Cenário Ativo'!$B$37)+H5*'🔧 Cenário Ativo'!$B$34,0) -> 317 | I8: =ROUND(H8*(1-'🔧 Cenário Ativo'!$B$37)+I5*'🔧 Cenário Ativo'!$B$34,0) -> 367 | J8: =ROUND(I8*(1-'🔧 Cenário Ativo'!$B$37)+J5*'🔧 Cenário Ativo'!$B$34,0) -> 416 | K8: =ROUND(J8*(1-'🔧 Cenário Ativo'!$B$37)+K5*'🔧 Cenário Ativo'!$B$34,0) -> 464 | ... Z8: =ROUND(Y8*(1-'🔧 Cenário Ativo'!$B$37)+Z5*'🔧 Cenário Ativo'!$B$34,0) -> 1130
A9: TOTAL PAGANTES | B9: ass. | C9: =SUM(C6:C8) -> 380 | D9: =SUM(D6:D8) -> 926 | E9: =SUM(E6:E8) -> 1437 | F9: =SUM(F6:F8) -> 1915 | G9: =SUM(G6:G8) -> 2364 | H9: =SUM(H6:H8) -> 2785 | I9: =SUM(I6:I8) -> 3179 | J9: =SUM(J6:J8) -> 3549 | ... Z9: =SUM(Z6:Z8) -> 8027
A10: RECEITA
A11: MRR MENSAL | B11: R$ | C11: =C6*('🔧 Cenário Ativo'!$B$6+'🔧 Cenário Ativo'!$B$9)+C7*'🔧 Cenário Ativo'!$B$7+C8*'🔧 Cenário Ativo'!$B$8 -> 21562 | D11: =D6*('🔧 Cenário Ativo'!$B$6+'🔧 Cenário Ativo'!$B$9)+D7*'🔧 Cenário Ativo'!$B$7+D8*'🔧 Cenário Ativo'!$B$8 -> 52607.4 | E11: =E6*('🔧 Cenário Ativo'!$B$6+'🔧 Cenário Ativo'!$B$9)+E7*'🔧 Cenário Ativo'!$B$7+E8*'🔧 Cenário Ativo'!$B$8 -> 81746.3 | F11: =F6*('🔧 Cenário Ativo'!$B$6+'🔧 Cenário Ativo'!$B$9)+F7*'🔧 Cenário Ativo'!$B$7+F8*'🔧 Cenário Ativo'!$B$8 -> 109078.5 | G11: =G6*('🔧 Cenário Ativo'!$B$6+'🔧 Cenário Ativo'!$B$9)+G7*'🔧 Cenário Ativo'!$B$7+G8*'🔧 Cenário Ativo'!$B$8 -> 134843.6 | H11: =H6*('🔧 Cenário Ativo'!$B$6+'🔧 Cenário Ativo'!$B$9)+H7*'🔧 Cenário Ativo'!$B$7+H8*'🔧 Cenário Ativo'!$B$8 -> 159061.5 | I11: =I6*('🔧 Cenário Ativo'!$B$6+'🔧 Cenário Ativo'!$B$9)+I7*'🔧 Cenário Ativo'!$B$7+I8*'🔧 Cenário Ativo'!$B$8 -> 181792.1 | J11: =J6*('🔧 Cenário Ativo'!$B$6+'🔧 Cenário Ativo'!$B$9)+J7*'🔧 Cenário Ativo'!$B$7+J8*'🔧 Cenário Ativo'!$B$8 -> 203215.1 | ... Z11: =Z6*('🔧 Cenário Ativo'!$B$6+'🔧 Cenário Ativo'!$B$9)+Z7*'🔧 Cenário Ativo'!$B$7+Z8*'🔧 Cenário Ativo'!$B$8 -> 467197.3
A12: MRR ACUMULADO | B12: R$ | C12: =C11 -> 21562 | D12: =C12+D11 -> 74169.4 | E12: =D12+E11 -> 155915.7 | F12: =E12+F11 -> 264994.2 | G12: =F12+G11 -> 399837.8 | H12: =G12+H11 -> 558899.3 | I12: =H12+I11 -> 740691.4 | J12: =I12+J11 -> 943906.5 | K12: =J12+K11 -> 1167346.8 | ... Z12: =Y12+Z11 -> 6638262.2
A13: CUSTO API · 100% Sonnet 4.6 · Caching ativo
A14: API Free (Haiku · 40 int/mês) | B14: R$ | C14: =C5*'🔧 Cenário Ativo'!$B$21*('🔧 Cenário Ativo'!$B$18*('🔧 Cenário Ativo'!$B$19/1000000*'🔧 Cenário Ativo'!$B$14+'🔧 Cenário Ativo'!$B$20/1000000*'🔧 Cenário Ativo'!$B$15)*(1-'🔧 Cenário Ativo'!$B$16)*'🔧 Cenário Ativo'!$B$11) -> 542.5875 | D14: =D5*'🔧 Cenário Ativo'!$B$21*('🔧 Cenário Ativo'!$B$18*('🔧 Cenário Ativo'!$B$19/1000000*'🔧 Cenário Ativo'!$B$14+'🔧 Cenário Ativo'!$B$20/1000000*'🔧 Cenário Ativo'!$B$15)*(1-'🔧 Cenário Ativo'!$B$16)*'🔧 Cenário Ativo'!$B$11) -> 813.88125 | E14: =E5*'🔧 Cenário Ativo'!$B$21*('🔧 Cenário Ativo'!$B$18*('🔧 Cenário Ativo'!$B$19/1000000*'🔧 Cenário Ativo'!$B$14+'🔧 Cenário Ativo'!$B$20/1000000*'🔧 Cenário Ativo'!$B$15)*(1-'🔧 Cenário Ativo'!$B$16)*'🔧 Cenário Ativo'!$B$11) -> 813.88125 | F14: =F5*'🔧 Cenário Ativo'!$B$21*('🔧 Cenário Ativo'!$B$18*('🔧 Cenário Ativo'!$B$19/1000000*'🔧 Cenário Ativo'!$B$14+'🔧 Cenário Ativo'!$B$20/1000000*'🔧 Cenário Ativo'!$B$15)*(1-'🔧 Cenário Ativo'!$B$16)*'🔧 Cenário Ativo'!$B$11) -> 813.88125 | G14: =G5*'🔧 Cenário Ativo'!$B$21*('🔧 Cenário Ativo'!$B$18*('🔧 Cenário Ativo'!$B$19/1000000*'🔧 Cenário Ativo'!$B$14+'🔧 Cenário Ativo'!$B$20/1000000*'🔧 Cenário Ativo'!$B$15)*(1-'🔧 Cenário Ativo'!$B$16)*'🔧 Cenário Ativo'!$B$11) -> 813.88125 | H14: =H5*'🔧 Cenário Ativo'!$B$21*('🔧 Cenário Ativo'!$B$18*('🔧 Cenário Ativo'!$B$19/1000000*'🔧 Cenário Ativo'!$B$14+'🔧 Cenário Ativo'!$B$20/1000000*'🔧 Cenário Ativo'!$B$15)*(1-'🔧 Cenário Ativo'!$B$16)*'🔧 Cenário Ativo'!$B$11) -> 813.88125 | I14: =I5*'🔧 Cenário Ativo'!$B$21*('🔧 Cenário Ativo'!$B$18*('🔧 Cenário Ativo'!$B$19/1000000*'🔧 Cenário Ativo'!$B$14+'🔧 Cenário Ativo'!$B$20/1000000*'🔧 Cenário Ativo'!$B$15)*(1-'🔧 Cenário Ativo'!$B$16)*'🔧 Cenário Ativo'!$B$11) -> 813.88125 | J14: =J5*'🔧 Cenário Ativo'!$B$21*('🔧 Cenário Ativo'!$B$18*('🔧 Cenário Ativo'!$B$19/1000000*'🔧 Cenário Ativo'!$B$14+'🔧 Cenário Ativo'!$B$20/1000000*'🔧 Cenário Ativo'!$B$15)*(1-'🔧 Cenário Ativo'!$B$16)*'🔧 Cenário Ativo'!$B$11) -> 813.88125 | ... Z14: =Z5*'🔧 Cenário Ativo'!$B$21*('🔧 Cenário Ativo'!$B$18*('🔧 Cenário Ativo'!$B$19/1000000*'🔧 Cenário Ativo'!$B$14+'🔧 Cenário Ativo'!$B$20/1000000*'🔧 Cenário Ativo'!$B$15)*(1-'🔧 Cenário Ativo'!$B$16)*'🔧 Cenário Ativo'!$B$11) -> 949.52813
A15: API Essencial (chat ilimitado) | B15: R$ | C15: =C6*'🔧 Cenário Ativo'!B22*('🔧 Cenário Ativo'!B23/1000000*'🔧 Cenário Ativo'!B12+'🔧 Cenário Ativo'!B24/1000000*'🔧 Cenário Ativo'!B13)*(1-'🔧 Cenário Ativo'!B16)*'🔧 Cenário Ativo'!B11 -> 1165.788 | D15: =D6*'🔧 Cenário Ativo'!B22*('🔧 Cenário Ativo'!B23/1000000*'🔧 Cenário Ativo'!B12+'🔧 Cenário Ativo'!B24/1000000*'🔧 Cenário Ativo'!B13)*(1-'🔧 Cenário Ativo'!B16)*'🔧 Cenário Ativo'!B11 -> 2821.207 | E15: =E6*'🔧 Cenário Ativo'!B22*('🔧 Cenário Ativo'!B23/1000000*'🔧 Cenário Ativo'!B12+'🔧 Cenário Ativo'!B24/1000000*'🔧 Cenário Ativo'!B13)*(1-'🔧 Cenário Ativo'!B16)*'🔧 Cenário Ativo'!B11 -> 4342.5603 | F15: =F6*'🔧 Cenário Ativo'!B22*('🔧 Cenário Ativo'!B23/1000000*'🔧 Cenário Ativo'!B12+'🔧 Cenário Ativo'!B24/1000000*'🔧 Cenário Ativo'!B13)*(1-'🔧 Cenário Ativo'!B16)*'🔧 Cenário Ativo'!B11 -> 5741.5059 | G15: =G6*'🔧 Cenário Ativo'!B22*('🔧 Cenário Ativo'!B23/1000000*'🔧 Cenário Ativo'!B12+'🔧 Cenário Ativo'!B24/1000000*'🔧 Cenário Ativo'!B13)*(1-'🔧 Cenário Ativo'!B16)*'🔧 Cenário Ativo'!B11 -> 7029.7016 | H15: =H6*'🔧 Cenário Ativo'!B22*('🔧 Cenário Ativo'!B23/1000000*'🔧 Cenário Ativo'!B12+'🔧 Cenário Ativo'!B24/1000000*'🔧 Cenário Ativo'!B13)*(1-'🔧 Cenário Ativo'!B16)*'🔧 Cenário Ativo'!B11 -> 8218.8054 | I15: =I6*'🔧 Cenário Ativo'!B22*('🔧 Cenário Ativo'!B23/1000000*'🔧 Cenário Ativo'!B12+'🔧 Cenário Ativo'!B24/1000000*'🔧 Cenário Ativo'!B13)*(1-'🔧 Cenário Ativo'!B16)*'🔧 Cenário Ativo'!B11 -> 9308.8172 | J15: =J6*'🔧 Cenário Ativo'!B22*('🔧 Cenário Ativo'!B23/1000000*'🔧 Cenário Ativo'!B12+'🔧 Cenário Ativo'!B24/1000000*'🔧 Cenário Ativo'!B13)*(1-'🔧 Cenário Ativo'!B16)*'🔧 Cenário Ativo'!B11 -> 10311.395 | K15: =K6*'🔧 Cenário Ativo'!B22*('🔧 Cenário Ativo'!B23/1000000*'🔧 Cenário Ativo'!B12+'🔧 Cenário Ativo'!B24/1000000*'🔧 Cenário Ativo'!B13)*(1-'🔧 Cenário Ativo'!B16)*'🔧 Cenário Ativo'!B11 -> 11232.367 | L15: =L6*'🔧 Cenário Ativo'!B22*('🔧 Cenário Ativo'!B23/1000000*'🔧 Cenário Ativo'!B12+'🔧 Cenário Ativo'!B24/1000000*'🔧 Cenário Ativo'!B13)*(1-'🔧 Cenário Ativo'!B16)*'🔧 Cenário Ativo'!B11 -> 12083.393 | M15: =M6*'🔧 Cenário Ativo'!B22*('🔧 Cenário Ativo'!B23/1000000*'🔧 Cenário Ativo'!B12+'🔧 Cenário Ativo'!B24/1000000*'🔧 Cenário Ativo'!B13)*(1-'🔧 Cenário Ativo'!B16)*'🔧 Cenário Ativo'!B11 -> 12864.471 | N15: =N6*'🔧 Cenário Ativo'!B22*('🔧 Cenário Ativo'!B23/1000000*'🔧 Cenário Ativo'!B12+'🔧 Cenário Ativo'!B24/1000000*'🔧 Cenário Ativo'!B13)*(1-'🔧 Cenário Ativo'!B16)*'🔧 Cenário Ativo'!B11 -> 13581.43 | O15: =O6*'🔧 Cenário Ativo'!B22*('🔧 Cenário Ativo'!B23/1000000*'🔧 Cenário Ativo'!B12+'🔧 Cenário Ativo'!B24/1000000*'🔧 Cenário Ativo'!B13)*(1-'🔧 Cenário Ativo'!B16)*'🔧 Cenário Ativo'!B11 -> 14537.376 | P15: =P6*'🔧 Cenário Ativo'!B22*('🔧 Cenário Ativo'!B23/1000000*'🔧 Cenário Ativo'!B12+'🔧 Cenário Ativo'!B24/1000000*'🔧 Cenário Ativo'!B13)*(1-'🔧 Cenário Ativo'!B16)*'🔧 Cenário Ativo'!B11 -> 15411.717 | Q15: =Q6*'🔧 Cenário Ativo'!B22*('🔧 Cenário Ativo'!B23/1000000*'🔧 Cenário Ativo'!B12+'🔧 Cenário Ativo'!B24/1000000*'🔧 Cenário Ativo'!B13)*(1-'🔧 Cenário Ativo'!B16)*'🔧 Cenário Ativo'!B11 -> 16216.111 | R15: =R6*'🔧 Cenário Ativo'!B22*('🔧 Cenário Ativo'!B23/1000000*'🔧 Cenário Ativo'!B12+'🔧 Cenário Ativo'!B24/1000000*'🔧 Cenário Ativo'!B13)*(1-'🔧 Cenário Ativo'!B16)*'🔧 Cenário Ativo'!B11 -> 16956.386 | S15: =S6*'🔧 Cenário Ativo'!B22*('🔧 Cenário Ativo'!B23/1000000*'🔧 Cenário Ativo'!B12+'🔧 Cenário Ativo'!B24/1000000*'🔧 Cenário Ativo'!B13)*(1-'🔧 Cenário Ativo'!B16)*'🔧 Cenário Ativo'!B11 -> 17638.372 | T15: =T6*'🔧 Cenário Ativo'!B22*('🔧 Cenário Ativo'!B23/1000000*'🔧 Cenário Ativo'!B12+'🔧 Cenário Ativo'!B24/1000000*'🔧 Cenário Ativo'!B13)*(1-'🔧 Cenário Ativo'!B16)*'🔧 Cenário Ativo'!B11 -> 18267.898 | U15: =U6*'🔧 Cenário Ativo'!B22*('🔧 Cenário Ativo'!B23/1000000*'🔧 Cenário Ativo'!B12+'🔧 Cenário Ativo'!B24/1000000*'🔧 Cenário Ativo'!B13)*(1-'🔧 Cenário Ativo'!B16)*'🔧 Cenário Ativo'!B11 -> 18844.963 | V15: =V6*'🔧 Cenário Ativo'!B22*('🔧 Cenário Ativo'!B23/1000000*'🔧 Cenário Ativo'!B12+'🔧 Cenário Ativo'!B24/1000000*'🔧 Cenário Ativo'!B13)*(1-'🔧 Cenário Ativo'!B16)*'🔧 Cenário Ativo'!B11 -> 19375.397 | W15: =W6*'🔧 Cenário Ativo'!B22*('🔧 Cenário Ativo'!B23/1000000*'🔧 Cenário Ativo'!B12+'🔧 Cenário Ativo'!B24/1000000*'🔧 Cenário Ativo'!B13)*(1-'🔧 Cenário Ativo'!B16)*'🔧 Cenário Ativo'!B11 -> 19865.028 | X15: =X6*'🔧 Cenário Ativo'!B22*('🔧 Cenário Ativo'!B23/1000000*'🔧 Cenário Ativo'!B12+'🔧 Cenário Ativo'!B24/1000000*'🔧 Cenário Ativo'!B13)*(1-'🔧 Cenário Ativo'!B16)*'🔧 Cenário Ativo'!B11 -> 20313.856 | Y15: =Y6*'🔧 Cenário Ativo'!B22*('🔧 Cenário Ativo'!B23/1000000*'🔧 Cenário Ativo'!B12+'🔧 Cenário Ativo'!B24/1000000*'🔧 Cenário Ativo'!B13)*(1-'🔧 Cenário Ativo'!B16)*'🔧 Cenário Ativo'!B11 -> 20727.711 | Z15: =Z6*'🔧 Cenário Ativo'!B22*('🔧 Cenário Ativo'!B23/1000000*'🔧 Cenário Ativo'!B12+'🔧 Cenário Ativo'!B24/1000000*'🔧 Cenário Ativo'!B13)*(1-'🔧 Cenário Ativo'!B16)*'🔧 Cenário Ativo'!B11 -> 21112.421
