Workbook

Sheet 🚀 Investor Dashboard
A2: AUTONOMA | C2: INVESTOR DASHBOARD · 24-MONTH PLAN
A3: Full Business Plan: 📋 Summary · 🌎 Market & GTM · 📈 P&L · 💰 Cash & Runway · ⚠️ Risks & Roadmap · 💎 Angel Summary
A5: ACTIVE SCENARIO | B5: ='🔧 Active Scenario'!B2 -> Conservative | C5: ← change in 🔧 Active Scenario!B2 (Conservative / Base / Optimistic) — the entire BP recalculates
A8: VALUATION · M24 | C8: ANGEL RETURN · M24 | E8: CUMUL. REVENUE · 24M | G8: CASH BREAKEVEN | I8: ENDING CASH · M24
A9: =IF('🔧 Active Scenario'!B2="Conservative",'📊 Scenario Summary'!B21,IF('🔧 Active Scenario'!B2="Base",'📊 Scenario Summary'!C21,'📊 Scenario Summary'!D21)) -> 19914787 | C9: =A9*'🎛️ Assumptions'!B59 -> 2987218 | E9: =IF('🔧 Active Scenario'!B2="Conservative",'📊 Scenario Summary'!B19,IF('🔧 Active Scenario'!B2="Base",'📊 Scenario Summary'!C19,'📊 Scenario Summary'!D19)) -> 6638262.2 | G9: {=IFERROR("M"&MATCH(TRUE,INDEX('📊 Monthly Base'!C25:Z25>0,0),0),">24m")} -> M5 | I9: ='💰 Cash & Runway'!Z10 -> 4275921.5
A10: ="cumul. rev. × "&TEXT('🔧 Active Scenario'!B50,"0.0")&"× (scenario multiple)" -> cumul. rev. × 03× (scenario multiple) | C10: =TEXT(C9/'🎛️ Assumptions'!B58,"0.0")&"× over R$ "&TEXT('🎛️ Assumptions'!B58/1000,"#,##0")&"K investment · "&TEXT('🎛️ Assumptions'!B59,"0%")&" stake" -> 03× over R$ 1000,0K investment · 15% stake | E10: official valuation base (📊 Scenario Summary) | G10: cumulative result turns positive | I10: ="cash never below R$ "&TEXT(MIN('💰 Cash & Runway'!C10:Z10)/1000,"#,##0")&"K" -> cash never below R$ 942,427K
A13: MRR · M24 | C13: PAYING SUBSCRIBERS · M24 | E13: LTV / CAC | G13: CAC PAYBACK | I13: GROSS MARGIN · M24
A14: ='📊 Monthly Base'!Z11*12 -> 5606367.6 | C14: ='📊 Monthly Base'!Z9 -> 8027 | E14: ='🔧 Active Scenario'!B56 -> 6.8861031 | G14: ='🔧 Active Scenario'!B57 -> 1.8152502 | I14: ='📊 Monthly Base'!Z26 -> 0.84939387
A15: ="ARR of R$ "&TEXT('📊 Monthly Base'!Z11*12/1000000,"0.0")&"M at end of Year 2" -> ARR of R$ 06M at end of Year 2 | C15: ="from "&TEXT(('🔧 Active Scenario'!B30+'🔧 Active Scenario'!B31)*12,"#,##0")&" cumul. sign-ups · 30d trial" -> from 78000,0 cumul. sign-ups · 30d trial | E15: ="CAC R$ "&TEXT('🔧 Active Scenario'!B47,"0")&" · LTV R$ "&TEXT('🔧 Active Scenario'!B55,"0")&" (Essencial)" -> CAC R$ 80 · LTV R$ 551 (Essencial) | G15: ="≈ "&TEXT('🔧 Active Scenario'!B57*30,"0")&" days to recover CAC" -> ≈ 54 days to recover CAC | I15: after API cost (Free Haiku · paid Sonnet)
A16: PROJECTIONS · 24 MONTHS | F16: ="Active scenario: "&'🔧 Active Scenario'!B2 -> Active scenario: Conservative
A30: REVENUE & SCENARIO COMPARISON
A35: RECEITA & COMPARATIVO DE CENÁRIOS
A53: Modelo 100% dinâmico · motor de cálculo em 📊 Base Mensal · premissas em 🎛️ Premissas e 🔧 Cenário Ativo · comparação em 📊 Resumo Cenários
A54: Este material é um estudo de projeção e não configura oferta de investimento. AutoNoma © 2025
L76: Month | M76: MRR | N76: Paying | O76: Free | P76: Result | Q76: Cumulative | R76: Essencial | S76: Autônoma | T76: Livre | U76: Total API | V76: Fixed Cost | W76: Margin%
L77: M01 | M77: ='📊 Monthly Base'!C11 -> 21562 | N77: ='📊 Monthly Base'!C9 -> 380 | O77: ='📊 Monthly Base'!C5 -> 2000 | P77: ='📊 Monthly Base'!C24 -> -39903.991 | Q77: ='📊 Monthly Base'!C25 -> -39903.991 | R77: ='📊 Monthly Base'!C6 -> 200 | S77: ='📊 Monthly Base'!C7 -> 140 | T77: ='📊 Monthly Base'!C8 -> 40 | U77: ='📊 Monthly Base'!C18 -> 3662.9307 | V77: ='📊 Monthly Base'!C20 -> 55000 | W77: ='📊 Monthly Base'!C26 -> 0.83012101
L78: M02 | M78: ='📊 Monthly Base'!D11 -> 52607.4 | N78: ='📊 Monthly Base'!D9 -> 926 | O78: ='📊 Monthly Base'!D5 -> 3000 | P78: ='📊 Monthly Base'!D24 -> -17668.581 | Q78: ='📊 Monthly Base'!D25 -> -57572.571 | R78: ='📊 Monthly Base'!D6 -> 484 | S78: ='📊 Monthly Base'!D7 -> 343 | T78: ='📊 Monthly Base'!D8 -> 99 | U78: ='📊 Monthly Base'!D18 -> 8437.0186 | V78: ='📊 Monthly Base'!D20 -> 55000 | W78: ='📊 Monthly Base'!D26 -> 0.83962297
L79: M03 | M79: ='📊 Monthly Base'!E11 -> 81746.3 | N79: ='📊 Monthly Base'!E9 -> 1437 | O79: ='📊 Monthly Base'!E5 -> 3000 | P79: ='📊 Monthly Base'!E24 -> 3441.7706 | Q79: ='📊 Monthly Base'!E25 -> -54130.801 | R79: ='📊 Monthly Base'!E6 -> 745 | S79: ='📊 Monthly Base'!E7 -> 536 | T79: ='📊 Monthly Base'!E8 -> 156 | U79: ='📊 Monthly Base'!E18 -> 12677.51 | V79: ='📊 Monthly Base'!E20 -> 55000 | W79: ='📊 Monthly Base'!E26 -> 0.8449164
L80: M04 | M80: ='📊 Monthly Base'!F11 -> 109078.5 | N80: ='📊 Monthly Base'!F9 -> 1915 | O80: ='📊 Monthly Base'!F5 -> 3000 | P80: ='📊 Monthly Base'!F24 -> 23230.937 | Q80: ='📊 Monthly Base'!F25 -> -30899.864 | R80: ='📊 Monthly Base'!F6 -> 985 | S80: ='📊 Monthly Base'!F7 -> 719 | T80: ='📊 Monthly Base'!F8 -> 211 | U80: ='📊 Monthly Base'!F18 -> 16667.358 | V80: ='📊 Monthly Base'!F20 -> 55000 | W80: ='📊 Monthly Base'!F26 -> 0.84719851
L81: M05 | M81: ='📊 Monthly Base'!G11 -> 134843.6 | N81: ='📊 Monthly Base'!G9 -> 2364 | O81: ='📊 Monthly Base'!G5 -> 3000 | P81: ='📊 Monthly Base'!G24 -> 41872.273 | Q81: ='📊 Monthly Base'!G25 -> 10972.41 | R81: ='📊 Monthly Base'!G6 -> 1206 | S81: ='📊 Monthly Base'!G7 -> 893 | T81: ='📊 Monthly Base'!G8 -> 265 | U81: ='📊 Monthly Base'!G18 -> 20441.659 | V81: ='📊 Monthly Base'!G20 -> 55000 | W81: ='📊 Monthly Base'!G26 -> 0.84840468
L82: M06 | M82: ='📊 Monthly Base'!H11 -> 159061.5 | N82: ='📊 Monthly Base'!H9 -> 2785 | O82: ='📊 Monthly Base'!H5 -> 3000 | P82: ='📊 Monthly Base'!H24 -> 59384.705 | Q82: ='📊 Monthly Base'!H25 -> 70357.115 | R82: ='📊 Monthly Base'!H6 -> 1410 | S82: ='📊 Monthly Base'!H7 -> 1058 | T82: ='📊 Monthly Base'!H8 -> 317 | U82: ='📊 Monthly Base'!H18 -> 23998.8 | V82: ='📊 Monthly Base'!H20 -> 55000 | W82: ='📊 Monthly Base'!H26 -> 0.84912251
L83: M07 | M83: ='📊 Monthly Base'!I11 -> 181792.1 | N83: ='📊 Monthly Base'!I9 -> 3179 | O83: ='📊 Monthly Base'!I5 -> 3000 | P83: ='📊 Monthly Base'!I24 -> 75810.175 | Q83: ='📊 Monthly Base'!I25 -> 146167.29 | R83: ='📊 Monthly Base'!I6 -> 1597 | S83: ='📊 Monthly Base'!I7 -> 1215 | T83: ='📊 Monthly Base'!I8 -> 367 | U83: ='📊 Monthly Base'!I18 -> 27348.952 | V83: ='📊 Monthly Base'!I20 -> 55000 | W83: ='📊 Monthly Base'!I26 -> 0.84955918
L84: M08 | M84: ='📊 Monthly Base'!J11 -> 203215.1 | N84: ='📊 Monthly Base'!J9 -> 3549 | O84: ='📊 Monthly Base'!J5 -> 3000 | P84: ='📊 Monthly Base'!J24 -> 91280.094 | Q84: ='📊 Monthly Base'!J25 -> 237447.38 | R84: ='📊 Monthly Base'!J6 -> 1769 | S84: ='📊 Monthly Base'!J7 -> 1364 | T84: ='📊 Monthly Base'!J8 -> 416 | U84: ='📊 Monthly Base'!J18 -> 30517.043 | V84: ='📊 Monthly Base'!J20 -> 55000 | W84: ='📊 Monthly Base'!J26 -> 0.84982886
L85: M09 | M85: ='📊 Monthly Base'!K11 -> 223440.3 | N85: ='📊 Monthly Base'!K9 -> 3897 | O85: ='📊 Monthly Base'!K5 -> 3000 | P85: ='📊 Monthly Base'!K24 -> 105873.99 | Q85: ='📊 Monthly Base'!K25 -> 343321.37 | R85: ='📊 Monthly Base'!K6 -> 1927 | S85: ='📊 Monthly Base'!K7 -> 1506 | T85: ='📊 Monthly Base'!K8 -> 464 | U85: ='📊 Monthly Base'!K18 -> 33519.071 | V85: ='📊 Monthly Base'!K20 -> 55000 | W85: ='📊 Monthly Base'!K26 -> 0.84998646
L86: M10 | M86: ='📊 Monthly Base'!L11 -> 242487.6 | N86: ='📊 Monthly Base'!L9 -> 4224 | O86: ='📊 Monthly Base'!L5 -> 3000 | P86: ='📊 Monthly Base'!L24 -> 119610.79 | Q86: ='📊 Monthly Base'!L25 -> 462932.16 | R86: ='📊 Monthly Base'!L6 -> 2073 | S86: ='📊 Monthly Base'!L7 -> 1641 | T86: ='📊 Monthly Base'!L8 -> 510 | U86: ='📊 Monthly Base'!L18 -> 36353.425 | V86: ='📊 Monthly Base'!L20 -> 55000 | W86: ='📊 Monthly Base'!L26 -> 0.85008131
L87: M11 | M87: ='📊 Monthly Base'!M11 -> 260436.9 | N87: ='📊 Monthly Base'!M9 -> 4531 | O87: ='📊 Monthly Base'!M5 -> 3000 | P87: ='📊 Monthly Base'!M24 -> 132546.73 | Q87: ='📊 Monthly Base'!M25 -> 595478.89 | R87: ='📊 Monthly Base'!M6 -> 2207 | S87: ='📊 Monthly Base'!M7 -> 1769 | T87: ='📊 Monthly Base'!M8 -> 555 | U87: ='📊 Monthly Base'!M18 -> 39033.373 | V87: ='📊 Monthly Base'!M20 -> 55000 | W87: ='📊 Monthly Base'!M26 -> 0.85012349
L88: M12 | M88: ='📊 Monthly Base'!N11 -> 277318.1 | N88: ='📊 Monthly Base'!N9 -> 4819 | O88: ='📊 Monthly Base'!N5 -> 3000 | P88: ='📊 Monthly Base'!N24 -> 144705.1 | Q88: ='📊 Monthly Base'!N25 -> 740183.99 | R88: ='📊 Monthly Base'!N6 -> 2330 | S88: ='📊 Monthly Base'!N7 -> 1891 | T88: ='📊 Monthly Base'!N8 -> 598 | U88: ='📊 Monthly Base'!N18 -> 41561.644 | V88: ='📊 Monthly Base'!N20 -> 55000 | W88: ='📊 Monthly Base'!N26 -> 0.85013007
L89: M13 | M89: ='📊 Monthly Base'!O11 -> 298641.5 | N89: ='📊 Monthly Base'!O9 -> 5185 | O89: ='📊 Monthly Base'!O5 -> 3500 | P89: ='📊 Monthly Base'!O24 -> 144949.37 | Q89: ='📊 Monthly Base'!O25 -> 885133.37 | R89: ='📊 Monthly Base'!O6 -> 2494 | S89: ='📊 Monthly Base'!O7 -> 2041 | T89: ='📊 Monthly Base'!O8 -> 650 | U89: ='📊 Monthly Base'!O18 -> 44868.731 | V89: ='📊 Monthly Base'!O20 -> 70000 | W89: ='📊 Monthly Base'!O26 -> 0.84975721
L90: M14 | M90: ='📊 Monthly Base'!P11 -> 318767.1 | N90: ='📊 Monthly Base'!P9 -> 5529 | O90: ='📊 Monthly Base'!P5 -> 3500 | P90: ='📊 Monthly Base'!P24 -> 159453.27 | Q90: ='📊 Monthly Base'!P25 -> 1044586.6 | R90: ='📊 Monthly Base'!P6 -> 2644 | S90: ='📊 Monthly Base'!P7 -> 2184 | T90: ='📊 Monthly Base'!P8 -> 701 | U90: ='📊 Monthly Base'!P18 -> 47874.107 | V90: ='📊 Monthly Base'!P20 -> 70000 | W90: ='📊 Monthly Base'!P26 -> 0.84981478
L91: M15 | M91: ='📊 Monthly Base'!Q11 -> 337714.8 | N91: ='📊 Monthly Base'!Q9 -> 5852 | O91: ='📊 Monthly Base'!Q5 -> 3500 | P91: ='📊 Monthly Base'!Q24 -> 173100.07 | Q91: ='📊 Monthly Base'!Q25 -> 1217686.7 | R91: ='📊 Monthly Base'!Q6 -> 2782 | S91: ='📊 Monthly Base'!Q7 -> 2320 | T91: ='📊 Monthly Base'!Q8 -> 750 | U91: ='📊 Monthly Base'!Q18 -> 50711.809 | V91: ='📊 Monthly Base'!Q20 -> 70000 | W91: ='📊 Monthly Base'!Q26 -> 0.84983836
L92: M16 | M92: ='📊 Monthly Base'!R11 -> 355614.4 | N92: ='📊 Monthly Base'!R9 -> 6156 | O92: ='📊 Monthly Base'!R5 -> 3500 | P92: ='📊 Monthly Base'!R24 -> 185983.59 | Q92: ='📊 Monthly Base'!R25 -> 1403670.3 | R92: ='📊 Monthly Base'!R6 -> 2909 | S92: ='📊 Monthly Base'!R7 -> 2449 | T92: ='📊 Monthly Base'!R8 -> 798 | U92: ='📊 Monthly Base'!R18 -> 53400.935 | V92: ='📊 Monthly Base'!R20 -> 70000 | W92: ='📊 Monthly Base'!R26 -> 0.84983472
L93: M17 | M93: ='📊 Monthly Base'!S11 -> 372495.8 | N93: ='📊 Monthly Base'!S9 -> 6442 | O93: ='📊 Monthly Base'!S5 -> 3500 | P93: ='📊 Monthly Base'!S24 -> 198127.13 | Q93: ='📊 Monthly Base'!S25 -> 1601797.4 | R93: ='📊 Monthly Base'!S6 -> 3026 | S93: ='📊 Monthly Base'!S7 -> 2572 | T93: ='📊 Monthly Base'!S8 -> 844 | U93: ='📊 Monthly Base'!S18 -> 55944.213 | V93: ='📊 Monthly Base'!S20 -> 70000 | W93: ='📊 Monthly Base'!S26 -> 0.8498125
L94: M18 | M94: ='📊 Monthly Base'!T11 -> 388428.9 | N94: ='📊 Monthly Base'!T9 -> 6711 | O94: ='📊 Monthly Base'!T5 -> 3500 | P94: ='📊 Monthly Base'!T24 -> 209582.57 | Q94: ='📊 Monthly Base'!T25 -> 1811380 | R94: ='📊 Monthly Base'!T6 -> 3134 | S94: ='📊 Monthly Base'!T7 -> 2688 | T94: ='📊 Monthly Base'!T8 -> 889 | U94: ='📊 Monthly Base'!T18 -> 58350.573 | V94: ='📊 Monthly Base'!T20 -> 70000 | W94: ='📊 Monthly Base'!T26 -> 0.84977798
L95: M19 | M95: ='📊 Monthly Base'!U11 -> 403453.6 | N95: ='📊 Monthly Base'!U9 -> 6964 | O95: ='📊 Monthly Base'!U5 -> 3500 | P95: ='📊 Monthly Base'!U24 -> 220377.55 | Q95: ='📊 Monthly Base'!U25 -> 2031757.5 | R95: ='📊 Monthly Base'!U6 -> 3233 | S95: ='📊 Monthly Base'!U7 -> 2799 | T95: ='📊 Monthly Base'!U8 -> 932 | U95: ='📊 Monthly Base'!U18 -> 60627.084 | V95: ='📊 Monthly Base'!U20 -> 70000 | W95: ='📊 Monthly Base'!U26 -> 0.84972972
L96: M20 | M96: ='📊 Monthly Base'!V11 -> 417639.8 | N96: ='📊 Monthly Base'!V9 -> 7202 | O96: ='📊 Monthly Base'!V5 -> 3500 | P96: ='📊 Monthly Base'!V24 -> 230563.95 | Q96: ='📊 Monthly Base'!V25 -> 2262321.5 | R96: ='📊 Monthly Base'!V6 -> 3324 | S96: ='📊 Monthly Base'!V7 -> 2904 | T96: ='📊 Monthly Base'!V8 -> 974 | U96: ='📊 Monthly Base'!V18 -> 62782.676 | V96: ='📊 Monthly Base'!V20 -> 70000 | W96: ='📊 Monthly Base'!V26 -> 0.84967267
L97: M21 | M97: ='📊 Monthly Base'!W11 -> 431097.3 | N97: ='📊 Monthly Base'!W9 -> 7427 | O97: ='📊 Monthly Base'!W5 -> 3500 | P97: ='📊 Monthly Base'!W24 -> 240221.3 | Q97: ='📊 Monthly Base'!W25 -> 2502542.8 | R97: ='📊 Monthly Base'!W6 -> 3408 | S97: ='📊 Monthly Base'!W7 -> 3004 | T97: ='📊 Monthly Base'!W8 -> 1015 | U97: ='📊 Monthly Base'!W18 -> 64833.346 | V97: ='📊 Monthly Base'!W20 -> 70000 | W97: ='📊 Monthly Base'!W26 -> 0.84960855
L98: M22 | M98: ='📊 Monthly Base'!X11 -> 443826.1 | N98: ='📊 Monthly Base'!X9 -> 7639 | O98: ='📊 Monthly Base'!X5 -> 3500 | P98: ='📊 Monthly Base'!X24 -> 249349.61 | Q98: ='📊 Monthly Base'!X25 -> 2751892.4 | R98: ='📊 Monthly Base'!X6 -> 3485 | S98: ='📊 Monthly Base'!X7 -> 3099 | T98: ='📊 Monthly Base'!X8 -> 1055 | U98: ='📊 Monthly Base'!X18 -> 66779.096 | V98: ='📊 Monthly Base'!X20 -> 70000 | W98: ='📊 Monthly Base'!X26 -> 0.8495377
L99: M23 | M99: ='📊 Monthly Base'!Y11 -> 455796.2 | N99: ='📊 Monthly Base'!Y9 -> 7838 | O99: ='📊 Monthly Base'!Y5 -> 3500 | P99: ='📊 Monthly Base'!Y24 -> 257930.21 | Q99: ='📊 Monthly Base'!Y25 -> 3009822.6 | R99: ='📊 Monthly Base'!Y6 -> 3556 | S99: ='📊 Monthly Base'!Y7 -> 3189 | T99: ='📊 Monthly Base'!Y8 -> 1093 | U99: ='📊 Monthly Base'!Y18 -> 68612.484 | V99: ='📊 Monthly Base'!Y20 -> 70000 | W99: ='📊 Monthly Base'!Y26 -> 0.84946675
L100: M24 | M100: ='📊 Monthly Base'!Z11 -> 467197.3 | N100: ='📊 Monthly Base'!Z9 -> 8027 | O100: ='📊 Monthly Base'!Z5 -> 3500 | P100: ='📊 Monthly Base'!Z24 -> 266098.87 | Q100: ='📊 Monthly Base'!Z25 -> 3275921.5 | R100: ='📊 Monthly Base'!Z6 -> 3622 | S100: ='📊 Monthly Base'!Z7 -> 3275 | T100: ='📊 Monthly Base'!Z8 -> 1130 | U100: ='📊 Monthly Base'!Z18 -> 70362.778 | V100: ='📊 Monthly Base'!Z20 -> 70000 | W100: ='📊 Monthly Base'!Z26 -> 0.84939387
L102: Scenario | M102: Investment R$1M | N102: Valuation 100% M24 | O102: ="Angel Return ("&TEXT('🎛️ Assumptions'!$B$59,"0%")&")" -> Angel Return (15%)
...

Sheet 📋 Executive Summary
B2: AUTONOMA · EXECUTIVE SUMMARY
B3: Asset-Light SaaS · Personal AI for Brazilian women · Brazil → LATAM · 24-month horizon
B6: 1 · THE COMPANY
B7: Vision | C7: To be the leading AI assistant for personal and financial autonomy in Latin America, starting with Brazil.
B8: Problem | C8: Generic assistants don't execute end-to-end tasks: the user still carries the mental load of planning, remembering, and solving.
B9: Solution | C9: Noma: assistant with memory + autonomous agents that complete full tasks (Sonnet 4.6 on paid plans; Haiku 4.5 on Free as acquisition cost).
B10: Why now | C10: Cost per token declining (caching -35% to -45%), agents mature for production, and Brazilian market with no player focused on this audience.
B12: 2 · BUSINESS MODEL · PLANS
B13: Plan | C13: Price (R$/month) | D13: AI Model | E13: Includes | F13: Funnel role
B14: Free | C14: 0 | D14: Haiku 4.5 | E14: 50 interactions/month | F14: Acquisition (mkt cost)
B15: Essencial | C15: ='🔧 Active Scenario'!B6 -> 39.9 | D15: Sonnet 4.6 | E15: Unlimited chat + memory · add-on specialized agents (avg R$ 10/month) | F15: Volume · revenue base
B16: Autônoma | C16: ='🔧 Active Scenario'!B7 -> 59.9 | D16: Sonnet 4.6 | E16: Chat + 1 autonomous agent | F16: Upsell · lock-in
B17: Livre | C17: ='🔧 Active Scenario'!B8 -> 79.9 | D17: Sonnet 4.6 | E17: Chat + 2 agents | F17: Premium · max lock-in
B18: Dynamic pricing per scenario selected in 🔧 Active Scenario!B2. Gross margin >80% sustained by caching and Free on Haiku.
B20: 3 · THE ANGEL INVESTOR OFFER
B21: Investment | C21: ='🎛️ Assumptions'!B58 -> 1000000 | D21: ← single entry, ~18-month runway
B22: Equity offered | C22: ='🎛️ Assumptions'!B59 -> 0.15 | D22: ← stake acquired in the investment
B23: Valuation pre-money | C23: ='🎛️ Assumptions'!B60 -> 5666666.7 | D23: = investment ÷ equity − investment
B24: Valuation post-money | C24: ='🎛️ Assumptions'!B61 -> 6666666.7 | D24: = investment ÷ equity
B25: Use of capital | C25: 40% Product · 30% Acquisition · 20% Team · 10% Reserve (detail in 💎 Angel Summary)
B27: 4 · FINANCIAL HIGHLIGHTS · ACTIVE SCENARIO: | C27: ='🔧 Active Scenario'!B2 -> Conservative
B28: Indicator | C28: M12 | D28: M24 | E28: Note
B29: Paying subscribers | C29: ='📊 Monthly Base'!N9 -> 4819 | D29: ='📊 Monthly Base'!Z9 -> 8027 | E29: compound growth from Free base
B30: MRR (R$/month) | C30: ='📊 Monthly Base'!N11 -> 277318.1 | D30: ='📊 Monthly Base'!Z11 -> 467197.3 | E30: monthly recurring revenue
B31: Cumulative revenue | C31: ='📊 Monthly Base'!N12 -> 1947589.4 | D31: ='📊 Monthly Base'!Z12 -> 6638262.2 | E31: sum of 24 months of MRR from active scenario (📊 Monthly Base)
B32: Monthly result | C32: ='📊 Monthly Base'!N24 -> 144705.1 | D32: ='📊 Monthly Base'!Z24 -> 266098.87 | E32: after API + fixed + taxes
B33: Gross margin (% MRR) | C33: ='📊 Monthly Base'!N26 -> 0.85013007 | D33: ='📊 Monthly Base'!Z26 -> 0.84939387 | E33: after API cost
B34: Cash breakeven | C34: {=IFERROR("M"&MATCH(TRUE,INDEX('📊 Monthly Base'!C25:Z25>0,0),0),">24m")} -> M5 | E34: cumulative result > 0
B35: LTV / CAC (Essencial) | C35: ='🔧 Active Scenario'!B56 -> 6.8861031 | E35: =IF(C35>=8,"✅ top quartile",IF(C35>=3,"✅ healthy","⚠️ review CAC")) -> ✅ healthy
B36: Valuation M24 (active scenario) | C36: =IF('🔧 Active Scenario'!B2="Conservative",'📊 Scenario Summary'!B21,IF('🔧 Active Scenario'!B2="Base",'📊 Scenario Summary'!C21,'📊 Scenario Summary'!D21)) -> 19914787 | E36: cumul. rev. 24m × scenario multiple
B37: Angel return (15% stake) | C37: =C36*'🎛️ Assumptions'!B59 -> 2987218 | D37: =C37/'🎛️ Assumptions'!B58 -> 2.987218 | E37: stake value ÷ investment
B39: 5 · INVESTMENT THESIS
B40: ① Unit economics proven from M1: LTV/CAC ≥5× even in the Conservative scenario; CAC payback < 3 months.
B41: ② Software margin (>80%) with controlled variable cost: Free runs on Haiku 4.5; paid on Sonnet 4.6 with caching.
B42: ③ Fast breakeven (M7 in Conservative) — the investment funds growth, not operating losses.
B43: ④ Churn decreases with agent adoption (8% → 3%): the more Noma executes, the greater the lock-in.
B44: ⑤ Viable exit in 24m: cumulative revenue supports Series A at 3–7× — 4–22× return on investment depending on scenario.
B46: Note: This study does not constitute an investment invitation or promise. All values are 100% dynamic — they recalculate when changing 🔧 Active Scenario!B2 and 🎛️ Assumptions. AutoNoma © 2025.

Sheet 🌎 Market & GTM
B2: AUTONOMA · MARKET & GO-TO-MARKET
B3: TAM/SAM/SOM sizing · acquisition funnel · channels · competitive positioning
B6: 1 · MARKET SIZE · BRAZIL (editable inputs in blue)
B7: Layer | C7: Users | D7: Annual potential (R$) | E7: % captured | F7: Definition
B8: TAM · total market | C8: 54000000 | D8: =C8*'🔧 Active Scenario'!B6*12 -> 25855200000 | F8: Connected adult women in Brazil (editable estimate)
B9: SAM · addressable market | C9: 12000000 | D9: =C9*'🔧 Active Scenario'!B6*12 -> 5745600000 | E9: =C9/C8 -> 0.22222222 | F9: Already pay for digital subscriptions and use AI/productivity apps
B10: SOM · captured by M24 (sign-ups) | C10: =('🔧 Active Scenario'!B30+'🔧 Active Scenario'!B31)*12 -> 78000 | D10: ='📊 Monthly Base'!Z11*12 -> 5606367.6 | E10: =C10/C9 -> 0.0065 | F10: Cumulative sign-ups in 24m (30-day trial) · potential = ARR at M24
B11: └ of which paying at M24 | C11: ='📊 Monthly Base'!Z9 -> 8027 | D11: ='📊 Monthly Base'!Z11 -> 467197.3 | E11: =C11/C10 -> 0.10291026 | F11: Cumulative Free → paid conversion rate
B12: Required SAM penetration in 24m is below 1% — the plan doesn't depend on dominating the market to deliver the projected return.
B14: 2 · ACQUISITION FUNNEL · ACTIVE SCENARIO (dynamic values)
B15: Funnel stage | C15: Value | D15: Unit | F15: Reading
B16: New Free sign-ups · M1–M12 | C16: ='🔧 Active Scenario'!B30 -> 3000 | D16: leads/month | F16: organic + viral + paid
B17: New Free sign-ups · M13–M24 | C17: ='🔧 Active Scenario'!B31 -> 3500 | D17: leads/month | F17: national scale
B18: Conversion Free → Essencial | C18: ='🔧 Active Scenario'!B32 -> 0.1 | D18: of eligible base/month | F18: paid entry door
B19: Upgrade Essencial → Autônoma | C19: ='🔧 Active Scenario'!B33 -> 0.07 | D19: of eligible base/month | F19: 1st autonomous agent
B20: Upgrade Autônoma → Livre | C20: ='🔧 Active Scenario'!B34 -> 0.02 | D20: of eligible base/month | F20: premium tier
B21: Monthly churn (Essencial / Autônoma / Livre) | C21: =TEXT('🔧 Active Scenario'!B35,"0%")&" / "&TEXT('🔧 Active Scenario'!B36,"0%")&" / "&TEXT('🔧 Active Scenario'!B37,"0%") -> 8% / 5% / 3% | D21: %/month | F21: lock-in grows with agents
B22: Full-loaded CAC | C22: ='🔧 Active Scenario'!B47 -> 80 | D22: per subscriber | F22: ="payback in "&TEXT('🔧 Active Scenario'!B57,"0.0")&" months" -> payback in 02 months
B23: % acquisition via paid (vs. organic) | C23: ='🔧 Active Scenario'!B48 -> 0.5 | D23: of new paying users | F23: remaining: organic, viral, partnerships
B25: 3 · CHANNELS & ENTRY STRATEGY
B26: Organic & viral | C26: Short-form content (TikTok/Reels/Shorts) showing Noma executing real tasks · in-app referral program
B27: Paid social | C27: Meta + TikTok Ads with use-case creatives · ~50% of new paying users · CAC cap governed by assumptions
B28: Partnerships & influencers | C28: Personal finance, career, and motherhood creators · trackable coupons per channel
B29: Free as engine | C29: Free plan (Haiku 4.5, 50 interactions/month) is the acquisition cost: the user experiences value before paying
B31: 4 · COMPETITIVE POSITIONING
B32: Player | C32: Price (R$/month) | D32: Focus | F32: Why AutoNoma wins
B33: ChatGPT / Gemini (generic) | C33: ~R$ 100+ | D33: generic chat | F33: End-to-end executing agents + personal context memory + affordable BRL pricing
B34: Productivity/organization apps | C34: R$ 20–50 | D34: lists and reminders | F34: Noma doesn’t remind the task — it does the task
B35: Embedded assistants (banks, e-commerce) | C35: free | D35: single vertical | F35: Cross-cutting view of the user’s life, not of a single product
B36: AutoNoma | C36: ="R$ "&TEXT('🔧 Active Scenario'!B6,"0,00")&"–"&TEXT('🔧 Active Scenario'!B8,"0,00") -> R$ 39,90–79,90 | D36: personal agents | F36: Audience focus, autonomous agents, optimized variable cost (Haiku Free / Sonnet paid)
B38: Note: market values are editable estimates for sizing — they do not replace formal research. AutoNoma © 2025.

Sheet 💎 Angel Summary
B2: AUTONOMA · ANGEL INVESTOR SUMMARY
B3: Asset-Light SaaS · Brazil → LATAM · Sonnet 4.6 (paid plans) + Haiku 4.5 (Free) · 24-month horizon
B5: 1 · THE OFFER
B6: Investment | C6: ='🎛️ Assumptions'!B58 -> 1000000 | D6: ← angel entry
B7: Equity offered | C7: ='🎛️ Assumptions'!B59 -> 0.15 | D7: ← stake acquired
B8: Valuation post-money | C8: ='🎛️ Assumptions'!B61 -> 6666666.7 | D8: = investment ÷ equity
B9: Valuation pre-money | C9: ='🎛️ Assumptions'!B60 -> 5666666.7
B11: 2 · MILESTONES TO SERIES A (Base scenario)
B12: Indicator | C12: M12 | D12: M24
B13: Paying subscribers | C13: ='📊 Monthly Base'!N9 -> 4819 | D13: ='📊 Monthly Base'!Z9 -> 8027
B14: MRR (R$/month) | C14: ='📊 Monthly Base'!N11 -> 277318.1 | D14: ='📊 Monthly Base'!Z11 -> 467197.3
B15: Cumulative revenue | C15: ='📊 Monthly Base'!N12 -> 1947589.4 | D15: ='📊 Monthly Base'!Z12 -> 6638262.2
B16: Gross margin | C16: ='📊 Monthly Base'!N26 -> 0.85013007 | D16: ='📊 Monthly Base'!Z26 -> 0.84939387
B17: Monthly result | C17: ='📊 Monthly Base'!N24 -> 144705.1 | D17: ='📊 Monthly Base'!Z24 -> 266098.87
B19: 3 · ANGEL RETURN (15% stake)
B20: Scenario | C20: Valuation M24 | D20: 15% stake value | E20: Multiple on investment
B21: Conservative | C21: ='📊 Scenario Summary'!B21 -> 19914787 | D21: =C21*'🎛️ Assumptions'!$B$59 -> 2987218 | E21: =D21/'🎛️ Assumptions'!$B$58 -> 2.987218
B22: Base | C22: ='📊 Scenario Summary'!C21 -> 50824494 | D22: =C22*'🎛️ Assumptions'!$B$59 -> 7623674 | E22: =D22/'🎛️ Assumptions'!$B$58 -> 7.623674
B23: Optimistic | C23: ='📊 Scenario Summary'!D21 -> 1.0118223e+08 | D23: =C23*'🎛️ Assumptions'!$B$59 -> 15177334 | E23: =D23/'🎛️ Assumptions'!$B$58 -> 15.177334
B25: 4 · USE OF CAPITAL (R$1M · ~18-month runway)
B26: Product & Engineering (Sonnet/Haiku, dev) | C26: 0.4 | D26: =C26*'🎛️ Assumptions'!$B$58 -> 400000
B27: Acquisition & Marketing (CAC, growth) | C27: 0.3 | D27: =C27*'🎛️ Assumptions'!$B$58 -> 300000
B28: Team & Operations (CS, founder comp) | C28: 0.2 | D28: =C28*'🎛️ Assumptions'!$B$58 -> 200000
B29: Reserve & Legal/Accounting | C29: 0.1 | D29: =C29*'🎛️ Assumptions'!$B$58 -> 100000
B30: Total | C30: =SUM(C26:C29) -> 1 | D30: =SUM(D26:D29) -> 1000000
B32: 5 · STRESS TEST / DOWNSIDE (transparency to the angel)
B33: ="• Even in the Conservative scenario, the investment returns ~"&TEXT('📊 Scenario Summary'!B23,"0.0")&"× in 24 months ("&TEXT('🎛️ Assumptions'!B59,"0%")&" stake = R$ "&TEXT('📊 Scenario Summary'!B22/1000000,"0.0")&"M)." -> • Even in the Conservative scenario, the investment returns ~03× in 24 months (15% stake = R$ 03M).
B34: • Differentiated churn by plan: Essencial 8%, Autônoma 5%, Livre 3% — lock-in grows with agent usage.
B35: • Cash break-even at M6; gross margin >80% sustained by running Free on Haiku (cost only).
B36: • Sensitive to: actual CAC (currently R$60 full-loaded) and Free→paid conversion. Both controllable in 🎛️ Assumptions.
B37: • Next milestone: Cumul. revenue R$15M at M24 supports Series A conversion at 5× revenue (≈R$75M).
B39: Note: This summary does not constitute an investment invitation or promise. All values recalculate when changing the scenario in 🔧 Active Scenario and assumptions in 🎛️ Assumptions. AutoNoma © 2025.
B42: 6 · SENSITIVITY: CHURN × LTV/CAC (Essencial plan, Base scenario)
B43: Churn/month | C43: Avg. lifetime (m) | D43: LTV (R$) | E43: LTV / CAC | F43: Reading
B44: 0.05 | C44: =1/B44 -> 20 | D44: ='📊 Scenario Summary'!$C$13*C44 -> 867.1112 | E44: =D44/'🎛️ Assumptions'!$C$48 -> 14.451853 | F44: =IF(E44>=8,"✅ top quartile",IF(E44>=3,"✅ healthy","⚠️ review CAC")) -> ✅ top quartile
B45: 0.06 | C45: =1/B45 -> 16.666667 | D45: ='📊 Scenario Summary'!$C$13*C45 -> 722.59267 | E45: =D45/'🎛️ Assumptions'!$C$48 -> 12.043211 | F45: =IF(E45>=8,"✅ top quartile",IF(E45>=3,"✅ healthy","⚠️ review CAC")) -> ✅ top quartile
B46: 0.07 | C46: =1/B46 -> 14.285714 | D46: ='📊 Scenario Summary'!$C$13*C46 -> 619.36514 | E46: =D46/'🎛️ Assumptions'!$C$48 -> 10.322752 | F46: =IF(E46>=8,"✅ top quartile",IF(E46>=3,"✅ healthy","⚠️ review CAC")) -> ✅ top quartile
B47: 0.08 | C47: =1/B47 -> 12.5 | D47: ='📊 Scenario Summary'!$C$13*C47 -> 541.9445 | E47: =D47/'🎛️ Assumptions'!$C$48 -> 9.0324083 | F47: =IF(E47>=8,"✅ top quartile",IF(E47>=3,"✅ healthy","⚠️ review CAC")) -> ✅ top quartile
B48: 0.1 | C48: =1/B48 -> 10 | D48: ='📊 Scenario Summary'!$C$13*C48 -> 433.5556 | E48: =D48/'🎛️ Assumptions'!$C$48 -> 7.2259267 | F48: =IF(E48>=8,"✅ top quartile",IF(E48>=3,"✅ healthy","⚠️ review CAC")) -> ✅ healthy
B49: 0.12 | C49: =1/B49 -> 8.3333333 | D49: ='📊 Scenario Summary'!$C$13*C49 -> 361.29633 | E49: =D49/'🎛️ Assumptions'!$C$48 -> 6.0216056 | F49: =IF(E49>=8,"✅ top quartile",IF(E49>=3,"✅ healthy","⚠️ review CAC")) -> ✅ healthy
...

Sheet 📈 Annual P&L
B2: AUTONOMA · PROJECTED P&L · YEAR 1 & YEAR 2
B3: ="Consolidated from 📊 Monthly Base · active scenario: "&'🔧 Active Scenario'!B2&" · values recalculate when switching scenario" -> Consolidated from 📊 Monthly Base · active scenario: Conservative · values recalculate when switching scenario
B6: Line item (R$) | C6: Year 1 (M1–M12) | D6: Year 2 (M13–M24) | E6: Total 24m | F6: Note
B7: Gross revenue (subscriptions) | C7: =SUM('📊 Monthly Base'!C11:N11) -> 1947589.4 | D7: =SUM('📊 Monthly Base'!O11:Z11) -> 4690672.8 | E7: =C7+D7 -> 6638262.2 | F7: sum of monthly MRR
B8: (−) Taxes on revenue | C8: =-SUM('📊 Monthly Base'!C21:N21) -> -253186.62 | D8: =-SUM('📊 Monthly Base'!O21:Z21) -> -609787.46 | E8: =C8+D8 -> -862974.09 | F8: ="Simples Nacional "&TEXT('🔧 Active Scenario'!B59,"0.0%")&" on MRR" -> Simples Nacional 13% on MRR
B9: (=) Net revenue | C9: =C7+C8 -> 1694402.8 | D9: =D7+D8 -> 4080885.3 | E9: =C9+D9 -> 5775288.1
B10: (−) Variable cost · Anthropic API | C10: =-SUM('📊 Monthly Base'!C18:N18) -> -294218.78 | D10: =-SUM('📊 Monthly Base'!O18:Z18) -> -705147.83 | E10: =C10+D10 -> -999366.62 | F10: Free tokens (Haiku) + paid (Sonnet, w/ caching)
B11: (=) Gross profit | C11: =C9+C10 -> 1400184 | D11: =D9+D10 -> 3375737.5 | E11: =C11+D11 -> 4775921.5
B12: Gross margin (% gross revenue) | C12: =IF(C7=0,0,C11/C7) -> 0.71893182 | D12: =IF(D7=0,0,D11/D7) -> 0.71967022 | E12: =IF(E7=0,0,E11/E7) -> 0.71945358
B13: (−) Fixed operating costs | C13: =-SUM('📊 Monthly Base'!C20:N20) -> -660000 | D13: =-SUM('📊 Monthly Base'!O20:Z20) -> -840000 | E13: =C13+D13 -> -1500000 | F13: breakdown below
B14: ├ Team | C14: =-'🔧 Active Scenario'!B39*12 -> -480000 | D14: =-'🔧 Active Scenario'!B40*12 -> -600000 | E14: =C14+D14 -> -1080000
B15: ├ Infrastructure & tools | C15: =-'🔧 Active Scenario'!B41*12 -> -60000 | D15: =-'🔧 Active Scenario'!B42*12 -> -84000 | E15: =C15+D15 -> -144000
B16: ├ Marketing & acquisition | C16: =-'🔧 Active Scenario'!B43*12 -> -60000 | D16: =-'🔧 Active Scenario'!B44*12 -> -96000 | E16: =C16+D16 -> -156000
B17: └ Other (accounting, legal, admin) | C17: =-'🔧 Active Scenario'!B45*12 -> -60000 | D17: =-'🔧 Active Scenario'!B45*12 -> -60000 | E17: =C17+D17 -> -120000
B18: (=) EBITDA ≈ operating result | C18: =C11+C13 -> 740183.99 | D18: =D11+D13 -> 2535737.5 | E18: =C18+D18 -> 3275921.5 | F18: asset-light: no relevant capex, no debt
B19: EBITDA margin (% gross revenue) | C19: =IF(C7=0,0,C18/C7) -> 0.38005136 | D19: =IF(D7=0,0,D18/D7) -> 0.54059143 | E19: =IF(E7=0,0,E18/E7) -> 0.49349083
B21: Cumulative result at end of period | C21: ='📊 Monthly Base'!N25 -> 740183.99 | D21: ='📊 Monthly Base'!Z25 -> 3275921.5 | F21: cross-check with row 25 of 📊 Monthly Base
B22: Check · EBITDA 24m = cumul. result M24 | C22: =IF(ROUND(E18-D21,0)=0,"✅ matches","⚠️ diverges by R$ "&TEXT(E18-D21,"#,##0")) -> ✅ matches
B24: Note: Simplified accrual P&L (no D&A, financial result, or additional income tax — Simples Nacional on revenue). Paid CAC is included in Marketing & acquisition.

Sheet 💰 Cash & Runway
B2: AUTONOMA · CASH & RUNWAY · 24 MONTHS
B3: ="R$ "&TEXT('🎛️ Assumptions'!B58,"#,##0")&" investment at M1 + monthly operating result · scenario: "&'🔧 Active Scenario'!B2 -> R$ 1000000,0 investment at M1 + monthly operating result · scenario: Conservative
B6: MONTHLY CASH FLOW (R$)
B7: Month | C7: ='📊 Monthly Base'!C3 -> M01 | D7: ='📊 Monthly Base'!D3 -> M02 | E7: ='📊 Monthly Base'!E3 -> M03 | F7: ='📊 Monthly Base'!F3 -> M04 | G7: ='📊 Monthly Base'!G3 -> M05 | H7: ='📊 Monthly Base'!H3 -> M06 | I7: ='📊 Monthly Base'!I3 -> M07 | J7: ='📊 Monthly Base'!J3 -> M08 | ... Z7: ='📊 Monthly Base'!Z3 -> M24 ★
B8: Capital inflow (angel investment) | C8: =IF(C7="M01",'🎛️ Assumptions'!$B$58,0) -> 1000000 | D8: =IF(D7="M01",'🎛️ Assumptions'!$B$58,0) -> 0 | E8: =IF(E7="M01",'🎛️ Assumptions'!$B$58,0) -> 0 | F8: =IF(F7="M01",'🎛️ Assumptions'!$B$58,0) -> 0 | G8: =IF(G7="M01",'🎛️ Assumptions'!$B$58,0) -> 0 | H8: =IF(H7="M01",'🎛️ Assumptions'!$B$58,0) -> 0 | I8: =IF(I7="M01",'🎛️ Assumptions'!$B$58,0) -> 0 | J8: =IF(J7="M01",'🎛️ Assumptions'!$B$58,0) -> 0 | ... Z8: =IF(Z7="M01",'🎛️ Assumptions'!$B$58,0) -> 0
B9: Monthly operating result | C9: ='📊 Monthly Base'!C24 -> -39903.991 | D9: ='📊 Monthly Base'!D24 -> -17668.581 | E9: ='📊 Monthly Base'!E24 -> 3441.7706 | F9: ='📊 Monthly Base'!F24 -> 23230.937 | G9: ='📊 Monthly Base'!G24 -> 41872.273 | H9: ='📊 Monthly Base'!H24 -> 59384.705 | I9: ='📊 Monthly Base'!I24 -> 75810.175 | J9: ='📊 Monthly Base'!J24 -> 91280.094 | ... Z9: ='📊 Monthly Base'!Z24 -> 266098.87
B10: Cash balance (end of month) | C10: =C8+C9 -> 960096.01 | D10: =C10+D8+D9 -> 942427.43 | E10: =D10+E8+E9 -> 945869.2 | F10: =E10+F8+F9 -> 969100.14 | G10: =F10+G8+G9 -> 1010972.4 | H10: =G10+H8+H9 -> 1070357.1 | I10: =H10+I8+I9 -> 1146167.3 | J10: =I10+J8+J9 -> 1237447.4 | K10: =J10+K8+K9 -> 1343321.4 | ... Z10: =Y10+Z8+Z9 -> 4275921.5
B12: RUNWAY & SOLVENCY INDICATORS
B13: Minimum cash in period | C13: =MIN(C10:Z10) -> 942427.43 | G13: ="occurs at "&INDEX(C7:Z7,MATCH(MIN(C10:Z10),C10:Z10,0))&" — "&IF(MIN(C10:Z10)>0,"investment covers entire curve: cash never goes negative ✅","⚠️ cash goes negative: review assumptions or investment") -> occurs at M02 — investment covers entire curve: cash never goes negative ✅
B14: Ending cash · M24 | C14: =Z10 -> 4275921.5 | G14: investment + 24-month cumulative result
B15: Avg. burn pre-breakeven | C15: =IFERROR(AVERAGEIF(C9:Z9,"<0"),0) -> -28786.286 | G15: average of months with negative result
B16: Theoretical runway w/o revenue | C16: ='🎛️ Assumptions'!B58/AVERAGE('📊 Monthly Base'!C20:N20) -> 18.181818 | G16: investment ÷ avg. Year 1 fixed cost (extreme stress: zero revenue)
B17: Cash breakeven (cumul. result > 0) | C17: {=IFERROR("M"&MATCH(TRUE,INDEX('📊 Monthly Base'!C25:Z25>0,0),0),">24m")} -> M5 | G17: from this point the operation is self-financing
B19: Note: Simplified cash flow = investment + operating result (no capex, no debt, no dividends). Alternative scenarios in 📊 Scenario Summary.

Sheet ⚠️ Risks & Roadmap
B2: AUTONOMA · RISKS, MITIGATIONS & ROADMAP
B3: Risk matrix with monitoring triggers · 24-month execution roadmap · management guard-rails
B6: 1 · RISK MATRIX & MITIGATIONS
B7: Risk | C7: Probability | D7: Impact | E7: Mitigation | F7: Alert trigger
B8: CAC above forecast (paid saturated) | C8: Medium | D8: High | E8: LTV/CAC ≥3× discipline per channel; reallocate budget to organic/partnerships; creatives tested weekly | F8: Blended CAC > R$ 120
B9: Churn above plan | C9: Medium | D9: High | E9: Guided onboarding; 1st agent activation within first 7 days (churn drops from 8% to 5–3% with active agents) | F9: Essencial churn > 10%/month
B10: API price increase / end of caching | C10: Low | D10: High | E10: Multi-model architecture (abstraction layer); usage limits per plan; partial price pass-through if needed | F10: Gross margin < 70%
B11: USD/BRL FX rate (dollar-denominated API cost) | C11: Medium | D11: Medium | E11: Margin >80% absorbs fluctuations; editable FX assumption in 🎛️ Assumptions; annual price adjustment | F11: USD > R$ 6.50
B12: Big techs launch direct competitor | C12: High | D12: Medium | E12: Niche focus + brand + accumulated personal memory (switching cost); local execution speed | F12: Conversion drop in new cohorts
B13: Single-vendor dependency (Anthropic) | C13: Low | D13: High | E13: LLM-agnostic abstraction layer; periodic testing with alternative models; SLA contract | F13: Latency/SLA below standard
B14: LGPD · sensitive data privacy | C14: Medium | D14: High | E14: Privacy by design; encryption at rest and in transit; granular consent; DPO from M1 | F14: Any data incident
B15: Execution with lean team | C15: Medium | D15: Medium | E15: 20% of investment in team; product/growth advisors; roadmap with quarterly verifiable milestones | F15: Delay > 1 quarter on milestones
B17: 2 · EXECUTION ROADMAP · 24 MONTHS (dynamic goals from active scenario)
B18: Phase | C18: Period | E18: Key deliverables | F18: Verifiable target
B19: Launch | C19: M1–M3 | E19: App + Noma core (chat with memory) · onboarding · recurring billing · beta with waitlist | F19: =TEXT('📊 Monthly Base'!E9,"#,##0")&" paying at M3" -> 1437,0 paying at M3
B20: Traction | C20: M4–M6 | E20: 1st autonomous agent (Autônoma plan) · referral program · paid ads at scale begins | F20: {="Cash breakeven at "&IFERROR("M"&MATCH(TRUE,INDEX('📊 Monthly Base'!C25:Z25>0,0),0),">24m")} -> Cash breakeven at M5
B21: Scale · Year 1 | C21: M7–M12 | E21: Livre plan (2 agents) · influencer partnerships · paid channel expansion | F21: =TEXT('📊 Monthly Base'!N9,"#,##0")&" paying · MRR R$ "&TEXT('📊 Monthly Base'!N11,"#,##0")&" at M12" -> 4819,0 paying · MRR R$ 277318,10 at M12
B22: Expansion | C22: M13–M18 | E22: New vertical agents (finance, career, family) · retention improvement · data prep for due diligence | F22: ="MRR R$ "&TEXT('📊 Monthly Base'!T11,"#,##0")&" at M18" -> MRR R$ 388428,90 at M18
B23: Series A ready | C23: M19–M24 | E23: Margin efficiency · LATAM study (Spanish) · Series A fundraise with audited metrics | F23: =TEXT('📊 Monthly Base'!Z9,"#,##0")&" paying · valuation R$ "&TEXT(IF('🔧 Active Scenario'!B2="Conservative",'📊 Scenario Summary'!B21,IF('🔧 Active Scenario'!B2="Base",'📊 Scenario Summary'!C21,'📊 Scenario Summary'!D21))/1000000,"#,##0.0")&"M" -> 8027,0 paying · valuation R$ 19,9148M
B25: 3 · MANAGEMENT GUARD-RAILS (auto status · active scenario)
B26: Indicator | C26: Current | D26: Threshold | E26: Status
B27: LTV / CAC (Essencial) | C27: ='🔧 Active Scenario'!B56 -> 6.8861031 | D27: ≥ 3.0× | E27: =IF(C27>=3,"✅ within guard-rail","⚠️ below minimum — slow paid and review funnel") -> ✅ within guard-rail
B28: CAC payback | C28: ='🔧 Active Scenario'!B57 -> 1.8152502 | D28: ≤ 6 months | E28: =IF(C28<=6,"✅ within guard-rail","⚠️ long payback — review CAC or pricing") -> ✅ within guard-rail
B29: Gross margin M24 | C29: ='📊 Monthly Base'!Z26 -> 0.84939387 | D29: ≥ 70% | E29: =IF(C29>=0.7,"✅ within guard-rail","⚠️ compressed margin — renegotiate API/pass-through price") -> ✅ within guard-rail
B30: Minimum cash on curve | C30: =MIN('💰 Cash & Runway'!C10:Z10) -> 942427.43 | D30: > R$ 0 | E30: =IF(C30>0,"✅ investment covers entire cash curve","⚠️ negative cash — increase investment or cut costs") -> ✅ investment covers entire cash curve
B32: Note: Triggers and limits are suggested management policy — editable per governance agreed with the investor. AutoNoma © 2025.

Sheet 🔧 Active Scenario
A1: AutoNoma · Scenario Selector · Controller
A2: ▶ ACTIVE SCENARIO ◀ (change here to switch model) | B2: Conservative | C2: ← Select: Conservative / Base / Optimistic
A3: Assumptions column (internal use — do not edit) | B3: =MATCH(B2,{"Conservative","Base","Optimistic"},0)+1 -> 2
A4: Resolved assumptions for the selected scenario
A5: ── PRICING ──
A6: Essencial Price | B6: =INDEX('🎛️ Assumptions'!B5:D5,1,MATCH($B$2,{"Conservative","Base","Optimistic"},0)) -> 39.9 | C6: ← Assumptions!Essencial Price (row 5)
A7: Autônoma Price | B7: =INDEX('🎛️ Assumptions'!B6:D6,1,MATCH($B$2,{"Conservative","Base","Optimistic"},0)) -> 59.9 | C7: ← Assumptions!Autônoma Price (row 6)
A8: Livre Price | B8: =INDEX('🎛️ Assumptions'!B7:D7,1,MATCH($B$2,{"Conservative","Base","Optimistic"},0)) -> 79.9 | C8: ← Assumptions!Livre Price (row 7)
A9: Add-on agent revenue / Essencial subscriber | B9: =INDEX('🎛️ Assumptions'!B8:D8,1,MATCH($B$2,{"Conservative","Base","Optimistic"},0)) -> 10 | C9: ← Assumptions!Add-on agents (row 8)
A10: ── API ──
A11: FX Rate USD/BRL | B11: =INDEX('🎛️ Assumptions'!B10:D10,1,MATCH($B$2,{"Conservative","Base","Optimistic"},0)) -> 5.3 | C11: ← Assumptions!FX Rate USD/BRL (row 10)
A12: Sonnet Input $/MTok | B12: =INDEX('🎛️ Assumptions'!B13:D13,1,MATCH($B$2,{"Conservative","Base","Optimistic"},0)) -> 3 | C12: ← Assumptions!Sonnet 4.6 Input ($/MTok) (row 13)
A13: Sonnet Output $/MTok | B13: =INDEX('🎛️ Assumptions'!B14:D14,1,MATCH($B$2,{"Conservative","Base","Optimistic"},0)) -> 15 | C13: ← Assumptions!Sonnet 4.6 Output ($/MTok) (row 14)
A14: Haiku Input $/MTok | B14: =INDEX('🎛️ Assumptions'!B11:D11,1,MATCH($B$2,{"Conservative","Base","Optimistic"},0)) -> 1 | C14: ← Assumptions!Haiku 4.5 Input ($/MTok) (row 11)
A15: Haiku Output $/MTok | B15: =INDEX('🎛️ Assumptions'!B12:D12,1,MATCH($B$2,{"Conservative","Base","Optimistic"},0)) -> 5 | C15: ← Assumptions!Haiku 4.5 Output ($/MTok) (row 12)
A16: Caching Discount | B16: =INDEX('🎛️ Assumptions'!B15:D15,1,MATCH($B$2,{"Conservative","Base","Optimistic"},0)) -> 0.35 | C16: ← Assumptions!Prompt Caching Discount (%) (row 15)
A17: ── USAGE ──
A18: Free: interactions/month | B18: =INDEX('🎛️ Assumptions'!B17:D17,1,MATCH($B$2,{"Conservative","Base","Optimistic"},0)) -> 50 | C18: ← Assumptions!Free: interactions/month (LIMIT) (row 14)
A19: Free: tokens input | B19: =INDEX('🎛️ Assumptions'!B18:D18,1,MATCH($B$2,{"Conservative","Base","Optimistic"},0)) -> 900 | C19: ← Assumptions!Free: tokens input/interaction (row 15)
A20: Free: tokens output | B20: =INDEX('🎛️ Assumptions'!B19:D19,1,MATCH($B$2,{"Conservative","Base","Optimistic"},0)) -> 450 | C20: ← Assumptions!Free: tokens output/interaction (row 16)
A21: Free: % active/month | B21: =INDEX('🎛️ Assumptions'!B20:D20,1,MATCH($B$2,{"Conservative","Base","Optimistic"},0)) -> 0.5 | C21: ← Assumptions!Free: % active users/month (row 17)
A22: Essencial: interactions/month | B22: =INDEX('🎛️ Assumptions'!B21:D21,1,MATCH($B$2,{"Conservative","Base","Optimistic"},0)) -> 120 | C22: ← Assumptions!Essencial: chat interactions/month (row 18)
A23: Essencial: tokens input | B23: =INDEX('🎛️ Assumptions'!B22:D22,1,MATCH($B$2,{"Conservative","Base","Optimistic"},0)) -> 1200 | C23: ← Assumptions!Essencial: tokens input/interaction (row 19)
A24: Essencial: tokens output | B24: =INDEX('🎛️ Assumptions'!B23:D23,1,MATCH($B$2,{"Conservative","Base","Optimistic"},0)) -> 700 | C24: ← Assumptions!Essencial: tokens output/interaction (row 20)
A25: Autônoma: agent sessions/month | B25: =INDEX('🎛️ Assumptions'!B25:D25,1,MATCH($B$2,{"Conservative","Base","Optimistic"},0)) -> 35 | C25: ← Assumptions!Autônoma: agent sessions/month (row 22)
A26: Autônoma: tokens input/session | B26: =INDEX('🎛️ Assumptions'!B26:D26,1,MATCH($B$2,{"Conservative","Base","Optimistic"},0)) -> 3000 | C26: ← Assumptions!Autônoma: tokens input/agent session (row 23)
A27: Autônoma: tokens output/session | B27: =INDEX('🎛️ Assumptions'!B27:D27,1,MATCH($B$2,{"Conservative","Base","Optimistic"},0)) -> 1800 | C27: ← Assumptions!Autônoma: tokens output/agent session (row 24)
A28: Livre: total sessions/month | B28: =INDEX('🎛️ Assumptions'!B29:D29,1,MATCH($B$2,{"Conservative","Base","Optimistic"},0)) -> 60 | C28: ← Assumptions!Livre: total agent sessions/month (row 26)
A29: ── GROWTH ──
A30: Free leads M1–12 | B30: =INDEX('🎛️ Assumptions'!B31:D31,1,MATCH($B$2,{"Conservative","Base","Optimistic"},0)) -> 3000 | C30: ← Assumptions!Free Growth M1–12 (leads/month) (row 28)
A31: Free leads M13–24 | B31: =INDEX('🎛️ Assumptions'!B32:D32,1,MATCH($B$2,{"Conservative","Base","Optimistic"},0)) -> 3500 | C31: ← Assumptions!Free Growth M13–24 (leads/month) (row 29)
A32: Conv. Free→Essencial | B32: =INDEX('🎛️ Assumptions'!B33:D33,1,MATCH($B$2,{"Conservative","Base","Optimistic"},0)) -> 0.1 | C32: ← Assumptions!Free → Essencial Conversion (%) (row 31)
A33: Conv. Free→Autônoma | B33: =INDEX('🎛️ Assumptions'!B34:D34,1,MATCH($B$2,{"Conservative","Base","Optimistic"},0)) -> 0.07 | C33: ← Assumptions!Free → Autônoma Conversion (%) (row 32)
A34: Conv. Free→Livre | B34: =INDEX('🎛️ Assumptions'!B35:D35,1,MATCH($B$2,{"Conservative","Base","Optimistic"},0)) -> 0.02 | C34: ← Assumptions!Free → Livre Conversion (%) (row 33)
A35: Churn Essencial/month | B35: =INDEX('🎛️ Assumptions'!B36:D36,1,MATCH($B$2,{"Conservative","Base","Optimistic"},0)) -> 0.08 | C35: ← Assumptions!Monthly Churn Essencial (row 34)
A36: Churn Autônoma/month | B36: =INDEX('🎛️ Assumptions'!B37:D37,1,MATCH($B$2,{"Conservative","Base","Optimistic"},0)) -> 0.05 | C36: ← Assumptions!Monthly Churn Autônoma (row 35)
A37: Churn Livre/month | B37: =INDEX('🎛️ Assumptions'!B38:D38,1,MATCH($B$2,{"Conservative","Base","Optimistic"},0)) -> 0.03 | C37: ← Assumptions!Monthly Churn Livre (row 36)
A38: ── FIXED COSTS ──
A39: Team Year 1 | B39: =INDEX('🎛️ Assumptions'!B40:D40,1,MATCH($B$2,{"Conservative","Base","Optimistic"},0)) -> 40000 | C39: ← Assumptions!Team Year 1 (avg/month) (row 38)
A40: Team Year 2 | B40: =INDEX('🎛️ Assumptions'!B41:D41,1,MATCH($B$2,{"Conservative","Base","Optimistic"},0)) -> 50000 | C40: ← Assumptions!Team Year 2 (avg/month) (row 39)
...

Sheet 🎛️ Assumptions
A1: AutoNoma · Assumptions · Single Source of Truth · Haiku Freemium / 100% Sonnet 4.6 Plans & Agents
A2: Blue = Editable input | B2: Black = Formula | C2: Purple = Cross-sheet link
A3: PARAMETER | B3: Conservative | C3: Base (default) | D3: Optimistic | E3: UNIT/NOTE
A4: 1 · PLAN PRICING (R$/month)
A5: Essencial Price | B5: 39.9 | C5: 39.9 | D5: 39.9 | E5: R$/month · + sporadic agent usage
A6: Autônoma Price | B6: 59.9 | C6: 59.9 | D6: 62.9 | E6: R$/month · chat + 1 agent
A7: Livre Price | B7: 79.9 | C7: 79.9 | D7: 79.9 | E7: R$/month · chat + 2 agents
A8: Add-on agent revenue per Essencial subscriber (R$/month) | B8: 10 | C8: 10 | D8: 10
A9: 2 · ANTHROPIC API COST (H1 2026)
A10: FX Rate USD/BRL | B10: 5.3 | C10: 5.3 | D10: 5.3 | E10: R$ per USD
A11: Haiku 4.5 Input ($/MTok) | B11: 1 | C11: 1 | D11: 1 | E11: USD — official Anthropic (Free plan)
A12: Haiku 4.5 Output ($/MTok) | B12: 5 | C12: 5 | D12: 5 | E12: USD — official Anthropic (Free plan)
A13: Sonnet 4.6 Input ($/MTok) | B13: 3 | C13: 3 | D13: 3 | E13: USD — official Anthropic
A14: Sonnet 4.6 Output ($/MTok) | B14: 15 | C14: 15 | D14: 15 | E14: USD — official Anthropic
A15: Prompt Caching Discount (%) | B15: 0.35 | C15: 0.4 | D15: 0.45 | E15: % reduction on fixed block
A16: 3 · USAGE PER PLAN — 100% SONNET 4.6
A17: Free: interactions/month (LIMIT) | B17: 50 | C17: 50 | D17: 50 | E17: Sonnet · product cap
A18: Free: tokens input/interaction | B18: 900 | C18: 900 | D18: 900 | E18: includes cached system prompt
A19: Free: tokens output/interaction | B19: 450 | C19: 450 | D19: 450 | E19: guided response
A20: Free: % active users/month | B20: 0.5 | C20: 0.5 | D20: 0.5 | E20: % of sign-ups active in the month
A21: Essencial: chat interactions/month | B21: 120 | C21: 140 | D21: 180 | E21: practical unlimited · 20 days × use
A22: Essencial: tokens input/interaction | B22: 1200 | C22: 1400 | D22: 1800 | E22: Noma context + memory
A23: Essencial: tokens output/interaction | B23: 700 | C23: 700 | D23: 700 | E23: response + autonomous action
A24: Autônoma: chat (= Essencial) | B24: 140 | C24: 140 | D24: 140 | E24: unlimited Sonnet chat
A25: Autônoma: agent sessions/month | B25: 35 | C25: 45 | D25: 60 | E25: deep sessions with 1 agent
A26: Autônoma: tokens input/agent session | B26: 3000 | C26: 3000 | D26: 3000 | E26: resolution context + memory
A27: Autônoma: tokens output/agent session | B27: 1800 | C27: 1800 | D27: 1800 | E27: full resolution + confirmation
A28: Livre: chat (= Essencial) | B28: 140 | C28: 140 | D28: 140 | E28: unlimited Sonnet chat
A29: Livre: total agent sessions/month | B29: 60 | C29: 80 | D29: 100 | E29: 2 agents · more than Autônoma
A30: 4 · USER BASE GROWTH
A31: Free Growth M1–12 (leads/month) | B31: 3000 | C31: 3500 | D31: 4000 | E31: organic+viral+paid sign-ups
A32: Free Growth M13–24 (leads/month) | B32: 3500 | C32: 4000 | D32: 4500 | E32: Brazil scale
A33: Conversion Free → Essencial (%) | B33: 0.1 | C33: 0.15 | D33: 0.2 | E33: % Free base becoming subscribers
A34: Conversion Free → Autônoma (%) | B34: 0.07 | C34: 0.07 | D34: 0.07 | E34: % Essencial that upgrade
A35: Conversion Free → Livre (%) | B35: 0.02 | C35: 0.03 | D35: 0.03 | E35: % Autônoma that upgrade
A36: Monthly Churn Essencial | B36: 0.08 | C36: 0.07 | D36: 0.05 | E36: % cancel per month
A37: Monthly Churn Autônoma | B37: 0.05 | C37: 0.05 | D37: 0.06 | E37: % cancel per month · agent = lock-in
A38: Monthly Churn Livre | B38: 0.03 | C38: 0.03 | D38: 0.02 | E38: % cancel · 2 agents = max lock-in
A39: 5 · MONTHLY FIXED COSTS (R$)
A40: Team Year 1 (avg/month) | B40: 40000 | C40: 45000 | D40: 50000 | E40: devs+CS+founder comp
...

Sheet 📊 Monthly Base
A1: AutoNoma · Monthly Base · 24 Months · Dynamic Formulas · Scenario Controlled by 🔧 Active Scenario
A2: Active scenario: | C2: ='🔧 Active Scenario'!B2 -> Conservative
A3: Indicator | B3: Unit | C3: M01 | D3: M02 | E3: M03 | F3: M04 | G3: M05 | H3: M06 | I3: M07 | J3: M08 | K3: M09 | L3: M10 | M3: M11 | N3: M12 ★ | O3: M13 | P3: M14 | Q3: M15 | R3: M16 | S3: M17 | T3: M18 | U3: M19 | V3: M20 | W3: M21 | X3: M22 | Y3: M23 | Z3: M24 ★
A4: USERS
A5: Free · 30-day Trial (active in month) | B5: usr | C5: ='🎛️ Assumptions'!B64 -> 2000 | D5: ='🔧 Active Scenario'!$B$30 -> 3000 | E5: ='🔧 Active Scenario'!$B$30 -> 3000 | F5: ='🔧 Active Scenario'!$B$30 -> 3000 | G5: ='🔧 Active Scenario'!$B$30 -> 3000 | H5: ='🔧 Active Scenario'!$B$30 -> 3000 | I5: ='🔧 Active Scenario'!$B$30 -> 3000 | J5: ='🔧 Active Scenario'!$B$30 -> 3000 | K5: ='🔧 Active Scenario'!$B$30 -> 3000 | ... N5: ='🔧 Active Scenario'!$B$30 -> 3000 | O5: ='🔧 Active Scenario'!$B$31 -> 3500 | P5: ='🔧 Active Scenario'!$B$31 -> 3500 | Q5: ='🔧 Active Scenario'!$B$31 -> 3500 | R5: ='🔧 Active Scenario'!$B$31 -> 3500 | S5: ='🔧 Active Scenario'!$B$31 -> 3500 | T5: ='🔧 Active Scenario'!$B$31 -> 3500 | U5: ='🔧 Active Scenario'!$B$31 -> 3500 | V5: ='🔧 Active Scenario'!$B$31 -> 3500 | ... Z5: ='🔧 Active Scenario'!$B$31 -> 3500
A6: Essencial · Subscribers | B6: sub. | C6: =ROUND(C5*'🔧 Active Scenario'!$B$32,0) -> 200 | D6: =ROUND(C6*(1-'🔧 Active Scenario'!$B$35)+D5*'🔧 Active Scenario'!$B$32,0) -> 484 | E6: =ROUND(D6*(1-'🔧 Active Scenario'!$B$35)+E5*'🔧 Active Scenario'!$B$32,0) -> 745 | F6: =ROUND(E6*(1-'🔧 Active Scenario'!$B$35)+F5*'🔧 Active Scenario'!$B$32,0) -> 985 | G6: =ROUND(F6*(1-'🔧 Active Scenario'!$B$35)+G5*'🔧 Active Scenario'!$B$32,0) -> 1206 | H6: =ROUND(G6*(1-'🔧 Active Scenario'!$B$35)+H5*'🔧 Active Scenario'!$B$32,0) -> 1410 | I6: =ROUND(H6*(1-'🔧 Active Scenario'!$B$35)+I5*'🔧 Active Scenario'!$B$32,0) -> 1597 | J6: =ROUND(I6*(1-'🔧 Active Scenario'!$B$35)+J5*'🔧 Active Scenario'!$B$32,0) -> 1769 | K6: =ROUND(J6*(1-'🔧 Active Scenario'!$B$35)+K5*'🔧 Active Scenario'!$B$32,0) -> 1927 | ... Z6: =ROUND(Y6*(1-'🔧 Active Scenario'!$B$35)+Z5*'🔧 Active Scenario'!$B$32,0) -> 3622
A7: Autônoma · Subscribers | B7: sub. | C7: =ROUND(C5*'🔧 Active Scenario'!$B$33,0) -> 140 | D7: =ROUND(C7*(1-'🔧 Active Scenario'!$B$36)+D5*'🔧 Active Scenario'!$B$33,0) -> 343 | E7: =ROUND(D7*(1-'🔧 Active Scenario'!$B$36)+E5*'🔧 Active Scenario'!$B$33,0) -> 536 | F7: =ROUND(E7*(1-'🔧 Active Scenario'!$B$36)+F5*'🔧 Active Scenario'!$B$33,0) -> 719 | G7: =ROUND(F7*(1-'🔧 Active Scenario'!$B$36)+G5*'🔧 Active Scenario'!$B$33,0) -> 893 | H7: =ROUND(G7*(1-'🔧 Active Scenario'!$B$36)+H5*'🔧 Active Scenario'!$B$33,0) -> 1058 | I7: =ROUND(H7*(1-'🔧 Active Scenario'!$B$36)+I5*'🔧 Active Scenario'!$B$33,0) -> 1215 | J7: =ROUND(I7*(1-'🔧 Active Scenario'!$B$36)+J5*'🔧 Active Scenario'!$B$33,0) -> 1364 | K7: =ROUND(J7*(1-'🔧 Active Scenario'!$B$36)+K5*'🔧 Active Scenario'!$B$33,0) -> 1506 | ... Z7: =ROUND(Y7*(1-'🔧 Active Scenario'!$B$36)+Z5*'🔧 Active Scenario'!$B$33,0) -> 3275
A8: Livre · Subscribers | B8: sub. | C8: =ROUND(C5*'🔧 Active Scenario'!$B$34,0) -> 40 | D8: =ROUND(C8*(1-'🔧 Active Scenario'!$B$37)+D5*'🔧 Active Scenario'!$B$34,0) -> 99 | E8: =ROUND(D8*(1-'🔧 Active Scenario'!$B$37)+E5*'🔧 Active Scenario'!$B$34,0) -> 156 | F8: =ROUND(E8*(1-'🔧 Active Scenario'!$B$37)+F5*'🔧 Active Scenario'!$B$34,0) -> 211 | G8: =ROUND(F8*(1-'🔧 Active Scenario'!$B$37)+G5*'🔧 Active Scenario'!$B$34,0) -> 265 | H8: =ROUND(G8*(1-'🔧 Active Scenario'!$B$37)+H5*'🔧 Active Scenario'!$B$34,0) -> 317 | I8: =ROUND(H8*(1-'🔧 Active Scenario'!$B$37)+I5*'🔧 Active Scenario'!$B$34,0) -> 367 | J8: =ROUND(I8*(1-'🔧 Active Scenario'!$B$37)+J5*'🔧 Active Scenario'!$B$34,0) -> 416 | K8: =ROUND(J8*(1-'🔧 Active Scenario'!$B$37)+K5*'🔧 Active Scenario'!$B$34,0) -> 464 | ... Z8: =ROUND(Y8*(1-'🔧 Active Scenario'!$B$37)+Z5*'🔧 Active Scenario'!$B$34,0) -> 1130
A9: TOTAL PAYING | B9: sub. | C9: =SUM(C6:C8) -> 380 | D9: =SUM(D6:D8) -> 926 | E9: =SUM(E6:E8) -> 1437 | F9: =SUM(F6:F8) -> 1915 | G9: =SUM(G6:G8) -> 2364 | H9: =SUM(H6:H8) -> 2785 | I9: =SUM(I6:I8) -> 3179 | J9: =SUM(J6:J8) -> 3549 | ... Z9: =SUM(Z6:Z8) -> 8027
A10: REVENUE
A11: MONTHLY MRR | B11: R$ | C11: =C6*('🔧 Active Scenario'!$B$6+'🔧 Active Scenario'!$B$9)+C7*'🔧 Active Scenario'!$B$7+C8*'🔧 Active Scenario'!$B$8 -> 21562 | D11: =D6*('🔧 Active Scenario'!$B$6+'🔧 Active Scenario'!$B$9)+D7*'🔧 Active Scenario'!$B$7+D8*'🔧 Active Scenario'!$B$8 -> 52607.4 | E11: =E6*('🔧 Active Scenario'!$B$6+'🔧 Active Scenario'!$B$9)+E7*'🔧 Active Scenario'!$B$7+E8*'🔧 Active Scenario'!$B$8 -> 81746.3 | F11: =F6*('🔧 Active Scenario'!$B$6+'🔧 Active Scenario'!$B$9)+F7*'🔧 Active Scenario'!$B$7+F8*'🔧 Active Scenario'!$B$8 -> 109078.5 | G11: =G6*('🔧 Active Scenario'!$B$6+'🔧 Active Scenario'!$B$9)+G7*'🔧 Active Scenario'!$B$7+G8*'🔧 Active Scenario'!$B$8 -> 134843.6 | H11: =H6*('🔧 Active Scenario'!$B$6+'🔧 Active Scenario'!$B$9)+H7*'🔧 Active Scenario'!$B$7+H8*'🔧 Active Scenario'!$B$8 -> 159061.5 | I11: =I6*('🔧 Active Scenario'!$B$6+'🔧 Active Scenario'!$B$9)+I7*'🔧 Active Scenario'!$B$7+I8*'🔧 Active Scenario'!$B$8 -> 181792.1 | J11: =J6*('🔧 Active Scenario'!$B$6+'🔧 Active Scenario'!$B$9)+J7*'🔧 Active Scenario'!$B$7+J8*'🔧 Active Scenario'!$B$8 -> 203215.1 | ... Z11: =Z6*('🔧 Active Scenario'!$B$6+'🔧 Active Scenario'!$B$9)+Z7*'🔧 Active Scenario'!$B$7+Z8*'🔧 Active Scenario'!$B$8 -> 467197.3
A12: CUMULATIVE MRR | B12: R$ | C12: =C11 -> 21562 | D12: =C12+D11 -> 74169.4 | E12: =D12+E11 -> 155915.7 | F12: =E12+F11 -> 264994.2 | G12: =F12+G11 -> 399837.8 | H12: =G12+H11 -> 558899.3 | I12: =H12+I11 -> 740691.4 | J12: =I12+J11 -> 943906.5 | K12: =J12+K11 -> 1167346.8 | ... Z12: =Y12+Z11 -> 6638262.2
A13: API COST · 100% Sonnet 4.6 · Caching active
A14: API Free (Haiku · 40 int/month) | B14: R$ | C14: =C5*'🔧 Active Scenario'!$B$21*('🔧 Active Scenario'!$B$18*('🔧 Active Scenario'!$B$19/1000000*'🔧 Active Scenario'!$B$14+'🔧 Active Scenario'!$B$20/1000000*'🔧 Active Scenario'!$B$15)*(1-'🔧 Active Scenario'!$B$16)*'🔧 Active Scenario'!$B$11) -> 542.5875 | D14: =D5*'🔧 Active Scenario'!$B$21*('🔧 Active Scenario'!$B$18*('🔧 Active Scenario'!$B$19/1000000*'🔧 Active Scenario'!$B$14+'🔧 Active Scenario'!$B$20/1000000*'🔧 Active Scenario'!$B$15)*(1-'🔧 Active Scenario'!$B$16)*'🔧 Active Scenario'!$B$11) -> 813.88125 | E14: =E5*'🔧 Active Scenario'!$B$21*('🔧 Active Scenario'!$B$18*('🔧 Active Scenario'!$B$19/1000000*'🔧 Active Scenario'!$B$14+'🔧 Active Scenario'!$B$20/1000000*'🔧 Active Scenario'!$B$15)*(1-'🔧 Active Scenario'!$B$16)*'🔧 Active Scenario'!$B$11) -> 813.88125 | F14: =F5*'🔧 Active Scenario'!$B$21*('🔧 Active Scenario'!$B$18*('🔧 Active Scenario'!$B$19/1000000*'🔧 Active Scenario'!$B$14+'🔧 Active Scenario'!$B$20/1000000*'🔧 Active Scenario'!$B$15)*(1-'🔧 Active Scenario'!$B$16)*'🔧 Active Scenario'!$B$11) -> 813.88125 | G14: =G5*'🔧 Active Scenario'!$B$21*('🔧 Active Scenario'!$B$18*('🔧 Active Scenario'!$B$19/1000000*'🔧 Active Scenario'!$B$14+'🔧 Active Scenario'!$B$20/1000000*'🔧 Active Scenario'!$B$15)*(1-'🔧 Active Scenario'!$B$16)*'🔧 Active Scenario'!$B$11) -> 813.88125 | H14: =H5*'🔧 Active Scenario'!$B$21*('🔧 Active Scenario'!$B$18*('🔧 Active Scenario'!$B$19/1000000*'🔧 Active Scenario'!$B$14+'🔧 Active Scenario'!$B$20/1000000*'🔧 Active Scenario'!$B$15)*(1-'🔧 Active Scenario'!$B$16)*'🔧 Active Scenario'!$B$11) -> 813.88125 | I14: =I5*'🔧 Active Scenario'!$B$21*('🔧 Active Scenario'!$B$18*('🔧 Active Scenario'!$B$19/1000000*'🔧 Active Scenario'!$B$14+'🔧 Active Scenario'!$B$20/1000000*'🔧 Active Scenario'!$B$15)*(1-'🔧 Active Scenario'!$B$16)*'🔧 Active Scenario'!$B$11) -> 813.88125 | J14: =J5*'🔧 Active Scenario'!$B$21*('🔧 Active Scenario'!$B$18*('🔧 Active Scenario'!$B$19/1000000*'🔧 Active Scenario'!$B$14+'🔧 Active Scenario'!$B$20/1000000*'🔧 Active Scenario'!$B$15)*(1-'🔧 Active Scenario'!$B$16)*'🔧 Active Scenario'!$B$11) -> 813.88125 | ... Z14: =Z5*'🔧 Active Scenario'!$B$21*('🔧 Active Scenario'!$B$18*('🔧 Active Scenario'!$B$19/1000000*'🔧 Active Scenario'!$B$14+'🔧 Active Scenario'!$B$20/1000000*'🔧 Active Scenario'!$B$15)*(1-'🔧 Active Scenario'!$B$16)*'🔧 Active Scenario'!$B$11) -> 949.52813
