Workbook

Sheet 🚀 Dashboard Investidor
A2: AUTONOMA · DASHBOARD
A3: Asset Light SaaS · Brasil → LATAM · Sonnet 4.6 (pagos) + Haiku 4.5 (Free) · Projeto de 24 meses com valuation M24
A5: CENÁRIO ATIVO: | B5: ='🔧 Cenário Ativo'!B2 -> Conservador | C5: ← altere em '🔧 Cenário Ativo'!B2 · Opções: Conservador / Base / Otimista
A7: PAYBACK CAC | C7: VALUATION M24 | E7: RECEITA ACUM 24m | G7: BREAKEVEN | I7: RETORNO ANJO
A8: ='🔧 Cenário Ativo'!B54*30 -> 70.441014 | C8: =IF('🔧 Cenário Ativo'!B2="Conservador",'📊 Resumo Cenários'!B21,IF('🔧 Cenário Ativo'!B2="Base",'📊 Resumo Cenários'!C21,'📊 Resumo Cenários'!D21)) -> 27698813 | E8: =IF('🔧 Cenário Ativo'!B2="Conservador",'📊 Resumo Cenários'!B19,IF('🔧 Cenário Ativo'!B2="Base",'📊 Resumo Cenários'!C19,'📊 Resumo Cenários'!D19)) -> 9232937.7 | G8: {=IFERROR("M"&MATCH(TRUE,INDEX('📊 Base Mensal'!C25:Z25>0,0),0),">24m")} -> M10 | I8: =C8*'🎛️ Premissas'!$B$56 -> 4154822
A9: tempo p/ recuperar CAC (dias) | C9: Receita acum 24m × múltiplo cenário | E9: soma MRR M1–M24 | G9: resultado acum. > 0 | I9: valor da fatia % sobre aporte
A11: FLUXO DE CAIXA ACUMULADO | F11: BREAKEVEN
A29: MRR & ASSINANTES | F29: VALUATION 3 CENARIOS
A47: UNIT ECONOMICS · CENARIO ATIVO
A49: CAC | C49: LTV Essencial | E49: LTV / CAC | G49: CHURN MENSAL | I49: MARGEM M24
A50: ='🔧 Cenário Ativo'!B44 -> 80 | C50: ='🔧 Cenário Ativo'!B52 -> 425.88825 | E50: ='🔧 Cenário Ativo'!B53 -> 5.3236031 | G50: ='🔧 Cenário Ativo'!B32 -> 0.08 | I50: ='📊 Base Mensal'!Z26 -> 0.8315493
A51: full-loaded | C51: margem × vida média | E51: =IF(E50>=8,"✅ top quartile",IF(E50>=3,"✅ saudável","⚠️ rever CAC")) -> ✅ saudável | G51: anual ~46% | I51: bruta sobre MRR
A52: Obs.: Este estudo não configura convite ou promessa de investimento. Valores projetados com base em premissas controláveis em 🎛️ Premissas e 🔧 Cenário Ativo.
A53: AutoNoma © 2025 · Dashboard dinâmico · Todos os valores recalculam ao mudar o cenário em '🔧 Cenário Ativo'!B2
L76: Mês | M76: MRR | N76: Pagantes | O76: Free | P76: Resultado | Q76: Acumulado | R76: Essencial | S76: Autônoma | T76: Livre | U76: API Total | V76: Custo Fixo | W76: Margem%
L77: M01 | M77: ='📊 Base Mensal'!C11 -> 16167 | N77: ='📊 Base Mensal'!C9 -> 330 | O77: ='📊 Base Mensal'!C5 -> 3000 | P77: ='📊 Base Mensal'!C24 -> -44124.37 | Q77: ='📊 Base Mensal'!C25 -> -44124.37 | R77: ='📊 Base Mensal'!C6 -> 210 | S77: ='📊 Base Mensal'!C7 -> 90 | T77: ='📊 Base Mensal'!C8 -> 30 | U77: ='📊 Base Mensal'!C18 -> 3351.3305 | V77: ='📊 Base Mensal'!C20 -> 55000 | W77: ='📊 Base Mensal'!C26 -> 0.79270548
L78: M02 | M78: ='📊 Base Mensal'!D11 -> 32334 | N78: ='📊 Base Mensal'!D9 -> 660 | O78: ='📊 Base Mensal'!D5 -> 6000 | P78: ='📊 Base Mensal'!D24 -> -33248.741 | Q78: ='📊 Base Mensal'!D25 -> -77373.111 | R78: ='📊 Base Mensal'!D6 -> 420 | S78: ='📊 Base Mensal'!D7 -> 180 | T78: ='📊 Base Mensal'!D8 -> 60 | U78: ='📊 Base Mensal'!D18 -> 6702.6609 | V78: ='📊 Base Mensal'!D20 -> 55000 | W78: ='📊 Base Mensal'!D26 -> 0.79270548
L79: M03 | M79: ='📊 Base Mensal'!E11 -> 48501 | N79: ='📊 Base Mensal'!E9 -> 990 | O79: ='📊 Base Mensal'!E5 -> 9000 | P79: ='📊 Base Mensal'!E24 -> -22373.111 | Q79: ='📊 Base Mensal'!E25 -> -99746.223 | R79: ='📊 Base Mensal'!E6 -> 630 | S79: ='📊 Base Mensal'!E7 -> 270 | T79: ='📊 Base Mensal'!E8 -> 90 | U79: ='📊 Base Mensal'!E18 -> 10053.991 | V79: ='📊 Base Mensal'!E20 -> 55000 | W79: ='📊 Base Mensal'!E26 -> 0.79270548
L80: M04 | M80: ='📊 Base Mensal'!F11 -> 64668 | N80: ='📊 Base Mensal'!F9 -> 1320 | O80: ='📊 Base Mensal'!F5 -> 12000 | P80: ='📊 Base Mensal'!F24 -> -11497.482 | Q80: ='📊 Base Mensal'!F25 -> -111243.7 | R80: ='📊 Base Mensal'!F6 -> 840 | S80: ='📊 Base Mensal'!F7 -> 360 | T80: ='📊 Base Mensal'!F8 -> 120 | U80: ='📊 Base Mensal'!F18 -> 13405.322 | V80: ='📊 Base Mensal'!F20 -> 55000 | W80: ='📊 Base Mensal'!F26 -> 0.79270548
L81: M05 | M81: ='📊 Base Mensal'!G11 -> 80835 | N81: ='📊 Base Mensal'!G9 -> 1650 | O81: ='📊 Base Mensal'!G5 -> 15000 | P81: ='📊 Base Mensal'!G24 -> -621.85225 | Q81: ='📊 Base Mensal'!G25 -> -111865.56 | R81: ='📊 Base Mensal'!G6 -> 1050 | S81: ='📊 Base Mensal'!G7 -> 450 | T81: ='📊 Base Mensal'!G8 -> 150 | U81: ='📊 Base Mensal'!G18 -> 16756.652 | V81: ='📊 Base Mensal'!G20 -> 55000 | W81: ='📊 Base Mensal'!G26 -> 0.79270548
L82: M06 | M82: ='📊 Base Mensal'!H11 -> 97002 | N82: ='📊 Base Mensal'!H9 -> 1980 | O82: ='📊 Base Mensal'!H5 -> 18000 | P82: ='📊 Base Mensal'!H24 -> 10253.777 | Q82: ='📊 Base Mensal'!H25 -> -101611.78 | R82: ='📊 Base Mensal'!H6 -> 1260 | S82: ='📊 Base Mensal'!H7 -> 540 | T82: ='📊 Base Mensal'!H8 -> 180 | U82: ='📊 Base Mensal'!H18 -> 20107.983 | V82: ='📊 Base Mensal'!H20 -> 55000 | W82: ='📊 Base Mensal'!H26 -> 0.79270548
L83: M07 | M83: ='📊 Base Mensal'!I11 -> 113169 | N83: ='📊 Base Mensal'!I9 -> 2310 | O83: ='📊 Base Mensal'!I5 -> 21000 | P83: ='📊 Base Mensal'!I24 -> 21129.407 | Q83: ='📊 Base Mensal'!I25 -> -80482.373 | R83: ='📊 Base Mensal'!I6 -> 1470 | S83: ='📊 Base Mensal'!I7 -> 630 | T83: ='📊 Base Mensal'!I8 -> 210 | U83: ='📊 Base Mensal'!I18 -> 23459.313 | V83: ='📊 Base Mensal'!I20 -> 55000 | W83: ='📊 Base Mensal'!I26 -> 0.79270548
L84: M08 | M84: ='📊 Base Mensal'!J11 -> 129336 | N84: ='📊 Base Mensal'!J9 -> 2640 | O84: ='📊 Base Mensal'!J5 -> 24000 | P84: ='📊 Base Mensal'!J24 -> 32005.036 | Q84: ='📊 Base Mensal'!J25 -> -48477.336 | R84: ='📊 Base Mensal'!J6 -> 1680 | S84: ='📊 Base Mensal'!J7 -> 720 | T84: ='📊 Base Mensal'!J8 -> 240 | U84: ='📊 Base Mensal'!J18 -> 26810.644 | V84: ='📊 Base Mensal'!J20 -> 55000 | W84: ='📊 Base Mensal'!J26 -> 0.79270548
L85: M09 | M85: ='📊 Base Mensal'!K11 -> 145503 | N85: ='📊 Base Mensal'!K9 -> 2970 | O85: ='📊 Base Mensal'!K5 -> 27000 | P85: ='📊 Base Mensal'!K24 -> 42880.666 | Q85: ='📊 Base Mensal'!K25 -> -5596.6703 | R85: ='📊 Base Mensal'!K6 -> 1890 | S85: ='📊 Base Mensal'!K7 -> 810 | T85: ='📊 Base Mensal'!K8 -> 270 | U85: ='📊 Base Mensal'!K18 -> 30161.974 | V85: ='📊 Base Mensal'!K20 -> 55000 | W85: ='📊 Base Mensal'!K26 -> 0.79270548
L86: M10 | M86: ='📊 Base Mensal'!L11 -> 161670 | N86: ='📊 Base Mensal'!L9 -> 3300 | O86: ='📊 Base Mensal'!L5 -> 30000 | P86: ='📊 Base Mensal'!L24 -> 53756.296 | Q86: ='📊 Base Mensal'!L25 -> 48159.625 | R86: ='📊 Base Mensal'!L6 -> 2100 | S86: ='📊 Base Mensal'!L7 -> 900 | T86: ='📊 Base Mensal'!L8 -> 300 | U86: ='📊 Base Mensal'!L18 -> 33513.305 | V86: ='📊 Base Mensal'!L20 -> 55000 | W86: ='📊 Base Mensal'!L26 -> 0.79270548
L87: M11 | M87: ='📊 Base Mensal'!M11 -> 177837 | N87: ='📊 Base Mensal'!M9 -> 3630 | O87: ='📊 Base Mensal'!M5 -> 33000 | P87: ='📊 Base Mensal'!M24 -> 64631.925 | Q87: ='📊 Base Mensal'!M25 -> 112791.55 | R87: ='📊 Base Mensal'!M6 -> 2310 | S87: ='📊 Base Mensal'!M7 -> 990 | T87: ='📊 Base Mensal'!M8 -> 330 | U87: ='📊 Base Mensal'!M18 -> 36864.635 | V87: ='📊 Base Mensal'!M20 -> 55000 | W87: ='📊 Base Mensal'!M26 -> 0.79270548
L88: M12 | M88: ='📊 Base Mensal'!N11 -> 194004 | N88: ='📊 Base Mensal'!N9 -> 3960 | O88: ='📊 Base Mensal'!N5 -> 36000 | P88: ='📊 Base Mensal'!N24 -> 75507.555 | Q88: ='📊 Base Mensal'!N25 -> 188299.1 | R88: ='📊 Base Mensal'!N6 -> 2520 | S88: ='📊 Base Mensal'!N7 -> 1080 | T88: ='📊 Base Mensal'!N8 -> 360 | U88: ='📊 Base Mensal'!N18 -> 40215.965 | V88: ='📊 Base Mensal'!N20 -> 55000 | W88: ='📊 Base Mensal'!N26 -> 0.79270548
L89: M13 | M89: ='📊 Base Mensal'!O11 -> 212865.5 | N89: ='📊 Base Mensal'!O9 -> 4345 | O89: ='📊 Base Mensal'!O5 -> 39500 | P89: ='📊 Base Mensal'!O24 -> 73195.789 | Q89: ='📊 Base Mensal'!O25 -> 261494.89 | R89: ='📊 Base Mensal'!O6 -> 2765 | S89: ='📊 Base Mensal'!O7 -> 1185 | T89: ='📊 Base Mensal'!O8 -> 395 | U89: ='📊 Base Mensal'!O18 -> 44125.851 | V89: ='📊 Base Mensal'!O20 -> 70000 | W89: ='📊 Base Mensal'!O26 -> 0.79270548
L90: M14 | M90: ='📊 Base Mensal'!P11 -> 231727 | N90: ='📊 Base Mensal'!P9 -> 4730 | O90: ='📊 Base Mensal'!P5 -> 43000 | P90: ='📊 Base Mensal'!P24 -> 85884.024 | Q90: ='📊 Base Mensal'!P25 -> 347378.92 | R90: ='📊 Base Mensal'!P6 -> 3010 | S90: ='📊 Base Mensal'!P7 -> 1290 | T90: ='📊 Base Mensal'!P8 -> 430 | U90: ='📊 Base Mensal'!P18 -> 48035.736 | V90: ='📊 Base Mensal'!P20 -> 70000 | W90: ='📊 Base Mensal'!P26 -> 0.79270548
L91: M15 | M91: ='📊 Base Mensal'!Q11 -> 250588.5 | N91: ='📊 Base Mensal'!Q9 -> 5115 | O91: ='📊 Base Mensal'!Q5 -> 46500 | P91: ='📊 Base Mensal'!Q24 -> 98572.258 | Q91: ='📊 Base Mensal'!Q25 -> 445951.18 | R91: ='📊 Base Mensal'!Q6 -> 3255 | S91: ='📊 Base Mensal'!Q7 -> 1395 | T91: ='📊 Base Mensal'!Q8 -> 465 | U91: ='📊 Base Mensal'!Q18 -> 51945.622 | V91: ='📊 Base Mensal'!Q20 -> 70000 | W91: ='📊 Base Mensal'!Q26 -> 0.79270548
L92: M16 | M92: ='📊 Base Mensal'!R11 -> 368794.8 | N92: ='📊 Base Mensal'!R9 -> 8052 | O92: ='📊 Base Mensal'!R5 -> 50000 | P92: ='📊 Base Mensal'!R24 -> 184298.34 | Q92: ='📊 Base Mensal'!R25 -> 630249.52 | R92: ='📊 Base Mensal'!R6 -> 6137 | S92: ='📊 Base Mensal'!R7 -> 1454 | T92: ='📊 Base Mensal'!R8 -> 461 | U92: ='📊 Base Mensal'!R18 -> 70241.083 | V92: ='📊 Base Mensal'!R20 -> 70000 | W92: ='📊 Base Mensal'!R26 -> 0.80953885
L93: M17 | M93: ='📊 Base Mensal'!S11 -> 483972.6 | N93: ='📊 Base Mensal'!S9 -> 10874 | O93: ='📊 Base Mensal'!S5 -> 53500 | P93: ='📊 Base Mensal'!S24 -> 267692.34 | Q93: ='📊 Base Mensal'!S25 -> 897941.85 | R93: ='📊 Base Mensal'!S6 -> 8827 | S93: ='📊 Base Mensal'!S7 -> 1589 | T93: ='📊 Base Mensal'!S8 -> 458 | U93: ='📊 Base Mensal'!S18 -> 88203.551 | V93: ='📊 Base Mensal'!S20 -> 70000 | W93: ='📊 Base Mensal'!S26 -> 0.81775094
L94: M18 | M94: ='📊 Base Mensal'!T11 -> 596620.3 | N94: ='📊 Base Mensal'!T9 -> 13597 | O94: ='📊 Base Mensal'!T5 -> 57000 | P94: ='📊 Base Mensal'!T24 -> 349132.44 | Q94: ='📊 Base Mensal'!T25 -> 1247074.3 | R94: ='📊 Base Mensal'!T6 -> 11350 | S94: ='📊 Base Mensal'!T7 -> 1789 | T94: ='📊 Base Mensal'!T8 -> 458 | U94: ='📊 Base Mensal'!T18 -> 105893.42 | V94: ='📊 Base Mensal'!T20 -> 70000 | W94: ='📊 Base Mensal'!T26 -> 0.8225112
L95: M19 | M95: ='📊 Base Mensal'!U11 -> 706817.1 | N95: ='📊 Base Mensal'!U9 -> 16229 | O95: ='📊 Base Mensal'!U5 -> 60500 | P95: ='📊 Base Mensal'!U24 -> 428692.57 | Q95: ='📊 Base Mensal'!U25 -> 1675766.9 | R95: ='📊 Base Mensal'!U6 -> 13725 | S95: ='📊 Base Mensal'!U7 -> 2044 | T95: ='📊 Base Mensal'!U8 -> 460 | U95: ='📊 Base Mensal'!U18 -> 123306.48 | V95: ='📊 Base Mensal'!U20 -> 70000 | W95: ='📊 Base Mensal'!U26 -> 0.82554683
L96: M20 | M96: ='📊 Base Mensal'!V11 -> 814921.8 | N96: ='📊 Base Mensal'!V9 -> 18782 | O96: ='📊 Base Mensal'!V5 -> 64000 | P96: ='📊 Base Mensal'!V24 -> 506645.79 | Q96: ='📊 Base Mensal'!V25 -> 2182412.7 | R96: ='📊 Base Mensal'!V6 -> 15971 | S96: ='📊 Base Mensal'!V7 -> 2346 | T96: ='📊 Base Mensal'!V8 -> 465 | U96: ='📊 Base Mensal'!V18 -> 140485.39 | V96: ='📊 Base Mensal'!V20 -> 70000 | W96: ='📊 Base Mensal'!V26 -> 0.82760875
L97: M21 | M97: ='📊 Base Mensal'!W11 -> 921093.6 | N97: ='📊 Base Mensal'!W9 -> 21264 | O97: ='📊 Base Mensal'!W5 -> 67500 | P97: ='📊 Base Mensal'!W24 -> 583120.31 | Q97: ='📊 Base Mensal'!W25 -> 2765533 | R97: ='📊 Base Mensal'!W6 -> 18104 | S97: ='📊 Base Mensal'!W7 -> 2687 | T97: ='📊 Base Mensal'!W8 -> 473 | U97: ='📊 Base Mensal'!W18 -> 157442.06 | V97: ='📊 Base Mensal'!W20 -> 70000 | W97: ='📊 Base Mensal'!W26 -> 0.82907051
L98: M22 | M98: ='📊 Base Mensal'!X11 -> 1025631.6 | N98: ='📊 Base Mensal'!X9 -> 23684 | O98: ='📊 Base Mensal'!X5 -> 71000 | P98: ='📊 Base Mensal'!X24 -> 658341.13 | Q98: ='📊 Base Mensal'!X25 -> 3423874.1 | R98: ='📊 Base Mensal'!X6 -> 20137 | S98: ='📊 Base Mensal'!X7 -> 3062 | T98: ='📊 Base Mensal'!X8 -> 485 | U98: ='📊 Base Mensal'!X18 -> 174214.68 | V98: ='📊 Base Mensal'!X20 -> 70000 | W98: ='📊 Base Mensal'!X26 -> 0.83013913
L99: M23 | M99: ='📊 Base Mensal'!Y11 -> 1128615.2 | N99: ='📊 Base Mensal'!Y9 -> 26048 | O99: ='📊 Base Mensal'!Y5 -> 74500 | P99: ='📊 Base Mensal'!Y24 -> 732376.64 | Q99: ='📊 Base Mensal'!Y25 -> 4156250.7 | R99: ='📊 Base Mensal'!Y6 -> 22083 | S99: ='📊 Base Mensal'!Y7 -> 3465 | T99: ='📊 Base Mensal'!Y8 -> 500 | U99: ='📊 Base Mensal'!Y18 -> 190804.74 | V99: ='📊 Base Mensal'!Y20 -> 70000 | W99: ='📊 Base Mensal'!Y26 -> 0.83093907
L100: M24 | M100: ='📊 Base Mensal'!Z11 -> 1230263.7 | N100: ='📊 Base Mensal'!Z9 -> 28363 | O100: ='📊 Base Mensal'!Z5 -> 78000 | P100: ='📊 Base Mensal'!Z24 -> 805393.27 | Q100: ='📊 Base Mensal'!Z25 -> 4961644 | R100: ='📊 Base Mensal'!Z6 -> 23953 | S100: ='📊 Base Mensal'!Z7 -> 3891 | T100: ='📊 Base Mensal'!Z8 -> 519 | U100: ='📊 Base Mensal'!Z18 -> 207238.78 | V100: ='📊 Base Mensal'!Z20 -> 70000 | W100: ='📊 Base Mensal'!Z26 -> 0.8315493
L102: Cenário | M102: Aporte R$1M | N102: Valuation 100% M24 | O102: ="Retorno Anjo ("&TEXT('🎛️ Premissas'!$B$56,"0%")&")" -> Retorno Anjo (15%)
...

Sheet 💎 Resumo Anjo
B2: AUTONOMA · RESUMO PARA INVESTIDOR ANJO
B3: Asset-Light SaaS · Brasil → LATAM · Sonnet 4.6 (planos pagos) + Haiku 4.5 (Free) · Horizonte 24 meses
B5: 1 · A OFERTA
B6: Aporte | C6: ='🎛️ Premissas'!B55 -> 1000000 | D6: ← entrada do anjo
B7: Equity oferecido | C7: ='🎛️ Premissas'!B56 -> 0.15 | D7: ← fatia adquirida
B8: Valuation post-money | C8: ='🎛️ Premissas'!B58 -> 6666666.7 | D8: = aporte ÷ equity
B9: Valuation pre-money | C9: ='🎛️ Premissas'!B57 -> 5666666.7
B11: 2 · MARCOS ATÉ A SÉRIE A (cenário Base)
B12: Indicador | C12: M12 | D12: M24
B13: Assinantes pagantes | C13: ='📊 Base Mensal'!N9 -> 3960 | D13: ='📊 Base Mensal'!Z9 -> 28363
B14: MRR (R$/mês) | C14: ='📊 Base Mensal'!N11 -> 194004 | D14: ='📊 Base Mensal'!Z11 -> 1230263.7
B15: Receita acumulada | C15: ='📊 Base Mensal'!N12 -> 1261026 | D15: ='📊 Base Mensal'!Z12 -> 9232937.7
B16: Margem bruta | C16: ='📊 Base Mensal'!N26 -> 0.79270548 | D16: ='📊 Base Mensal'!Z26 -> 0.8315493
B17: Resultado mensal | C17: ='📊 Base Mensal'!N24 -> 75507.555 | D17: ='📊 Base Mensal'!Z24 -> 805393.27
B19: 3 · RETORNO DO ANJO (fatia de 15%)
B20: Cenário | C20: Valuation M24 | D20: Valor da fatia 15% | E20: Múltiplo s/ aporte
B21: Conservador | C21: ='📊 Resumo Cenários'!B21 -> 27698813 | D21: =C21*'🎛️ Premissas'!$B$56 -> 4154822 | E21: =D21/'🎛️ Premissas'!$B$55 -> 4.154822
B22: Base | C22: ='📊 Resumo Cenários'!C21 -> 75044719 | D22: =C22*'🎛️ Premissas'!$B$56 -> 11256708 | E22: =D22/'🎛️ Premissas'!$B$55 -> 11.256708
B23: Otimista | C23: ='📊 Resumo Cenários'!D21 -> 1.4872558e+08 | D23: =C23*'🎛️ Premissas'!$B$56 -> 22308836 | E23: =D23/'🎛️ Premissas'!$B$55 -> 22.308836
B25: 4 · USO DO CAPITAL (R$1M · ~runway 18 meses)
B26: Produto & Engenharia (Sonnet/Haiku, dev) | C26: 0.4 | D26: =C26*'🎛️ Premissas'!$B$55 -> 400000
B27: Aquisição & Marketing (CAC, growth) | C27: 0.3 | D27: =C27*'🎛️ Premissas'!$B$55 -> 300000
B28: Equipe & Operação (CS, pró-labore) | C28: 0.2 | D28: =C28*'🎛️ Premissas'!$B$55 -> 200000
B29: Reserva & Jurídico/Contab. | C29: 0.1 | D29: =C29*'🎛️ Premissas'!$B$55 -> 100000
B30: Total | C30: =SUM(C26:C29) -> 1 | D30: =SUM(D26:D29) -> 1000000
B32: 5 · TESTE DE STRESS / DOWNSIDE (honestidade ao anjo)
B33: • Mesmo no cenário Conservador, o aporte retorna ~4,2× em 24 meses (fatia 15% = R$4,2M).
B34: • Churn diferenciado por plano: Essencial 8%, Autônoma 5%, Livre 3% — lock-in cresce com o agente.
B35: • Break-even de caixa no M6; margem bruta >80% sustentada por rodar o Free em Haiku (só custo).
B36: • Sensível a: CAC real (hoje R$60 full-loaded) e conversão Free→pago. Ambos controláveis em 🎛️ Premissas.
B37: • Próximo marco: Receita acum. R$15M no M24 sustenta conversão Série A a 5× receita (≈R$75M).
B39: Obs.: Este resumo não configura convite ou promessa de investimento. Todos os valores recalculam ao alterar o cenário em 🔧 Cenário Ativo e as premissas em 🎛️ Premissas. AutoNoma © 2025.
B42: 6 · SENSIBILIDADE: CHURN × LTV/CAC (plano Essencial, cenário Base)
B43: Churn/mês | C43: Vida média (m) | D43: LTV (R$) | E43: LTV / CAC | F43: Leitura
B44: 0.05 | C44: =1/B44 -> 20 | D44: ='📊 Resumo Cenários'!$C$13*C44 -> 867.1112 | E44: =D44/'🎛️ Premissas'!$C$45 -> 14.451853 | F44: =IF(E44>=8,"✅ top quartile",IF(E44>=3,"✅ saudável","⚠️ rever CAC")) -> ✅ top quartile
B45: 0.06 | C45: =1/B45 -> 16.666667 | D45: ='📊 Resumo Cenários'!$C$13*C45 -> 722.59267 | E45: =D45/'🎛️ Premissas'!$C$45 -> 12.043211 | F45: =IF(E45>=8,"✅ top quartile",IF(E45>=3,"✅ saudável","⚠️ rever CAC")) -> ✅ top quartile
B46: 0.07 | C46: =1/B46 -> 14.285714 | D46: ='📊 Resumo Cenários'!$C$13*C46 -> 619.36514 | E46: =D46/'🎛️ Premissas'!$C$45 -> 10.322752 | F46: =IF(E46>=8,"✅ top quartile",IF(E46>=3,"✅ saudável","⚠️ rever CAC")) -> ✅ top quartile
B47: 0.08 | C47: =1/B47 -> 12.5 | D47: ='📊 Resumo Cenários'!$C$13*C47 -> 541.9445 | E47: =D47/'🎛️ Premissas'!$C$45 -> 9.0324083 | F47: =IF(E47>=8,"✅ top quartile",IF(E47>=3,"✅ saudável","⚠️ rever CAC")) -> ✅ top quartile
B48: 0.1 | C48: =1/B48 -> 10 | D48: ='📊 Resumo Cenários'!$C$13*C48 -> 433.5556 | E48: =D48/'🎛️ Premissas'!$C$45 -> 7.2259267 | F48: =IF(E48>=8,"✅ top quartile",IF(E48>=3,"✅ saudável","⚠️ rever CAC")) -> ✅ saudável
B49: 0.12 | C49: =1/B49 -> 8.3333333 | D49: ='📊 Resumo Cenários'!$C$13*C49 -> 361.29633 | E49: =D49/'🎛️ Premissas'!$C$45 -> 6.0216056 | F49: =IF(E49>=8,"✅ top quartile",IF(E49>=3,"✅ saudável","⚠️ rever CAC")) -> ✅ saudável
...

Sheet 🔧 Cenário Ativo
A1: AutoNoma · Seletor de Cenário · Controler
A2: ▶ CENÁRIO ATIVO ◀ (altere aqui o modelo) | B2: Conservador | C2: ← Selecione: Conservador / Base / Otimista
A3: Coluna das premissas (uso interno — não edite) | B3: =MATCH(B2,{"Conservador","Base","Otimista"},0)+1 -> 2
A4: Premissas resolvidas para o cenário selecionado
A5: ── PREÇOS ──
A6: Preço Essencial | B6: =INDEX('🎛️ Premissas'!B5:D5,1,MATCH($B$2,{"Conservador","Base","Otimista"},0)) -> 39.9 | C6: ← Premissas!Preço Essencial (linha 5)
A7: Preço Autônoma | B7: =INDEX('🎛️ Premissas'!B6:D6,1,MATCH($B$2,{"Conservador","Base","Otimista"},0)) -> 59.9 | C7: ← Premissas!Preço Autônoma (linha 6)
A8: Preço Livre | B8: =INDEX('🎛️ Premissas'!B7:D7,1,MATCH($B$2,{"Conservador","Base","Otimista"},0)) -> 79.9 | C8: ← Premissas!Preço Livre (linha 7)
A9: ── API ──
A10: Câmbio USD/BRL | B10: =INDEX('🎛️ Premissas'!B9:D9,1,MATCH($B$2,{"Conservador","Base","Otimista"},0)) -> 5.3 | C10: ← Premissas!Câmbio USD/BRL (linha 9)
A11: Sonnet Input $/MTok | B11: =INDEX('🎛️ Premissas'!B10:D10,1,MATCH($B$2,{"Conservador","Base","Otimista"},0)) -> 3 | C11: ← Premissas!Sonnet 4.6 Input ($/MTok) (linha 10)
A12: Sonnet Output $/MTok | B12: =INDEX('🎛️ Premissas'!B11:D11,1,MATCH($B$2,{"Conservador","Base","Otimista"},0)) -> 15 | C12: ← Premissas!Sonnet 4.6 Output ($/MTok) (linha 11)
A13: Desconto Caching | B13: =INDEX('🎛️ Premissas'!B12:D12,1,MATCH($B$2,{"Conservador","Base","Otimista"},0)) -> 0.35 | C13: ← Premissas!Desconto Prompt Caching (%) (linha 12)
A14: ── USO ──
A15: Free: interações/mês | B15: =INDEX('🎛️ Premissas'!B14:D14,1,MATCH($B$2,{"Conservador","Base","Otimista"},0)) -> 50 | C15: ← Premissas!Free: interações/mês (LIMITE) (linha 14)
A16: Free: tokens input | B16: =INDEX('🎛️ Premissas'!B15:D15,1,MATCH($B$2,{"Conservador","Base","Otimista"},0)) -> 900 | C16: ← Premissas!Free: tokens input/interação (linha 15)
A17: Free: tokens output | B17: =INDEX('🎛️ Premissas'!B16:D16,1,MATCH($B$2,{"Conservador","Base","Otimista"},0)) -> 450 | C17: ← Premissas!Free: tokens output/interação (linha 16)
A18: Free: % ativas/mês | B18: =INDEX('🎛️ Premissas'!B17:D17,1,MATCH($B$2,{"Conservador","Base","Otimista"},0)) -> 0.5 | C18: ← Premissas!Free: % usuárias ativas/mês (linha 17)
A19: Essencial: interações/mês | B19: =INDEX('🎛️ Premissas'!B18:D18,1,MATCH($B$2,{"Conservador","Base","Otimista"},0)) -> 120 | C19: ← Premissas!Essencial: interações chat/mês (linha 18)
A20: Essencial: tokens input | B20: =INDEX('🎛️ Premissas'!B19:D19,1,MATCH($B$2,{"Conservador","Base","Otimista"},0)) -> 1200 | C20: ← Premissas!Essencial: tokens input/interação (linha 19)
A21: Essencial: tokens output | B21: =INDEX('🎛️ Premissas'!B20:D20,1,MATCH($B$2,{"Conservador","Base","Otimista"},0)) -> 700 | C21: ← Premissas!Essencial: tokens output/interação (linha 20)
A22: Autônoma: sessões agente/mês | B22: =INDEX('🎛️ Premissas'!B22:D22,1,MATCH($B$2,{"Conservador","Base","Otimista"},0)) -> 35 | C22: ← Premissas!Autônoma: sessões agente/mês (linha 22)
A23: Autônoma: tokens input/sessão | B23: =INDEX('🎛️ Premissas'!B23:D23,1,MATCH($B$2,{"Conservador","Base","Otimista"},0)) -> 3000 | C23: ← Premissas!Autônoma: tokens input/sessão agente (linha 23)
A24: Autônoma: tokens output/sessão | B24: =INDEX('🎛️ Premissas'!B24:D24,1,MATCH($B$2,{"Conservador","Base","Otimista"},0)) -> 1800 | C24: ← Premissas!Autônoma: tokens output/sessão agente (linha 24)
A25: Livre: sessões totais/mês | B25: =INDEX('🎛️ Premissas'!B26:D26,1,MATCH($B$2,{"Conservador","Base","Otimista"},0)) -> 60 | C25: ← Premissas!Livre: sessões totais agentes/mês (linha 26)
A26: ── CRESCIMENTO ──
A27: Free leads M1–12 | B27: =INDEX('🎛️ Premissas'!B28:D28,1,MATCH($B$2,{"Conservador","Base","Otimista"},0)) -> 3000 | C27: ← Premissas!Crescimento Free M1–12 (leads/mês) (linha 28)
A28: Free leads M13–24 | B28: =INDEX('🎛️ Premissas'!B29:D29,1,MATCH($B$2,{"Conservador","Base","Otimista"},0)) -> 3500 | C28: ← Premissas!Crescimento Free M13–24 (leads/mês) (linha 29)
A29: Conv. Free→Essencial | B29: =INDEX('🎛️ Premissas'!B30:D30,1,MATCH($B$2,{"Conservador","Base","Otimista"},0)) -> 0.07 | C29: ← Premissas!Conversão Free → Essencial (%) (linha 31)
A30: Conv. Free→Autônoma | B30: =INDEX('🎛️ Premissas'!B31:D31,1,MATCH($B$2,{"Conservador","Base","Otimista"},0)) -> 0.03 | C30: ← Premissas!Conversão Free → Autônoma (%) (linha 32)
A31: Conv. Free→Livre | B31: =INDEX('🎛️ Premissas'!B32:D32,1,MATCH($B$2,{"Conservador","Base","Otimista"},0)) -> 0.01 | C31: ← Premissas!Conversão Free → Livre (%) (linha 33)
A32: Churn Essencial/mês | B32: =INDEX('🎛️ Premissas'!B33:D33,1,MATCH($B$2,{"Conservador","Base","Otimista"},0)) -> 0.08 | C32: ← Premissas!Churn mensal Essencial (linha 34)
A33: Churn Autônoma/mês | B33: =INDEX('🎛️ Premissas'!B34:D34,1,MATCH($B$2,{"Conservador","Base","Otimista"},0)) -> 0.05 | C33: ← Premissas!Churn mensal Autônoma (linha 35)
A34: Churn Livre/mês | B34: =INDEX('🎛️ Premissas'!B35:D35,1,MATCH($B$2,{"Conservador","Base","Otimista"},0)) -> 0.03 | C34: ← Premissas!Churn mensal Livre (linha 36)
A35: ── CUSTO FIXO ──
A36: Equipe Ano 1 | B36: =INDEX('🎛️ Premissas'!B37:D37,1,MATCH($B$2,{"Conservador","Base","Otimista"},0)) -> 40000 | C36: ← Premissas!Equipe Ano 1 (média/mês) (linha 38)
A37: Equipe Ano 2 | B37: =INDEX('🎛️ Premissas'!B38:D38,1,MATCH($B$2,{"Conservador","Base","Otimista"},0)) -> 50000 | C37: ← Premissas!Equipe Ano 2 (média/mês) (linha 39)
A38: Infra Ano 1 | B38: =INDEX('🎛️ Premissas'!B39:D39,1,MATCH($B$2,{"Conservador","Base","Otimista"},0)) -> 5000 | C38: ← Premissas!Infraestrutura Ano 1 (linha 41)
A39: Infra Ano 2 | B39: =INDEX('🎛️ Premissas'!B40:D40,1,MATCH($B$2,{"Conservador","Base","Otimista"},0)) -> 7000 | C39: ← Premissas!Infraestrutura Ano 2 (linha 42)
A40: Marketing Ano 1 | B40: =INDEX('🎛️ Premissas'!B41:D41,1,MATCH($B$2,{"Conservador","Base","Otimista"},0)) -> 5000 | C40: ← Premissas!Marketing base Ano 1 (linha 44)
...

Sheet 🎛️ Premissas
A1: AutoNoma · Premissas · Fonte Única de Verdade · 100% Sonnet 4.6
A2: Azul = Input editável | B2: Preto = Fórmula | C2: Malva = Link cross-sheet
A3: PARAMETRO | B3: Conservador | C3: Base (padrão) | D3: Otimista | E3: UNIDADE/NOTA
A4: 1 · PREÇOS DOS PLANOS (R$/mês)
A5: Preço Essencial | B5: 39.9 | C5: 49.9 | D5: 49.9 | E5: R$/mês · + uso esporadico agente
A6: Preço Autônoma | B6: 59.9 | C6: 59.9 | D6: 62.9 | E6: R$/mês · chat + 1 agente
A7: Preço Livre | B7: 79.9 | C7: 79.9 | D7: 79.9 | E7: R$/mês · chat + 2 agentes
A8: 2 · CUSTO API ANTHROPIC (1 semestre 2026) | F8: 2b · CUSTO API HAIKU (plano Free)
A9: Câmbio USD/BRL | B9: 5.3 | C9: 5.3 | D9: 5.3 | E9: R$ por USD | F9: Haiku 4.5 Input ($/MTok) | G9: 1
A10: Sonnet 4.6 Input ($/MTok) | B10: 3 | C10: 3 | D10: 3 | E10: USD — oficial Anthropic | F10: Haiku 4.5 Output ($/MTok) | G10: 5
A11: Sonnet 4.6 Output ($/MTok) | B11: 15 | C11: 15 | D11: 15 | E11: USD — oficial Anthropic | F11: ← Free roda em Haiku (só custo)
A12: Desconto Prompt Caching (%) | B12: 0.35 | C12: 0.4 | D12: 0.45 | E12: % redução no bloco fixo
A13: 3 · USO POR PLANO — 100% SONNET 4.6
A14: Free: interações/mês (LIMITE) | B14: 50 | C14: 50 | D14: 50 | E14: Sonnet · teto produto
A15: Free: tokens input/interação | B15: 900 | C15: 900 | D15: 900 | E15: inclui system prompt cacheado
A16: Free: tokens output/interação | B16: 450 | C16: 450 | D16: 450 | E16: resposta orientada
A17: Free: % usuárias ativas/mês | B17: 0.5 | C17: 0.5 | D17: 0.5 | E17: % do cadastro que usa no mês
A18: Essencial: interações chat/mês | B18: 120 | C18: 140 | D18: 180 | E18: ilimitado prático · 20 dias × uso
A19: Essencial: tokens input/interação | B19: 1200 | C19: 1400 | D19: 1800 | E19: contexto Noma + memória
A20: Essencial: tokens output/interação | B20: 700 | C20: 700 | D20: 700 | E20: resposta + ação autônoma
A21: Autônoma: chat (= Essencial) | B21: 140 | C21: 140 | D21: 140 | E21: chat ilimitado Sonnet
A22: Autônoma: sessões agente/mês | B22: 35 | C22: 45 | D22: 60 | E22: sessões profundas com 1 agente
A23: Autônoma: tokens input/sessão agente | B23: 3000 | C23: 3000 | D23: 3000 | E23: contexto resolução + memória
A24: Autônoma: tokens output/sessão agente | B24: 1800 | C24: 1800 | D24: 1800 | E24: resolução completa + confirmação
A25: Livre: chat (= Essencial) | B25: 140 | C25: 140 | D25: 140 | E25: chat ilimitado Sonnet
A26: Livre: sessões totais agentes/mês | B26: 60 | C26: 80 | D26: 100 | E26: 2 agentes · mais que Autônoma
A27: 4 · CRESCIMENTO DA BASE
A28: Crescimento Free M1–12 (leads/mês) | B28: 3000 | C28: 3500 | D28: 4000 | E28: cadastros orgânicos+viral+paid
A29: Crescimento Free M13–24 (leads/mês) | B29: 3500 | C29: 4000 | D29: 4500 | E29: escala Brasil
A30: Conversão Free → Essencial (%) | B30: 0.07 | C30: 0.08 | D30: 0.1 | E30: % base Free que vira assinante
A31: Conversão Free → Autônoma (%) | B31: 0.03 | C31: 0.04 | D31: 0.05 | E31: % Essenciais que sobem
A32: Conversão Free → Livre (%) | B32: 0.01 | C32: 0.02 | D32: 0.03 | E32: % Autônomas que sobem
A33: Churn mensal Essencial | B33: 0.08 | C33: 0.08 | D33: 0.08 | E33: % cancela por mês
A34: Churn mensal Autônoma | B34: 0.05 | C34: 0.05 | D34: 0.05 | E34: % cancela por mês · agente = lock-in
A35: Churn mensal Livre | B35: 0.03 | C35: 0.03 | D35: 0.03 | E35: % cancela · 2 agentes = máximo lock-in
A36: 5 · CUSTO FIXO MENSAL (R$)
A37: Equipe Ano 1 (média/mês) | B37: 40000 | C37: 45000 | D37: 50000 | E37: devs+CS+pró-labore fundadores
A38: Equipe Ano 2 (média/mês) | B38: 50000 | C38: 60000 | D38: 70000 | E38: expansão de time
A39: Infraestrutura Ano 1 | B39: 5000 | C39: 6000 | D39: 8000 | E39: servidores, DB, CDN
A40: Infraestrutura Ano 2 | B40: 7000 | C40: 8000 | D40: 10000 | E40: escala com base
...

Sheet 📊 Base Mensal
A1: AutoNoma · Base Mensal · 24 Meses · Fórmulas Dinâmicas · Cenário Controlado por 🔧 Cenário Ativo
A2: Cenário ativo: | C2: ='🔧 Cenário Ativo'!B2 -> Conservador
A3: Indicador | B3: Unid. | C3: M01 | D3: M02 | E3: M03 | F3: M04 | G3: M05 | H3: M06 | I3: M07 | J3: M08 | K3: M09 | L3: M10 | M3: M11 | N3: M12 ★ | O3: M13 | P3: M14 | Q3: M15 | R3: M16 | S3: M17 | T3: M18 | U3: M19 | V3: M20 | W3: M21 | X3: M22 | Y3: M23 | Z3: M24 ★
A4: USUÁRIOS
A5: Free · Cadastros (Sonnet 40 int/mês) | B5: usr | C5: ='🎛️ Premissas'!B61 -> 3000 | D5: =C5+'🔧 Cenário Ativo'!$B$27 -> 6000 | E5: =D5+'🔧 Cenário Ativo'!$B$27 -> 9000 | F5: =E5+'🔧 Cenário Ativo'!$B$27 -> 12000 | G5: =F5+'🔧 Cenário Ativo'!$B$27 -> 15000 | H5: =G5+'🔧 Cenário Ativo'!$B$27 -> 18000 | I5: =H5+'🔧 Cenário Ativo'!$B$27 -> 21000 | J5: =I5+'🔧 Cenário Ativo'!$B$27 -> 24000 | K5: =J5+'🔧 Cenário Ativo'!$B$27 -> 27000 | ... N5: =M5+'🔧 Cenário Ativo'!$B$27 -> 36000 | O5: =N5+'🔧 Cenário Ativo'!$B$28 -> 39500 | P5: =O5+'🔧 Cenário Ativo'!$B$28 -> 43000 | Q5: =P5+'🔧 Cenário Ativo'!$B$28 -> 46500 | R5: =Q5+'🔧 Cenário Ativo'!$B$28 -> 50000 | S5: =R5+'🔧 Cenário Ativo'!$B$28 -> 53500 | T5: =S5+'🔧 Cenário Ativo'!$B$28 -> 57000 | U5: =T5+'🔧 Cenário Ativo'!$B$28 -> 60500 | V5: =U5+'🔧 Cenário Ativo'!$B$28 -> 64000 | ... Z5: =Y5+'🔧 Cenário Ativo'!$B$28 -> 78000
A6: Essencial · Assinantes | B6: ass. | C6: =ROUND(C5*'🔧 Cenário Ativo'!$B$29,0) -> 210 | D6: =ROUND(D5*'🔧 Cenário Ativo'!$B$29,0) -> 420 | E6: =ROUND(E5*'🔧 Cenário Ativo'!$B$29,0) -> 630 | F6: =ROUND(F5*'🔧 Cenário Ativo'!$B$29,0) -> 840 | G6: =ROUND(G5*'🔧 Cenário Ativo'!$B$29,0) -> 1050 | H6: =ROUND(H5*'🔧 Cenário Ativo'!$B$29,0) -> 1260 | I6: =ROUND(I5*'🔧 Cenário Ativo'!$B$29,0) -> 1470 | J6: =ROUND(J5*'🔧 Cenário Ativo'!$B$29,0) -> 1680 | ... Q6: =ROUND(Q5*'🔧 Cenário Ativo'!$B$29,0) -> 3255 | R6: =ROUND(Q6*(1-'🔧 Cenário Ativo'!B32)+MAX(0,R5-Q9)*'🔧 Cenário Ativo'!B29,0) -> 6137 | S6: =ROUND(R6*(1-'🔧 Cenário Ativo'!B32)+MAX(0,S5-R9)*'🔧 Cenário Ativo'!B29,0) -> 8827 | T6: =ROUND(S6*(1-'🔧 Cenário Ativo'!B32)+MAX(0,T5-S9)*'🔧 Cenário Ativo'!B29,0) -> 11350 | U6: =ROUND(T6*(1-'🔧 Cenário Ativo'!B32)+MAX(0,U5-T9)*'🔧 Cenário Ativo'!B29,0) -> 13725 | V6: =ROUND(U6*(1-'🔧 Cenário Ativo'!B32)+MAX(0,V5-U9)*'🔧 Cenário Ativo'!B29,0) -> 15971 | W6: =ROUND(V6*(1-'🔧 Cenário Ativo'!B32)+MAX(0,W5-V9)*'🔧 Cenário Ativo'!B29,0) -> 18104 | X6: =ROUND(W6*(1-'🔧 Cenário Ativo'!B32)+MAX(0,X5-W9)*'🔧 Cenário Ativo'!B29,0) -> 20137 | Y6: =ROUND(X6*(1-'🔧 Cenário Ativo'!B32)+MAX(0,Y5-X9)*'🔧 Cenário Ativo'!B29,0) -> 22083 | Z6: =ROUND(Y6*(1-'🔧 Cenário Ativo'!B32)+MAX(0,Z5-Y9)*'🔧 Cenário Ativo'!B29,0) -> 23953
A7: Autônoma · Assinantes | B7: ass. | C7: =ROUND(C5*'🔧 Cenário Ativo'!$B$30,0) -> 90 | D7: =ROUND(D5*'🔧 Cenário Ativo'!$B$30,0) -> 180 | E7: =ROUND(E5*'🔧 Cenário Ativo'!$B$30,0) -> 270 | F7: =ROUND(F5*'🔧 Cenário Ativo'!$B$30,0) -> 360 | G7: =ROUND(G5*'🔧 Cenário Ativo'!$B$30,0) -> 450 | H7: =ROUND(H5*'🔧 Cenário Ativo'!$B$30,0) -> 540 | I7: =ROUND(I5*'🔧 Cenário Ativo'!$B$30,0) -> 630 | J7: =ROUND(J5*'🔧 Cenário Ativo'!$B$30,0) -> 720 | ... Q7: =ROUND(Q5*'🔧 Cenário Ativo'!$B$30,0) -> 1395 | R7: =ROUND(Q7*(1-'🔧 Cenário Ativo'!B33)+MAX(0,R6-Q7-Q8)*'🔧 Cenário Ativo'!B30,0) -> 1454 | S7: =ROUND(R7*(1-'🔧 Cenário Ativo'!B33)+MAX(0,S6-R7-R8)*'🔧 Cenário Ativo'!B30,0) -> 1589 | T7: =ROUND(S7*(1-'🔧 Cenário Ativo'!B33)+MAX(0,T6-S7-S8)*'🔧 Cenário Ativo'!B30,0) -> 1789 | U7: =ROUND(T7*(1-'🔧 Cenário Ativo'!B33)+MAX(0,U6-T7-T8)*'🔧 Cenário Ativo'!B30,0) -> 2044 | V7: =ROUND(U7*(1-'🔧 Cenário Ativo'!B33)+MAX(0,V6-U7-U8)*'🔧 Cenário Ativo'!B30,0) -> 2346 | W7: =ROUND(V7*(1-'🔧 Cenário Ativo'!B33)+MAX(0,W6-V7-V8)*'🔧 Cenário Ativo'!B30,0) -> 2687 | X7: =ROUND(W7*(1-'🔧 Cenário Ativo'!B33)+MAX(0,X6-W7-W8)*'🔧 Cenário Ativo'!B30,0) -> 3062 | Y7: =ROUND(X7*(1-'🔧 Cenário Ativo'!B33)+MAX(0,Y6-X7-X8)*'🔧 Cenário Ativo'!B30,0) -> 3465 | Z7: =ROUND(Y7*(1-'🔧 Cenário Ativo'!B33)+MAX(0,Z6-Y7-Y8)*'🔧 Cenário Ativo'!B30,0) -> 3891
A8: Livre · Assinantes | B8: ass. | C8: =ROUND(C5*'🔧 Cenário Ativo'!$B$31,0) -> 30 | D8: =ROUND(D5*'🔧 Cenário Ativo'!$B$31,0) -> 60 | E8: =ROUND(E5*'🔧 Cenário Ativo'!$B$31,0) -> 90 | F8: =ROUND(F5*'🔧 Cenário Ativo'!$B$31,0) -> 120 | G8: =ROUND(G5*'🔧 Cenário Ativo'!$B$31,0) -> 150 | H8: =ROUND(H5*'🔧 Cenário Ativo'!$B$31,0) -> 180 | I8: =ROUND(I5*'🔧 Cenário Ativo'!$B$31,0) -> 210 | J8: =ROUND(J5*'🔧 Cenário Ativo'!$B$31,0) -> 240 | ... Q8: =ROUND(Q5*'🔧 Cenário Ativo'!$B$31,0) -> 465 | R8: =ROUND(Q8*(1-'🔧 Cenário Ativo'!B34)+MAX(0,R7-Q8)*'🔧 Cenário Ativo'!B31,0) -> 461 | S8: =ROUND(R8*(1-'🔧 Cenário Ativo'!B34)+MAX(0,S7-R8)*'🔧 Cenário Ativo'!B31,0) -> 458 | T8: =ROUND(S8*(1-'🔧 Cenário Ativo'!B34)+MAX(0,T7-S8)*'🔧 Cenário Ativo'!B31,0) -> 458 | U8: =ROUND(T8*(1-'🔧 Cenário Ativo'!B34)+MAX(0,U7-T8)*'🔧 Cenário Ativo'!B31,0) -> 460 | V8: =ROUND(U8*(1-'🔧 Cenário Ativo'!B34)+MAX(0,V7-U8)*'🔧 Cenário Ativo'!B31,0) -> 465 | W8: =ROUND(V8*(1-'🔧 Cenário Ativo'!B34)+MAX(0,W7-V8)*'🔧 Cenário Ativo'!B31,0) -> 473 | X8: =ROUND(W8*(1-'🔧 Cenário Ativo'!B34)+MAX(0,X7-W8)*'🔧 Cenário Ativo'!B31,0) -> 485 | Y8: =ROUND(X8*(1-'🔧 Cenário Ativo'!B34)+MAX(0,Y7-X8)*'🔧 Cenário Ativo'!B31,0) -> 500 | Z8: =ROUND(Y8*(1-'🔧 Cenário Ativo'!B34)+MAX(0,Z7-Y8)*'🔧 Cenário Ativo'!B31,0) -> 519
A9: TOTAL PAGANTES | B9: ass. | C9: =SUM(C6:C8) -> 330 | D9: =SUM(D6:D8) -> 660 | E9: =SUM(E6:E8) -> 990 | F9: =SUM(F6:F8) -> 1320 | G9: =SUM(G6:G8) -> 1650 | H9: =SUM(H6:H8) -> 1980 | I9: =SUM(I6:I8) -> 2310 | J9: =SUM(J6:J8) -> 2640 | ... Z9: =SUM(Z6:Z8) -> 28363
A10: RECEITA
A11: MRR MENSAL | B11: R$ | C11: =C6*'🔧 Cenário Ativo'!B6+C7*'🔧 Cenário Ativo'!B7+C8*'🔧 Cenário Ativo'!B8 -> 16167 | D11: =D6*'🔧 Cenário Ativo'!B6+D7*'🔧 Cenário Ativo'!B7+D8*'🔧 Cenário Ativo'!B8 -> 32334 | E11: =E6*'🔧 Cenário Ativo'!B6+E7*'🔧 Cenário Ativo'!B7+E8*'🔧 Cenário Ativo'!B8 -> 48501 | F11: =F6*'🔧 Cenário Ativo'!B6+F7*'🔧 Cenário Ativo'!B7+F8*'🔧 Cenário Ativo'!B8 -> 64668 | G11: =G6*'🔧 Cenário Ativo'!B6+G7*'🔧 Cenário Ativo'!B7+G8*'🔧 Cenário Ativo'!B8 -> 80835 | H11: =H6*'🔧 Cenário Ativo'!B6+H7*'🔧 Cenário Ativo'!B7+H8*'🔧 Cenário Ativo'!B8 -> 97002 | I11: =I6*'🔧 Cenário Ativo'!B6+I7*'🔧 Cenário Ativo'!B7+I8*'🔧 Cenário Ativo'!B8 -> 113169 | J11: =J6*'🔧 Cenário Ativo'!B6+J7*'🔧 Cenário Ativo'!B7+J8*'🔧 Cenário Ativo'!B8 -> 129336 | K11: =K6*'🔧 Cenário Ativo'!B6+K7*'🔧 Cenário Ativo'!B7+K8*'🔧 Cenário Ativo'!B8 -> 145503 | L11: =L6*'🔧 Cenário Ativo'!B6+L7*'🔧 Cenário Ativo'!B7+L8*'🔧 Cenário Ativo'!B8 -> 161670 | M11: =M6*'🔧 Cenário Ativo'!B6+M7*'🔧 Cenário Ativo'!B7+M8*'🔧 Cenário Ativo'!B8 -> 177837 | N11: =N6*'🔧 Cenário Ativo'!B6+N7*'🔧 Cenário Ativo'!B7+N8*'🔧 Cenário Ativo'!B8 -> 194004 | O11: =O6*'🔧 Cenário Ativo'!B6+O7*'🔧 Cenário Ativo'!B7+O8*'🔧 Cenário Ativo'!B8 -> 212865.5 | P11: =P6*'🔧 Cenário Ativo'!B6+P7*'🔧 Cenário Ativo'!B7+P8*'🔧 Cenário Ativo'!B8 -> 231727 | Q11: =Q6*'🔧 Cenário Ativo'!B6+Q7*'🔧 Cenário Ativo'!B7+Q8*'🔧 Cenário Ativo'!B8 -> 250588.5 | R11: =R6*'🔧 Cenário Ativo'!B6+R7*'🔧 Cenário Ativo'!B7+R8*'🔧 Cenário Ativo'!B8 -> 368794.8 | S11: =S6*'🔧 Cenário Ativo'!B6+S7*'🔧 Cenário Ativo'!B7+S8*'🔧 Cenário Ativo'!B8 -> 483972.6 | T11: =T6*'🔧 Cenário Ativo'!B6+T7*'🔧 Cenário Ativo'!B7+T8*'🔧 Cenário Ativo'!B8 -> 596620.3 | U11: =U6*'🔧 Cenário Ativo'!B6+U7*'🔧 Cenário Ativo'!B7+U8*'🔧 Cenário Ativo'!B8 -> 706817.1 | V11: =V6*'🔧 Cenário Ativo'!B6+V7*'🔧 Cenário Ativo'!B7+V8*'🔧 Cenário Ativo'!B8 -> 814921.8 | W11: =W6*'🔧 Cenário Ativo'!B6+W7*'🔧 Cenário Ativo'!B7+W8*'🔧 Cenário Ativo'!B8 -> 921093.6 | X11: =X6*'🔧 Cenário Ativo'!B6+X7*'🔧 Cenário Ativo'!B7+X8*'🔧 Cenário Ativo'!B8 -> 1025631.6 | Y11: =Y6*'🔧 Cenário Ativo'!B6+Y7*'🔧 Cenário Ativo'!B7+Y8*'🔧 Cenário Ativo'!B8 -> 1128615.2 | Z11: =Z6*'🔧 Cenário Ativo'!B6+Z7*'🔧 Cenário Ativo'!B7+Z8*'🔧 Cenário Ativo'!B8 -> 1230263.7
A12: MRR ACUMULADO | B12: R$ | C12: =C11 -> 16167 | D12: =C12+D11 -> 48501 | E12: =D12+E11 -> 97002 | F12: =E12+F11 -> 161670 | G12: =F12+G11 -> 242505 | H12: =G12+H11 -> 339507 | I12: =H12+I11 -> 452676 | J12: =I12+J11 -> 582012 | K12: =J12+K11 -> 727515 | ... Z12: =Y12+Z11 -> 9232937.7
A13: CUSTO API · 100% Sonnet 4.6 · Caching ativo
A14: API Free (Sonnet · 40 int/mês) | B14: R$ | C14: =C5*'🔧 Cenário Ativo'!$B$18*('🔧 Cenário Ativo'!$B$15*('🔧 Cenário Ativo'!$B$16/1000000*'🎛️ Premissas'!$G$9+'🔧 Cenário Ativo'!$B$17/1000000*'🎛️ Premissas'!$G$10)*(1-'🔧 Cenário Ativo'!$B$13)*'🔧 Cenário Ativo'!$B$10) -> 813.88125 | D14: =D5*'🔧 Cenário Ativo'!$B$18*('🔧 Cenário Ativo'!$B$15*('🔧 Cenário Ativo'!$B$16/1000000*'🎛️ Premissas'!$G$9+'🔧 Cenário Ativo'!$B$17/1000000*'🎛️ Premissas'!$G$10)*(1-'🔧 Cenário Ativo'!$B$13)*'🔧 Cenário Ativo'!$B$10) -> 1627.7625 | E14: =E5*'🔧 Cenário Ativo'!$B$18*('🔧 Cenário Ativo'!$B$15*('🔧 Cenário Ativo'!$B$16/1000000*'🎛️ Premissas'!$G$9+'🔧 Cenário Ativo'!$B$17/1000000*'🎛️ Premissas'!$G$10)*(1-'🔧 Cenário Ativo'!$B$13)*'🔧 Cenário Ativo'!$B$10) -> 2441.6438 | F14: =F5*'🔧 Cenário Ativo'!$B$18*('🔧 Cenário Ativo'!$B$15*('🔧 Cenário Ativo'!$B$16/1000000*'🎛️ Premissas'!$G$9+'🔧 Cenário Ativo'!$B$17/1000000*'🎛️ Premissas'!$G$10)*(1-'🔧 Cenário Ativo'!$B$13)*'🔧 Cenário Ativo'!$B$10) -> 3255.525 | G14: =G5*'🔧 Cenário Ativo'!$B$18*('🔧 Cenário Ativo'!$B$15*('🔧 Cenário Ativo'!$B$16/1000000*'🎛️ Premissas'!$G$9+'🔧 Cenário Ativo'!$B$17/1000000*'🎛️ Premissas'!$G$10)*(1-'🔧 Cenário Ativo'!$B$13)*'🔧 Cenário Ativo'!$B$10) -> 4069.4062 | H14: =H5*'🔧 Cenário Ativo'!$B$18*('🔧 Cenário Ativo'!$B$15*('🔧 Cenário Ativo'!$B$16/1000000*'🎛️ Premissas'!$G$9+'🔧 Cenário Ativo'!$B$17/1000000*'🎛️ Premissas'!$G$10)*(1-'🔧 Cenário Ativo'!$B$13)*'🔧 Cenário Ativo'!$B$10) -> 4883.2875 | I14: =I5*'🔧 Cenário Ativo'!$B$18*('🔧 Cenário Ativo'!$B$15*('🔧 Cenário Ativo'!$B$16/1000000*'🎛️ Premissas'!$G$9+'🔧 Cenário Ativo'!$B$17/1000000*'🎛️ Premissas'!$G$10)*(1-'🔧 Cenário Ativo'!$B$13)*'🔧 Cenário Ativo'!$B$10) -> 5697.1687 | J14: =J5*'🔧 Cenário Ativo'!$B$18*('🔧 Cenário Ativo'!$B$15*('🔧 Cenário Ativo'!$B$16/1000000*'🎛️ Premissas'!$G$9+'🔧 Cenário Ativo'!$B$17/1000000*'🎛️ Premissas'!$G$10)*(1-'🔧 Cenário Ativo'!$B$13)*'🔧 Cenário Ativo'!$B$10) -> 6511.05 | ... Z14: =Z5*'🔧 Cenário Ativo'!$B$18*('🔧 Cenário Ativo'!$B$15*('🔧 Cenário Ativo'!$B$16/1000000*'🎛️ Premissas'!$G$9+'🔧 Cenário Ativo'!$B$17/1000000*'🎛️ Premissas'!$G$10)*(1-'🔧 Cenário Ativo'!$B$13)*'🔧 Cenário Ativo'!$B$10) -> 21160.912
A15: API Essencial (chat ilimitado) | B15: R$ | C15: =C6*'🔧 Cenário Ativo'!B19*('🔧 Cenário Ativo'!B20/1000000*'🔧 Cenário Ativo'!B11+'🔧 Cenário Ativo'!B21/1000000*'🔧 Cenário Ativo'!B12)*(1-'🔧 Cenário Ativo'!B13)*'🔧 Cenário Ativo'!B10 -> 1224.0774 | D15: =D6*'🔧 Cenário Ativo'!B19*('🔧 Cenário Ativo'!B20/1000000*'🔧 Cenário Ativo'!B11+'🔧 Cenário Ativo'!B21/1000000*'🔧 Cenário Ativo'!B12)*(1-'🔧 Cenário Ativo'!B13)*'🔧 Cenário Ativo'!B10 -> 2448.1548 | E15: =E6*'🔧 Cenário Ativo'!B19*('🔧 Cenário Ativo'!B20/1000000*'🔧 Cenário Ativo'!B11+'🔧 Cenário Ativo'!B21/1000000*'🔧 Cenário Ativo'!B12)*(1-'🔧 Cenário Ativo'!B13)*'🔧 Cenário Ativo'!B10 -> 3672.2322 | F15: =F6*'🔧 Cenário Ativo'!B19*('🔧 Cenário Ativo'!B20/1000000*'🔧 Cenário Ativo'!B11+'🔧 Cenário Ativo'!B21/1000000*'🔧 Cenário Ativo'!B12)*(1-'🔧 Cenário Ativo'!B13)*'🔧 Cenário Ativo'!B10 -> 4896.3096 | G15: =G6*'🔧 Cenário Ativo'!B19*('🔧 Cenário Ativo'!B20/1000000*'🔧 Cenário Ativo'!B11+'🔧 Cenário Ativo'!B21/1000000*'🔧 Cenário Ativo'!B12)*(1-'🔧 Cenário Ativo'!B13)*'🔧 Cenário Ativo'!B10 -> 6120.387 | H15: =H6*'🔧 Cenário Ativo'!B19*('🔧 Cenário Ativo'!B20/1000000*'🔧 Cenário Ativo'!B11+'🔧 Cenário Ativo'!B21/1000000*'🔧 Cenário Ativo'!B12)*(1-'🔧 Cenário Ativo'!B13)*'🔧 Cenário Ativo'!B10 -> 7344.4644 | I15: =I6*'🔧 Cenário Ativo'!B19*('🔧 Cenário Ativo'!B20/1000000*'🔧 Cenário Ativo'!B11+'🔧 Cenário Ativo'!B21/1000000*'🔧 Cenário Ativo'!B12)*(1-'🔧 Cenário Ativo'!B13)*'🔧 Cenário Ativo'!B10 -> 8568.5418 | J15: =J6*'🔧 Cenário Ativo'!B19*('🔧 Cenário Ativo'!B20/1000000*'🔧 Cenário Ativo'!B11+'🔧 Cenário Ativo'!B21/1000000*'🔧 Cenário Ativo'!B12)*(1-'🔧 Cenário Ativo'!B13)*'🔧 Cenário Ativo'!B10 -> 9792.6192 | K15: =K6*'🔧 Cenário Ativo'!B19*('🔧 Cenário Ativo'!B20/1000000*'🔧 Cenário Ativo'!B11+'🔧 Cenário Ativo'!B21/1000000*'🔧 Cenário Ativo'!B12)*(1-'🔧 Cenário Ativo'!B13)*'🔧 Cenário Ativo'!B10 -> 11016.697 | L15: =L6*'🔧 Cenário Ativo'!B19*('🔧 Cenário Ativo'!B20/1000000*'🔧 Cenário Ativo'!B11+'🔧 Cenário Ativo'!B21/1000000*'🔧 Cenário Ativo'!B12)*(1-'🔧 Cenário Ativo'!B13)*'🔧 Cenário Ativo'!B10 -> 12240.774 | M15: =M6*'🔧 Cenário Ativo'!B19*('🔧 Cenário Ativo'!B20/1000000*'🔧 Cenário Ativo'!B11+'🔧 Cenário Ativo'!B21/1000000*'🔧 Cenário Ativo'!B12)*(1-'🔧 Cenário Ativo'!B13)*'🔧 Cenário Ativo'!B10 -> 13464.851 | N15: =N6*'🔧 Cenário Ativo'!B19*('🔧 Cenário Ativo'!B20/1000000*'🔧 Cenário Ativo'!B11+'🔧 Cenário Ativo'!B21/1000000*'🔧 Cenário Ativo'!B12)*(1-'🔧 Cenário Ativo'!B13)*'🔧 Cenário Ativo'!B10 -> 14688.929 | O15: =O6*'🔧 Cenário Ativo'!B19*('🔧 Cenário Ativo'!B20/1000000*'🔧 Cenário Ativo'!B11+'🔧 Cenário Ativo'!B21/1000000*'🔧 Cenário Ativo'!B12)*(1-'🔧 Cenário Ativo'!B13)*'🔧 Cenário Ativo'!B10 -> 16117.019 | P15: =P6*'🔧 Cenário Ativo'!B19*('🔧 Cenário Ativo'!B20/1000000*'🔧 Cenário Ativo'!B11+'🔧 Cenário Ativo'!B21/1000000*'🔧 Cenário Ativo'!B12)*(1-'🔧 Cenário Ativo'!B13)*'🔧 Cenário Ativo'!B10 -> 17545.109 | Q15: =Q6*'🔧 Cenário Ativo'!B19*('🔧 Cenário Ativo'!B20/1000000*'🔧 Cenário Ativo'!B11+'🔧 Cenário Ativo'!B21/1000000*'🔧 Cenário Ativo'!B12)*(1-'🔧 Cenário Ativo'!B13)*'🔧 Cenário Ativo'!B10 -> 18973.2 | R15: =R6*'🔧 Cenário Ativo'!B19*('🔧 Cenário Ativo'!B20/1000000*'🔧 Cenário Ativo'!B11+'🔧 Cenário Ativo'!B21/1000000*'🔧 Cenário Ativo'!B12)*(1-'🔧 Cenário Ativo'!B13)*'🔧 Cenário Ativo'!B10 -> 35772.205 | S15: =S6*'🔧 Cenário Ativo'!B19*('🔧 Cenário Ativo'!B20/1000000*'🔧 Cenário Ativo'!B11+'🔧 Cenário Ativo'!B21/1000000*'🔧 Cenário Ativo'!B12)*(1-'🔧 Cenário Ativo'!B13)*'🔧 Cenário Ativo'!B10 -> 51452.053 | T15: =T6*'🔧 Cenário Ativo'!B19*('🔧 Cenário Ativo'!B20/1000000*'🔧 Cenário Ativo'!B11+'🔧 Cenário Ativo'!B21/1000000*'🔧 Cenário Ativo'!B12)*(1-'🔧 Cenário Ativo'!B13)*'🔧 Cenário Ativo'!B10 -> 66158.469 | U15: =U6*'🔧 Cenário Ativo'!B19*('🔧 Cenário Ativo'!B20/1000000*'🔧 Cenário Ativo'!B11+'🔧 Cenário Ativo'!B21/1000000*'🔧 Cenário Ativo'!B12)*(1-'🔧 Cenário Ativo'!B13)*'🔧 Cenário Ativo'!B10 -> 80002.201 | V15: =V6*'🔧 Cenário Ativo'!B19*('🔧 Cenário Ativo'!B20/1000000*'🔧 Cenário Ativo'!B11+'🔧 Cenário Ativo'!B21/1000000*'🔧 Cenário Ativo'!B12)*(1-'🔧 Cenário Ativo'!B13)*'🔧 Cenário Ativo'!B10 -> 93094.001 | W15: =W6*'🔧 Cenário Ativo'!B19*('🔧 Cenário Ativo'!B20/1000000*'🔧 Cenário Ativo'!B11+'🔧 Cenário Ativo'!B21/1000000*'🔧 Cenário Ativo'!B12)*(1-'🔧 Cenário Ativo'!B13)*'🔧 Cenário Ativo'!B10 -> 105527.13 | X15: =X6*'🔧 Cenário Ativo'!B19*('🔧 Cenário Ativo'!B20/1000000*'🔧 Cenário Ativo'!B11+'🔧 Cenário Ativo'!B21/1000000*'🔧 Cenário Ativo'!B12)*(1-'🔧 Cenário Ativo'!B13)*'🔧 Cenário Ativo'!B10 -> 117377.36 | Y15: =Y6*'🔧 Cenário Ativo'!B19*('🔧 Cenário Ativo'!B20/1000000*'🔧 Cenário Ativo'!B11+'🔧 Cenário Ativo'!B21/1000000*'🔧 Cenário Ativo'!B12)*(1-'🔧 Cenário Ativo'!B13)*'🔧 Cenário Ativo'!B10 -> 128720.48 | Z15: =Z6*'🔧 Cenário Ativo'!B19*('🔧 Cenário Ativo'!B20/1000000*'🔧 Cenário Ativo'!B11+'🔧 Cenário Ativo'!B21/1000000*'🔧 Cenário Ativo'!B12)*(1-'🔧 Cenário Ativo'!B13)*'🔧 Cenário Ativo'!B10 -> 139620.6
A16: API Autônoma (+1 agente) | B16: R$ | C16: =C7*('🔧 Cenário Ativo'!B19*('🔧 Cenário Ativo'!B20/1000000*'🔧 Cenário Ativo'!B11+'🔧 Cenário Ativo'!B21/1000000*'🔧 Cenário Ativo'!B12)*(1-'🔧 Cenário Ativo'!B13)*'🔧 Cenário Ativo'!B10+'🔧 Cenário Ativo'!B22*('🔧 Cenário Ativo'!B23/1000000*'🔧 Cenário Ativo'!B11+'🔧 Cenário Ativo'!B24/1000000*'🔧 Cenário Ativo'!B12)*(1-'🔧 Cenário Ativo'!B13)*'🔧 Cenário Ativo'!B10) -> 915.2676 | D16: =D7*('🔧 Cenário Ativo'!B19*('🔧 Cenário Ativo'!B20/1000000*'🔧 Cenário Ativo'!B11+'🔧 Cenário Ativo'!B21/1000000*'🔧 Cenário Ativo'!B12)*(1-'🔧 Cenário Ativo'!B13)*'🔧 Cenário Ativo'!B10+'🔧 Cenário Ativo'!B22*('🔧 Cenário Ativo'!B23/1000000*'🔧 Cenário Ativo'!B11+'🔧 Cenário Ativo'!B24/1000000*'🔧 Cenário Ativo'!B12)*(1-'🔧 Cenário Ativo'!B13)*'🔧 Cenário Ativo'!B10) -> 1830.5352 | E16: =E7*('🔧 Cenário Ativo'!B19*('🔧 Cenário Ativo'!B20/1000000*'🔧 Cenário Ativo'!B11+'🔧 Cenário Ativo'!B21/1000000*'🔧 Cenário Ativo'!B12)*(1-'🔧 Cenário Ativo'!B13)*'🔧 Cenário Ativo'!B10+'🔧 Cenário Ativo'!B22*('🔧 Cenário Ativo'!B23/1000000*'🔧 Cenário Ativo'!B11+'🔧 Cenário Ativo'!B24/1000000*'🔧 Cenário Ativo'!B12)*(1-'🔧 Cenário Ativo'!B13)*'🔧 Cenário Ativo'!B10) -> 2745.8028 | F16: =F7*('🔧 Cenário Ativo'!B19*('🔧 Cenário Ativo'!B20/1000000*'🔧 Cenário Ativo'!B11+'🔧 Cenário Ativo'!B21/1000000*'🔧 Cenário Ativo'!B12)*(1-'🔧 Cenário Ativo'!B13)*'🔧 Cenário Ativo'!B10+'🔧 Cenário Ativo'!B22*('🔧 Cenário Ativo'!B23/1000000*'🔧 Cenário Ativo'!B11+'🔧 Cenário Ativo'!B24/1000000*'🔧 Cenário Ativo'!B12)*(1-'🔧 Cenário Ativo'!B13)*'🔧 Cenário Ativo'!B10) -> 3661.0704 | G16: =G7*('🔧 Cenário Ativo'!B19*('🔧 Cenário Ativo'!B20/1000000*'🔧 Cenário Ativo'!B11+'🔧 Cenário Ativo'!B21/1000000*'🔧 Cenário Ativo'!B12)*(1-'🔧 Cenário Ativo'!B13)*'🔧 Cenário Ativo'!B10+'🔧 Cenário Ativo'!B22*('🔧 Cenário Ativo'!B23/1000000*'🔧 Cenário Ativo'!B11+'🔧 Cenário Ativo'!B24/1000000*'🔧 Cenário Ativo'!B12)*(1-'🔧 Cenário Ativo'!B13)*'🔧 Cenário Ativo'!B10) -> 4576.338 | H16: =H7*('🔧 Cenário Ativo'!B19*('🔧 Cenário Ativo'!B20/1000000*'🔧 Cenário Ativo'!B11+'🔧 Cenário Ativo'!B21/1000000*'🔧 Cenário Ativo'!B12)*(1-'🔧 Cenário Ativo'!B13)*'🔧 Cenário Ativo'!B10+'🔧 Cenário Ativo'!B22*('🔧 Cenário Ativo'!B23/1000000*'🔧 Cenário Ativo'!B11+'🔧 Cenário Ativo'!B24/1000000*'🔧 Cenário Ativo'!B12)*(1-'🔧 Cenário Ativo'!B13)*'🔧 Cenário Ativo'!B10) -> 5491.6056 | I16: =I7*('🔧 Cenário Ativo'!B19*('🔧 Cenário Ativo'!B20/1000000*'🔧 Cenário Ativo'!B11+'🔧 Cenário Ativo'!B21/1000000*'🔧 Cenário Ativo'!B12)*(1-'🔧 Cenário Ativo'!B13)*'🔧 Cenário Ativo'!B10+'🔧 Cenário Ativo'!B22*('🔧 Cenário Ativo'!B23/1000000*'🔧 Cenário Ativo'!B11+'🔧 Cenário Ativo'!B24/1000000*'🔧 Cenário Ativo'!B12)*(1-'🔧 Cenário Ativo'!B13)*'🔧 Cenário Ativo'!B10) -> 6406.8732 | J16: =J7*('🔧 Cenário Ativo'!B19*('🔧 Cenário Ativo'!B20/1000000*'🔧 Cenário Ativo'!B11+'🔧 Cenário Ativo'!B21/1000000*'🔧 Cenário Ativo'!B12)*(1-'🔧 Cenário Ativo'!B13)*'🔧 Cenário Ativo'!B10+'🔧 Cenário Ativo'!B22*('🔧 Cenário Ativo'!B23/1000000*'🔧 Cenário Ativo'!B11+'🔧 Cenário Ativo'!B24/1000000*'🔧 Cenário Ativo'!B12)*(1-'🔧 Cenário Ativo'!B13)*'🔧 Cenário Ativo'!B10) -> 7322.1408 | K16: =K7*('🔧 Cenário Ativo'!B19*('🔧 Cenário Ativo'!B20/1000000*'🔧 Cenário Ativo'!B11+'🔧 Cenário Ativo'!B21/1000000*'🔧 Cenário Ativo'!B12)*(1-'🔧 Cenário Ativo'!B13)*'🔧 Cenário Ativo'!B10+'🔧 Cenário Ativo'!B22*('🔧 Cenário Ativo'!B23/1000000*'🔧 Cenário Ativo'!B11+'🔧 Cenário Ativo'!B24/1000000*'🔧 Cenário Ativo'!B12)*(1-'🔧 Cenário Ativo'!B13)*'🔧 Cenário Ativo'!B10) -> 8237.4084 | L16: =L7*('🔧 Cenário Ativo'!B19*('🔧 Cenário Ativo'!B20/1000000*'🔧 Cenário Ativo'!B11+'🔧 Cenário Ativo'!B21/1000000*'🔧 Cenário Ativo'!B12)*(1-'🔧 Cenário Ativo'!B13)*'🔧 Cenário Ativo'!B10+'🔧 Cenário Ativo'!B22*('🔧 Cenário Ativo'!B23/1000000*'🔧 Cenário Ativo'!B11+'🔧 Cenário Ativo'!B24/1000000*'🔧 Cenário Ativo'!B12)*(1-'🔧 Cenário Ativo'!B13)*'🔧 Cenário Ativo'!B10) -> 9152.676 | M16: =M7*('🔧 Cenário Ativo'!B19*('🔧 Cenário Ativo'!B20/1000000*'🔧 Cenário Ativo'!B11+'🔧 Cenário Ativo'!B21/1000000*'🔧 Cenário Ativo'!B12)*(1-'🔧 Cenário Ativo'!B13)*'🔧 Cenário Ativo'!B10+'🔧 Cenário Ativo'!B22*('🔧 Cenário Ativo'!B23/1000000*'🔧 Cenário Ativo'!B11+'🔧 Cenário Ativo'!B24/1000000*'🔧 Cenário Ativo'!B12)*(1-'🔧 Cenário Ativo'!B13)*'🔧 Cenário Ativo'!B10) -> 10067.944 | N16: =N7*('🔧 Cenário Ativo'!B19*('🔧 Cenário Ativo'!B20/1000000*'🔧 Cenário Ativo'!B11+'🔧 Cenário Ativo'!B21/1000000*'🔧 Cenário Ativo'!B12)*(1-'🔧 Cenário Ativo'!B13)*'🔧 Cenário Ativo'!B10+'🔧 Cenário Ativo'!B22*('🔧 Cenário Ativo'!B23/1000000*'🔧 Cenário Ativo'!B11+'🔧 Cenário Ativo'!B24/1000000*'🔧 Cenário Ativo'!B12)*(1-'🔧 Cenário Ativo'!B13)*'🔧 Cenário Ativo'!B10) -> 10983.211 | O16: =O7*('🔧 Cenário Ativo'!B19*('🔧 Cenário Ativo'!B20/1000000*'🔧 Cenário Ativo'!B11+'🔧 Cenário Ativo'!B21/1000000*'🔧 Cenário Ativo'!B12)*(1-'🔧 Cenário Ativo'!B13)*'🔧 Cenário Ativo'!B10+'🔧 Cenário Ativo'!B22*('🔧 Cenário Ativo'!B23/1000000*'🔧 Cenário Ativo'!B11+'🔧 Cenário Ativo'!B24/1000000*'🔧 Cenário Ativo'!B12)*(1-'🔧 Cenário Ativo'!B13)*'🔧 Cenário Ativo'!B10) -> 12051.023 | P16: =P7*('🔧 Cenário Ativo'!B19*('🔧 Cenário Ativo'!B20/1000000*'🔧 Cenário Ativo'!B11+'🔧 Cenário Ativo'!B21/1000000*'🔧 Cenário Ativo'!B12)*(1-'🔧 Cenário Ativo'!B13)*'🔧 Cenário Ativo'!B10+'🔧 Cenário Ativo'!B22*('🔧 Cenário Ativo'!B23/1000000*'🔧 Cenário Ativo'!B11+'🔧 Cenário Ativo'!B24/1000000*'🔧 Cenário Ativo'!B12)*(1-'🔧 Cenário Ativo'!B13)*'🔧 Cenário Ativo'!B10) -> 13118.836 | Q16: =Q7*('🔧 Cenário Ativo'!B19*('🔧 Cenário Ativo'!B20/1000000*'🔧 Cenário Ativo'!B11+'🔧 Cenário Ativo'!B21/1000000*'🔧 Cenário Ativo'!B12)*(1-'🔧 Cenário Ativo'!B13)*'🔧 Cenário Ativo'!B10+'🔧 Cenário Ativo'!B22*('🔧 Cenário Ativo'!B23/1000000*'🔧 Cenário Ativo'!B11+'🔧 Cenário Ativo'!B24/1000000*'🔧 Cenário Ativo'!B12)*(1-'🔧 Cenário Ativo'!B13)*'🔧 Cenário Ativo'!B10) -> 14186.648 | R16: =R7*('🔧 Cenário Ativo'!B19*('🔧 Cenário Ativo'!B20/1000000*'🔧 Cenário Ativo'!B11+'🔧 Cenário Ativo'!B21/1000000*'🔧 Cenário Ativo'!B12)*(1-'🔧 Cenário Ativo'!B13)*'🔧 Cenário Ativo'!B10+'🔧 Cenário Ativo'!B22*('🔧 Cenário Ativo'!B23/1000000*'🔧 Cenário Ativo'!B11+'🔧 Cenário Ativo'!B24/1000000*'🔧 Cenário Ativo'!B12)*(1-'🔧 Cenário Ativo'!B13)*'🔧 Cenário Ativo'!B10) -> 14786.657 | S16: =S7*('🔧 Cenário Ativo'!B19*('🔧 Cenário Ativo'!B20/1000000*'🔧 Cenário Ativo'!B11+'🔧 Cenário Ativo'!B21/1000000*'🔧 Cenário Ativo'!B12)*(1-'🔧 Cenário Ativo'!B13)*'🔧 Cenário Ativo'!B10+'🔧 Cenário Ativo'!B22*('🔧 Cenário Ativo'!B23/1000000*'🔧 Cenário Ativo'!B11+'🔧 Cenário Ativo'!B24/1000000*'🔧 Cenário Ativo'!B12)*(1-'🔧 Cenário Ativo'!B13)*'🔧 Cenário Ativo'!B10) -> 16159.558 | T16: =T7*('🔧 Cenário Ativo'!B19*('🔧 Cenário Ativo'!B20/1000000*'🔧 Cenário Ativo'!B11+'🔧 Cenário Ativo'!B21/1000000*'🔧 Cenário Ativo'!B12)*(1-'🔧 Cenário Ativo'!B13)*'🔧 Cenário Ativo'!B10+'🔧 Cenário Ativo'!B22*('🔧 Cenário Ativo'!B23/1000000*'🔧 Cenário Ativo'!B11+'🔧 Cenário Ativo'!B24/1000000*'🔧 Cenário Ativo'!B12)*(1-'🔧 Cenário Ativo'!B13)*'🔧 Cenário Ativo'!B10) -> 18193.486 | U16: =U7*('🔧 Cenário Ativo'!B19*('🔧 Cenário Ativo'!B20/1000000*'🔧 Cenário Ativo'!B11+'🔧 Cenário Ativo'!B21/1000000*'🔧 Cenário Ativo'!B12)*(1-'🔧 Cenário Ativo'!B13)*'🔧 Cenário Ativo'!B10+'🔧 Cenário Ativo'!B22*('🔧 Cenário Ativo'!B23/1000000*'🔧 Cenário Ativo'!B11+'🔧 Cenário Ativo'!B24/1000000*'🔧 Cenário Ativo'!B12)*(1-'🔧 Cenário Ativo'!B13)*'🔧 Cenário Ativo'!B10) -> 20786.744 | V16: =V7*('🔧 Cenário Ativo'!B19*('🔧 Cenário Ativo'!B20/1000000*'🔧 Cenário Ativo'!B11+'🔧 Cenário Ativo'!B21/1000000*'🔧 Cenário Ativo'!B12)*(1-'🔧 Cenário Ativo'!B13)*'🔧 Cenário Ativo'!B10+'🔧 Cenário Ativo'!B22*('🔧 Cenário Ativo'!B23/1000000*'🔧 Cenário Ativo'!B11+'🔧 Cenário Ativo'!B24/1000000*'🔧 Cenário Ativo'!B12)*(1-'🔧 Cenário Ativo'!B13)*'🔧 Cenário Ativo'!B10) -> 23857.975 | W16: =W7*('🔧 Cenário Ativo'!B19*('🔧 Cenário Ativo'!B20/1000000*'🔧 Cenário Ativo'!B11+'🔧 Cenário Ativo'!B21/1000000*'🔧 Cenário Ativo'!B12)*(1-'🔧 Cenário Ativo'!B13)*'🔧 Cenário Ativo'!B10+'🔧 Cenário Ativo'!B22*('🔧 Cenário Ativo'!B23/1000000*'🔧 Cenário Ativo'!B11+'🔧 Cenário Ativo'!B24/1000000*'🔧 Cenário Ativo'!B12)*(1-'🔧 Cenário Ativo'!B13)*'🔧 Cenário Ativo'!B10) -> 27325.823 | X16: =X7*('🔧 Cenário Ativo'!B19*('🔧 Cenário Ativo'!B20/1000000*'🔧 Cenário Ativo'!B11+'🔧 Cenário Ativo'!B21/1000000*'🔧 Cenário Ativo'!B12)*(1-'🔧 Cenário Ativo'!B13)*'🔧 Cenário Ativo'!B10+'🔧 Cenário Ativo'!B22*('🔧 Cenário Ativo'!B23/1000000*'🔧 Cenário Ativo'!B11+'🔧 Cenário Ativo'!B24/1000000*'🔧 Cenário Ativo'!B12)*(1-'🔧 Cenário Ativo'!B13)*'🔧 Cenário Ativo'!B10) -> 31139.438 | Y16: =Y7*('🔧 Cenário Ativo'!B19*('🔧 Cenário Ativo'!B20/1000000*'🔧 Cenário Ativo'!B11+'🔧 Cenário Ativo'!B21/1000000*'🔧 Cenário Ativo'!B12)*(1-'🔧 Cenário Ativo'!B13)*'🔧 Cenário Ativo'!B10+'🔧 Cenário Ativo'!B22*('🔧 Cenário Ativo'!B23/1000000*'🔧 Cenário Ativo'!B11+'🔧 Cenário Ativo'!B24/1000000*'🔧 Cenário Ativo'!B12)*(1-'🔧 Cenário Ativo'!B13)*'🔧 Cenário Ativo'!B10) -> 35237.803 | Z16: =Z7*('🔧 Cenário Ativo'!B19*('🔧 Cenário Ativo'!B20/1000000*'🔧 Cenário Ativo'!B11+'🔧 Cenário Ativo'!B21/1000000*'🔧 Cenário Ativo'!B12)*(1-'🔧 Cenário Ativo'!B13)*'🔧 Cenário Ativo'!B10+'🔧 Cenário Ativo'!B22*('🔧 Cenário Ativo'!B23/1000000*'🔧 Cenário Ativo'!B11+'🔧 Cenário Ativo'!B24/1000000*'🔧 Cenário Ativo'!B12)*(1-'🔧 Cenário Ativo'!B13)*'🔧 Cenário Ativo'!B10) -> 39570.069
A17: API Livre (+2 agentes) | B17: R$ | C17: =C8*('🔧 Cenário Ativo'!B19*('🔧 Cenário Ativo'!B20/1000000*'🔧 Cenário Ativo'!B11+'🔧 Cenário Ativo'!B21/1000000*'🔧 Cenário Ativo'!B12)*(1-'🔧 Cenário Ativo'!B13)*'🔧 Cenário Ativo'!B10+'🔧 Cenário Ativo'!B25*('🔧 Cenário Ativo'!B23/1000000*'🔧 Cenário Ativo'!B11+'🔧 Cenário Ativo'!B24/1000000*'🔧 Cenário Ativo'!B12)*(1-'🔧 Cenário Ativo'!B13)*'🔧 Cenário Ativo'!B10) -> 398.1042 | D17: =D8*('🔧 Cenário Ativo'!B19*('🔧 Cenário Ativo'!B20/1000000*'🔧 Cenário Ativo'!B11+'🔧 Cenário Ativo'!B21/1000000*'🔧 Cenário Ativo'!B12)*(1-'🔧 Cenário Ativo'!B13)*'🔧 Cenário Ativo'!B10+'🔧 Cenário Ativo'!B25*('🔧 Cenário Ativo'!B23/1000000*'🔧 Cenário Ativo'!B11+'🔧 Cenário Ativo'!B24/1000000*'🔧 Cenário Ativo'!B12)*(1-'🔧 Cenário Ativo'!B13)*'🔧 Cenário Ativo'!B10) -> 796.2084 | E17: =E8*('🔧 Cenário Ativo'!B19*('🔧 Cenário Ativo'!B20/1000000*'🔧 Cenário Ativo'!B11+'🔧 Cenário Ativo'!B21/1000000*'🔧 Cenário Ativo'!B12)*(1-'🔧 Cenário Ativo'!B13)*'🔧 Cenário Ativo'!B10+'🔧 Cenário Ativo'!B25*('🔧 Cenário Ativo'!B23/1000000*'🔧 Cenário Ativo'!B11+'🔧 Cenário Ativo'!B24/1000000*'🔧 Cenário Ativo'!B12)*(1-'🔧 Cenário Ativo'!B13)*'🔧 Cenário Ativo'!B10) -> 1194.3126 | F17: =F8*('🔧 Cenário Ativo'!B19*('🔧 Cenário Ativo'!B20/1000000*'🔧 Cenário Ativo'!B11+'🔧 Cenário Ativo'!B21/1000000*'🔧 Cenário Ativo'!B12)*(1-'🔧 Cenário Ativo'!B13)*'🔧 Cenário Ativo'!B10+'🔧 Cenário Ativo'!B25*('🔧 Cenário Ativo'!B23/1000000*'🔧 Cenário Ativo'!B11+'🔧 Cenário Ativo'!B24/1000000*'🔧 Cenário Ativo'!B12)*(1-'🔧 Cenário Ativo'!B13)*'🔧 Cenário Ativo'!B10) -> 1592.4168 | G17: =G8*('🔧 Cenário Ativo'!B19*('🔧 Cenário Ativo'!B20/1000000*'🔧 Cenário Ativo'!B11+'🔧 Cenário Ativo'!B21/1000000*'🔧 Cenário Ativo'!B12)*(1-'🔧 Cenário Ativo'!B13)*'🔧 Cenário Ativo'!B10+'🔧 Cenário Ativo'!B25*('🔧 Cenário Ativo'!B23/1000000*'🔧 Cenário Ativo'!B11+'🔧 Cenário Ativo'!B24/1000000*'🔧 Cenário Ativo'!B12)*(1-'🔧 Cenário Ativo'!B13)*'🔧 Cenário Ativo'!B10) -> 1990.521 | H17: =H8*('🔧 Cenário Ativo'!B19*('🔧 Cenário Ativo'!B20/1000000*'🔧 Cenário Ativo'!B11+'🔧 Cenário Ativo'!B21/1000000*'🔧 Cenário Ativo'!B12)*(1-'🔧 Cenário Ativo'!B13)*'🔧 Cenário Ativo'!B10+'🔧 Cenário Ativo'!B25*('🔧 Cenário Ativo'!B23/1000000*'🔧 Cenário Ativo'!B11+'🔧 Cenário Ativo'!B24/1000000*'🔧 Cenário Ativo'!B12)*(1-'🔧 Cenário Ativo'!B13)*'🔧 Cenário Ativo'!B10) -> 2388.6252 | I17: =I8*('🔧 Cenário Ativo'!B19*('🔧 Cenário Ativo'!B20/1000000*'🔧 Cenário Ativo'!B11+'🔧 Cenário Ativo'!B21/1000000*'🔧 Cenário Ativo'!B12)*(1-'🔧 Cenário Ativo'!B13)*'🔧 Cenário Ativo'!B10+'🔧 Cenário Ativo'!B25*('🔧 Cenário Ativo'!B23/1000000*'🔧 Cenário Ativo'!B11+'🔧 Cenário Ativo'!B24/1000000*'🔧 Cenário Ativo'!B12)*(1-'🔧 Cenário Ativo'!B13)*'🔧 Cenário Ativo'!B10) -> 2786.7294 | J17: =J8*('🔧 Cenário Ativo'!B19*('🔧 Cenário Ativo'!B20/1000000*'🔧 Cenário Ativo'!B11+'🔧 Cenário Ativo'!B21/1000000*'🔧 Cenário Ativo'!B12)*(1-'🔧 Cenário Ativo'!B13)*'🔧 Cenário Ativo'!B10+'🔧 Cenário Ativo'!B25*('🔧 Cenário Ativo'!B23/1000000*'🔧 Cenário Ativo'!B11+'🔧 Cenário Ativo'!B24/1000000*'🔧 Cenário Ativo'!B12)*(1-'🔧 Cenário Ativo'!B13)*'🔧 Cenário Ativo'!B10) -> 3184.8336 | K17: =K8*('🔧 Cenário Ativo'!B19*('🔧 Cenário Ativo'!B20/1000000*'🔧 Cenário Ativo'!B11+'🔧 Cenário Ativo'!B21/1000000*'🔧 Cenário Ativo'!B12)*(1-'🔧 Cenário Ativo'!B13)*'🔧 Cenário Ativo'!B10+'🔧 Cenário Ativo'!B25*('🔧 Cenário Ativo'!B23/1000000*'🔧 Cenário Ativo'!B11+'🔧 Cenário Ativo'!B24/1000000*'🔧 Cenário Ativo'!B12)*(1-'🔧 Cenário Ativo'!B13)*'🔧 Cenário Ativo'!B10) -> 3582.9378 | L17: =L8*('🔧 Cenário Ativo'!B19*('🔧 Cenário Ativo'!B20/1000000*'🔧 Cenário Ativo'!B11+'🔧 Cenário Ativo'!B21/1000000*'🔧 Cenário Ativo'!B12)*(1-'🔧 Cenário Ativo'!B13)*'🔧 Cenário Ativo'!B10+'🔧 Cenário Ativo'!B25*('🔧 Cenário Ativo'!B23/1000000*'🔧 Cenário Ativo'!B11+'🔧 Cenário Ativo'!B24/1000000*'🔧 Cenário Ativo'!B12)*(1-'🔧 Cenário Ativo'!B13)*'🔧 Cenário Ativo'!B10) -> 3981.042 | M17: =M8*('🔧 Cenário Ativo'!B19*('🔧 Cenário Ativo'!B20/1000000*'🔧 Cenário Ativo'!B11+'🔧 Cenário Ativo'!B21/1000000*'🔧 Cenário Ativo'!B12)*(1-'🔧 Cenário Ativo'!B13)*'🔧 Cenário Ativo'!B10+'🔧 Cenário Ativo'!B25*('🔧 Cenário Ativo'!B23/1000000*'🔧 Cenário Ativo'!B11+'🔧 Cenário Ativo'!B24/1000000*'🔧 Cenário Ativo'!B12)*(1-'🔧 Cenário Ativo'!B13)*'🔧 Cenário Ativo'!B10) -> 4379.1462 | N17: =N8*('🔧 Cenário Ativo'!B19*('🔧 Cenário Ativo'!B20/1000000*'🔧 Cenário Ativo'!B11+'🔧 Cenário Ativo'!B21/1000000*'🔧 Cenário Ativo'!B12)*(1-'🔧 Cenário Ativo'!B13)*'🔧 Cenário Ativo'!B10+'🔧 Cenário Ativo'!B25*('🔧 Cenário Ativo'!B23/1000000*'🔧 Cenário Ativo'!B11+'🔧 Cenário Ativo'!B24/1000000*'🔧 Cenário Ativo'!B12)*(1-'🔧 Cenário Ativo'!B13)*'🔧 Cenário Ativo'!B10) -> 4777.2504 | O17: =O8*('🔧 Cenário Ativo'!B19*('🔧 Cenário Ativo'!B20/1000000*'🔧 Cenário Ativo'!B11+'🔧 Cenário Ativo'!B21/1000000*'🔧 Cenário Ativo'!B12)*(1-'🔧 Cenário Ativo'!B13)*'🔧 Cenário Ativo'!B10+'🔧 Cenário Ativo'!B25*('🔧 Cenário Ativo'!B23/1000000*'🔧 Cenário Ativo'!B11+'🔧 Cenário Ativo'!B24/1000000*'🔧 Cenário Ativo'!B12)*(1-'🔧 Cenário Ativo'!B13)*'🔧 Cenário Ativo'!B10) -> 5241.7053 | P17: =P8*('🔧 Cenário Ativo'!B19*('🔧 Cenário Ativo'!B20/1000000*'🔧 Cenário Ativo'!B11+'🔧 Cenário Ativo'!B21/1000000*'🔧 Cenário Ativo'!B12)*(1-'🔧 Cenário Ativo'!B13)*'🔧 Cenário Ativo'!B10+'🔧 Cenário Ativo'!B25*('🔧 Cenário Ativo'!B23/1000000*'🔧 Cenário Ativo'!B11+'🔧 Cenário Ativo'!B24/1000000*'🔧 Cenário Ativo'!B12)*(1-'🔧 Cenário Ativo'!B13)*'🔧 Cenário Ativo'!B10) -> 5706.1602 | Q17: =Q8*('🔧 Cenário Ativo'!B19*('🔧 Cenário Ativo'!B20/1000000*'🔧 Cenário Ativo'!B11+'🔧 Cenário Ativo'!B21/1000000*'🔧 Cenário Ativo'!B12)*(1-'🔧 Cenário Ativo'!B13)*'🔧 Cenário Ativo'!B10+'🔧 Cenário Ativo'!B25*('🔧 Cenário Ativo'!B23/1000000*'🔧 Cenário Ativo'!B11+'🔧 Cenário Ativo'!B24/1000000*'🔧 Cenário Ativo'!B12)*(1-'🔧 Cenário Ativo'!B13)*'🔧 Cenário Ativo'!B10) -> 6170.6151 | R17: =R8*('🔧 Cenário Ativo'!B19*('🔧 Cenário Ativo'!B20/1000000*'🔧 Cenário Ativo'!B11+'🔧 Cenário Ativo'!B21/1000000*'🔧 Cenário Ativo'!B12)*(1-'🔧 Cenário Ativo'!B13)*'🔧 Cenário Ativo'!B10+'🔧 Cenário Ativo'!B25*('🔧 Cenário Ativo'!B23/1000000*'🔧 Cenário Ativo'!B11+'🔧 Cenário Ativo'!B24/1000000*'🔧 Cenário Ativo'!B12)*(1-'🔧 Cenário Ativo'!B13)*'🔧 Cenário Ativo'!B10) -> 6117.5345 | S17: =S8*('🔧 Cenário Ativo'!B19*('🔧 Cenário Ativo'!B20/1000000*'🔧 Cenário Ativo'!B11+'🔧 Cenário Ativo'!B21/1000000*'🔧 Cenário Ativo'!B12)*(1-'🔧 Cenário Ativo'!B13)*'🔧 Cenário Ativo'!B10+'🔧 Cenário Ativo'!B25*('🔧 Cenário Ativo'!B23/1000000*'🔧 Cenário Ativo'!B11+'🔧 Cenário Ativo'!B24/1000000*'🔧 Cenário Ativo'!B12)*(1-'🔧 Cenário Ativo'!B13)*'🔧 Cenário Ativo'!B10) -> 6077.7241 | T17: =T8*('🔧 Cenário Ativo'!B19*('🔧 Cenário Ativo'!B20/1000000*'🔧 Cenário Ativo'!B11+'🔧 Cenário Ativo'!B21/1000000*'🔧 Cenário Ativo'!B12)*(1-'🔧 Cenário Ativo'!B13)*'🔧 Cenário Ativo'!B10+'🔧 Cenário Ativo'!B25*('🔧 Cenário Ativo'!B23/1000000*'🔧 Cenário Ativo'!B11+'🔧 Cenário Ativo'!B24/1000000*'🔧 Cenário Ativo'!B12)*(1-'🔧 Cenário Ativo'!B13)*'🔧 Cenário Ativo'!B10) -> 6077.7241 | U17: =U8*('🔧 Cenário Ativo'!B19*('🔧 Cenário Ativo'!B20/1000000*'🔧 Cenário Ativo'!B11+'🔧 Cenário Ativo'!B21/1000000*'🔧 Cenário Ativo'!B12)*(1-'🔧 Cenário Ativo'!B13)*'🔧 Cenário Ativo'!B10+'🔧 Cenário Ativo'!B25*('🔧 Cenário Ativo'!B23/1000000*'🔧 Cenário Ativo'!B11+'🔧 Cenário Ativo'!B24/1000000*'🔧 Cenário Ativo'!B12)*(1-'🔧 Cenário Ativo'!B13)*'🔧 Cenário Ativo'!B10) -> 6104.2644 | V17: =V8*('🔧 Cenário Ativo'!B19*('🔧 Cenário Ativo'!B20/1000000*'🔧 Cenário Ativo'!B11+'🔧 Cenário Ativo'!B21/1000000*'🔧 Cenário Ativo'!B12)*(1-'🔧 Cenário Ativo'!B13)*'🔧 Cenário Ativo'!B10+'🔧 Cenário Ativo'!B25*('🔧 Cenário Ativo'!B23/1000000*'🔧 Cenário Ativo'!B11+'🔧 Cenário Ativo'!B24/1000000*'🔧 Cenário Ativo'!B12)*(1-'🔧 Cenário Ativo'!B13)*'🔧 Cenário Ativo'!B10) -> 6170.6151 | W17: =W8*('🔧 Cenário Ativo'!B19*('🔧 Cenário Ativo'!B20/1000000*'🔧 Cenário Ativo'!B11+'🔧 Cenário Ativo'!B21/1000000*'🔧 Cenário Ativo'!B12)*(1-'🔧 Cenário Ativo'!B13)*'🔧 Cenário Ativo'!B10+'🔧 Cenário Ativo'!B25*('🔧 Cenário Ativo'!B23/1000000*'🔧 Cenário Ativo'!B11+'🔧 Cenário Ativo'!B24/1000000*'🔧 Cenário Ativo'!B12)*(1-'🔧 Cenário Ativo'!B13)*'🔧 Cenário Ativo'!B10) -> 6276.7762 | X17: =X8*('🔧 Cenário Ativo'!B19*('🔧 Cenário Ativo'!B20/1000000*'🔧 Cenário Ativo'!B11+'🔧 Cenário Ativo'!B21/1000000*'🔧 Cenário Ativo'!B12)*(1-'🔧 Cenário Ativo'!B13)*'🔧 Cenário Ativo'!B10+'🔧 Cenário Ativo'!B25*('🔧 Cenário Ativo'!B23/1000000*'🔧 Cenário Ativo'!B11+'🔧 Cenário Ativo'!B24/1000000*'🔧 Cenário Ativo'!B12)*(1-'🔧 Cenário Ativo'!B13)*'🔧 Cenário Ativo'!B10) -> 6436.0179 | Y17: =Y8*('🔧 Cenário Ativo'!B19*('🔧 Cenário Ativo'!B20/1000000*'🔧 Cenário Ativo'!B11+'🔧 Cenário Ativo'!B21/1000000*'🔧 Cenário Ativo'!B12)*(1-'🔧 Cenário Ativo'!B13)*'🔧 Cenário Ativo'!B10+'🔧 Cenário Ativo'!B25*('🔧 Cenário Ativo'!B23/1000000*'🔧 Cenário Ativo'!B11+'🔧 Cenário Ativo'!B24/1000000*'🔧 Cenário Ativo'!B12)*(1-'🔧 Cenário Ativo'!B13)*'🔧 Cenário Ativo'!B10) -> 6635.07 | Z17: =Z8*('🔧 Cenário Ativo'!B19*('🔧 Cenário Ativo'!B20/1000000*'🔧 Cenário Ativo'!B11+'🔧 Cenário Ativo'!B21/1000000*'🔧 Cenário Ativo'!B12)*(1-'🔧 Cenário Ativo'!B13)*'🔧 Cenário Ativo'!B10+'🔧 Cenário Ativo'!B25*('🔧 Cenário Ativo'!B23/1000000*'🔧 Cenário Ativo'!B11+'🔧 Cenário Ativo'!B24/1000000*'🔧 Cenário Ativo'!B12)*(1-'🔧 Cenário Ativo'!B13)*'🔧 Cenário Ativo'!B10) -> 6887.2027
